Workbook

Sheet Zinsermittlung
A1: Eingabe | C1: Ergebnis aus Sicht 28.02.2026
A2: Stichtag | B2: Duration | C2: IAS 19 Zins | D2: Stichtags- zins UGB | E2: 5-Jahres- durchschnitts- zins | F2: 6-Jahres- durchschnitts- zins | G2: 7-Jahres- durchschnitts- zins | H2: 8-Jahres- durchschnitts- zins | I2: 9-Jahres- durchschnitts- zins | J2: 10-Jahres- durchschnitts- zins
A3: 46081 | B3: 4 | C3: 0.01 | D3: =ROUND(VLOOKUP(A3,Stichtagszins!A:AY,ROUND(B3,0)+1,0)/100,4) | E3: =ROUND(VLOOKUP(A3,'5J-Zins'!A:AY,ROUND(B3,0)+1,0)/100,4) | F3: =ROUND(VLOOKUP(A3,'6J-Zins'!A:AY,ROUND(B3,0)+1,0)/100,4) | G3: =ROUND(VLOOKUP(A3,'7J-Zins'!A:AY,ROUND(B3,0)+1,0)/100,4) | H3: =ROUND(VLOOKUP(A3,'8J-Zins'!A:AY,ROUND(B3,0)+1,0)/100,4) | I3: =ROUND(VLOOKUP(A3,'9J-Zins'!A:AY,ROUND(B3,0)+1,0)/100,4) | J3: =ROUND(VLOOKUP(A3,'10J-Zins'!A:AY,ROUND(B3,0)+1,0)/100,4)
A4: =DATE(YEAR(A3+1)+1,MONTH(A3+1),DAY(A3+1))-1 | B4: =B3 | C4: 0.01 | D4: =ROUND(VLOOKUP(A4,Stichtagszins!A3:AY482,ROUND(B4,0)+1,0)/100,4) | E4: =ROUND(VLOOKUP(A4,'5J-Zins'!A:AY,ROUND(B4,0)+1,0)/100,4) | F4: =ROUND(VLOOKUP(A4,'6J-Zins'!A:AY,ROUND(B4,0)+1,0)/100,4) | G4: =ROUND(VLOOKUP(A4,'7J-Zins'!A:AY,ROUND(B4,0)+1,0)/100,4) | H4: =ROUND(VLOOKUP(A4,'8J-Zins'!A:AY,ROUND(B4,0)+1,0)/100,4) | I4: =ROUND(VLOOKUP(A4,'9J-Zins'!A:AY,ROUND(B4,0)+1,0)/100,4) | J4: =ROUND(VLOOKUP(A4,'10J-Zins'!A:AY,ROUND(B4,0)+1,0)/100,4)
A5: =DATE(YEAR(A4+1)+1,MONTH(A4+1),DAY(A4+1))-1 | B5: =B4 | C5: 0.01 | D5: =ROUND(VLOOKUP(A5,Stichtagszins!A4:AY483,ROUND(B5,0)+1,0)/100,4) | E5: =ROUND(VLOOKUP(A5,'5J-Zins'!A:AY,ROUND(B5,0)+1,0)/100,4) | F5: =ROUND(VLOOKUP(A5,'6J-Zins'!A:AY,ROUND(B5,0)+1,0)/100,4) | G5: =ROUND(VLOOKUP(A5,'7J-Zins'!A:AY,ROUND(B5,0)+1,0)/100,4) | H5: =ROUND(VLOOKUP(A5,'8J-Zins'!A:AY,ROUND(B5,0)+1,0)/100,4) | I5: =ROUND(VLOOKUP(A5,'9J-Zins'!A:AY,ROUND(B5,0)+1,0)/100,4) | J5: =ROUND(VLOOKUP(A5,'10J-Zins'!A:AY,ROUND(B5,0)+1,0)/100,4)
A6: =DATE(YEAR(A5+1)+1,MONTH(A5+1),DAY(A5+1))-1 | B6: =B5 | C6: 0.01 | D6: =ROUND(VLOOKUP(A6,Stichtagszins!A5:AY484,ROUND(B6,0)+1,0)/100,4) | E6: =ROUND(VLOOKUP(A6,'5J-Zins'!A:AY,ROUND(B6,0)+1,0)/100,4) | F6: =ROUND(VLOOKUP(A6,'6J-Zins'!A:AY,ROUND(B6,0)+1,0)/100,4) | G6: =ROUND(VLOOKUP(A6,'7J-Zins'!A:AY,ROUND(B6,0)+1,0)/100,4) | H6: =ROUND(VLOOKUP(A6,'8J-Zins'!A:AY,ROUND(B6,0)+1,0)/100,4) | I6: =ROUND(VLOOKUP(A6,'9J-Zins'!A:AY,ROUND(B6,0)+1,0)/100,4) | J6: =ROUND(VLOOKUP(A6,'10J-Zins'!A:AY,ROUND(B6,0)+1,0)/100,4)
A7: =DATE(YEAR(A6+1)+1,MONTH(A6+1),DAY(A6+1))-1 | B7: =B6 | C7: 0.01 | D7: =ROUND(VLOOKUP(A7,Stichtagszins!A6:AY485,ROUND(B7,0)+1,0)/100,4) | E7: =ROUND(VLOOKUP(A7,'5J-Zins'!A:AY,ROUND(B7,0)+1,0)/100,4) | F7: =ROUND(VLOOKUP(A7,'6J-Zins'!A:AY,ROUND(B7,0)+1,0)/100,4) | G7: =ROUND(VLOOKUP(A7,'7J-Zins'!A:AY,ROUND(B7,0)+1,0)/100,4) | H7: =ROUND(VLOOKUP(A7,'8J-Zins'!A:AY,ROUND(B7,0)+1,0)/100,4) | I7: =ROUND(VLOOKUP(A7,'9J-Zins'!A:AY,ROUND(B7,0)+1,0)/100,4) | J7: =ROUND(VLOOKUP(A7,'10J-Zins'!A:AY,ROUND(B7,0)+1,0)/100,4)
A8: =DATE(YEAR(A7+1)+1,MONTH(A7+1),DAY(A7+1))-1 | B8: =B7 | C8: 0.01 | D8: =ROUND(VLOOKUP(A8,Stichtagszins!A7:AY486,ROUND(B8,0)+1,0)/100,4) | E8: =ROUND(VLOOKUP(A8,'5J-Zins'!A:AY,ROUND(B8,0)+1,0)/100,4) | F8: =ROUND(VLOOKUP(A8,'6J-Zins'!A:AY,ROUND(B8,0)+1,0)/100,4) | G8: =ROUND(VLOOKUP(A8,'7J-Zins'!A:AY,ROUND(B8,0)+1,0)/100,4) | H8: =ROUND(VLOOKUP(A8,'8J-Zins'!A:AY,ROUND(B8,0)+1,0)/100,4) | I8: =ROUND(VLOOKUP(A8,'9J-Zins'!A:AY,ROUND(B8,0)+1,0)/100,4) | J8: =ROUND(VLOOKUP(A8,'10J-Zins'!A:AY,ROUND(B8,0)+1,0)/100,4)
A9: =DATE(YEAR(A8+1)+1,MONTH(A8+1),DAY(A8+1))-1 | B9: =B8 | C9: 0.01 | D9: =ROUND(VLOOKUP(A9,Stichtagszins!A8:AY487,ROUND(B9,0)+1,0)/100,4) | E9: =ROUND(VLOOKUP(A9,'5J-Zins'!A:AY,ROUND(B9,0)+1,0)/100,4) | F9: =ROUND(VLOOKUP(A9,'6J-Zins'!A:AY,ROUND(B9,0)+1,0)/100,4) | G9: =ROUND(VLOOKUP(A9,'7J-Zins'!A:AY,ROUND(B9,0)+1,0)/100,4) | H9: =ROUND(VLOOKUP(A9,'8J-Zins'!A:AY,ROUND(B9,0)+1,0)/100,4) | I9: =ROUND(VLOOKUP(A9,'9J-Zins'!A:AY,ROUND(B9,0)+1,0)/100,4) | J9: =ROUND(VLOOKUP(A9,'10J-Zins'!A:AY,ROUND(B9,0)+1,0)/100,4)
A10: =DATE(YEAR(A9+1)+1,MONTH(A9+1),DAY(A9+1))-1 | B10: =B9 | C10: 0.01 | D10: =ROUND(VLOOKUP(A10,Stichtagszins!A9:AY488,ROUND(B10,0)+1,0)/100,4) | E10: =ROUND(VLOOKUP(A10,'5J-Zins'!A:AY,ROUND(B10,0)+1,0)/100,4) | F10: =ROUND(VLOOKUP(A10,'6J-Zins'!A:AY,ROUND(B10,0)+1,0)/100,4) | G10: =ROUND(VLOOKUP(A10,'7J-Zins'!A:AY,ROUND(B10,0)+1,0)/100,4) | H10: =ROUND(VLOOKUP(A10,'8J-Zins'!A:AY,ROUND(B10,0)+1,0)/100,4) | I10: =ROUND(VLOOKUP(A10,'9J-Zins'!A:AY,ROUND(B10,0)+1,0)/100,4) | J10: =ROUND(VLOOKUP(A10,'10J-Zins'!A:AY,ROUND(B10,0)+1,0)/100,4)
A11: =DATE(YEAR(A10+1)+1,MONTH(A10+1),DAY(A10+1))-1 | B11: =B10 | C11: 0.01 | D11: =ROUND(VLOOKUP(A11,Stichtagszins!A10:AY489,ROUND(B11,0)+1,0)/100,4) | E11: =ROUND(VLOOKUP(A11,'5J-Zins'!A:AY,ROUND(B11,0)+1,0)/100,4) | F11: =ROUND(VLOOKUP(A11,'6J-Zins'!A:AY,ROUND(B11,0)+1,0)/100,4) | G11: =ROUND(VLOOKUP(A11,'7J-Zins'!A:AY,ROUND(B11,0)+1,0)/100,4) | H11: =ROUND(VLOOKUP(A11,'8J-Zins'!A:AY,ROUND(B11,0)+1,0)/100,4) | I11: =ROUND(VLOOKUP(A11,'9J-Zins'!A:AY,ROUND(B11,0)+1,0)/100,4) | J11: =ROUND(VLOOKUP(A11,'10J-Zins'!A:AY,ROUND(B11,0)+1,0)/100,4)
A12: =DATE(YEAR(A11+1)+1,MONTH(A11+1),DAY(A11+1))-1 | B12: =B11 | C12: 0.01 | D12: =ROUND(VLOOKUP(A12,Stichtagszins!A11:AY490,ROUND(B12,0)+1,0)/100,4) | E12: =ROUND(VLOOKUP(A12,'5J-Zins'!A:AY,ROUND(B12,0)+1,0)/100,4) | F12: =ROUND(VLOOKUP(A12,'6J-Zins'!A:AY,ROUND(B12,0)+1,0)/100,4) | G12: =ROUND(VLOOKUP(A12,'7J-Zins'!A:AY,ROUND(B12,0)+1,0)/100,4) | H12: =ROUND(VLOOKUP(A12,'8J-Zins'!A:AY,ROUND(B12,0)+1,0)/100,4) | I12: =ROUND(VLOOKUP(A12,'9J-Zins'!A:AY,ROUND(B12,0)+1,0)/100,4) | J12: =ROUND(VLOOKUP(A12,'10J-Zins'!A:AY,ROUND(B12,0)+1,0)/100,4)
A13: =DATE(YEAR(A12+1)+1,MONTH(A12+1),DAY(A12+1))-1 | B13: =B12 | C13: 0.01 | D13: =ROUND(VLOOKUP(A13,Stichtagszins!A12:AY491,ROUND(B13,0)+1,0)/100,4) | E13: =ROUND(VLOOKUP(A13,'5J-Zins'!A:AY,ROUND(B13,0)+1,0)/100,4) | F13: =ROUND(VLOOKUP(A13,'6J-Zins'!A:AY,ROUND(B13,0)+1,0)/100,4) | G13: =ROUND(VLOOKUP(A13,'7J-Zins'!A:AY,ROUND(B13,0)+1,0)/100,4) | H13: =ROUND(VLOOKUP(A13,'8J-Zins'!A:AY,ROUND(B13,0)+1,0)/100,4) | I13: =ROUND(VLOOKUP(A13,'9J-Zins'!A:AY,ROUND(B13,0)+1,0)/100,4) | J13: =ROUND(VLOOKUP(A13,'10J-Zins'!A:AY,ROUND(B13,0)+1,0)/100,4)

Sheet iboxx-corpAA
A1: Stichtag | B1: Annual Yield in % | C1: Annual Modified Duration | D1: Zinsswap zur annual mod. Duration Stichtag | E1: Aufschlag Stichtag | G1: Annual Yield in % 5-Year-Aver. | H1: Annual Modified Duration 5-Year-Aver. | I1: Zinsswap zur annual mod. Duration 5-Year-Aver. | J1: Aufschlag 5-Year-Aver. | L1: Annual Yield in % 6-Year-Aver. | M1: Annual Modified Duration 6-Year-Aver. | N1: Zinsswap zur annual mod. Duration 6-Year-Aver. | O1: Aufschlag 6-Year-Aver. | Q1: Annual Yield in % 7-Year-Aver. | R1: Annual Modified Duration 7-Year-Aver. | S1: Zinsswap zur annual mod. Duration 7-Year-Aver. | T1: Aufschlag 7-Year-Aver. | V1: Annual Yield in % 8-Year-Aver. | W1: Annual Modified Duration 8-Year-Aver. | X1: Zinsswap zur annual mod. Duration 8-Year-Aver. | Y1: Aufschlag 8-Year-Aver. | AA1: Annual Yield in % 9-Year-Aver. | AB1: Annual Modified Duration 9-Year-Aver. | AC1: Zinsswap zur annual mod. Duration 9-Year-Aver. | AD1: Aufschlag 9-Year-Aver. | AF1: Annual Yield in % 10-Year-Aver. | AG1: Annual Modified Duration 10-Year-Aver. | AH1: Zinsswap zur annual mod. Duration 10-Year-Aver. | AI1: Aufschlag 10-Year-Aver.
A2: 37287 | B2: 5.31 | C2: 5.16
A3: 37315 | B3: 5.32 | C3: 5.08
A4: 37346 | B4: 5.6 | C4: 5.08
A5: 37376 | B5: 5.45 | C5: 5.01
A6: 37407 | B6: 5.51 | C6: 5.03
A7: 37437 | B7: 5.32 | C7: 5.06
A8: 37468 | B8: 5.17 | C8: 5
A9: 37499 | B9: 4.95 | C9: 4.98
A10: 37529 | B10: 4.67 | C10: 4.98
A11: 37560 | B11: 4.85 | C11: 4.85
A12: 37590 | B12: 4.75 | C12: 4.95
A13: 37621 | B13: 4.45 | C13: 5.02
... A84: 39782 | B84: 6.33 | C84: 3.93
A85: 39813 | B85: 6.06 | C85: 3.87 | D85: 3.08855 | E85: 2.97145 | G85: 4.4533333 | H85: 4.7113333 | I85: 3.7677879 | J85: 0.68554546 | L85: 4.3979167 | M85: 4.74125 | N85: 3.7140809 | O85: 0.6838358 | Q85: 4.5 | R85: 4.7805952 | S85: 3.8247617 | T85: 0.67523828
A86: 39844 | B86: 5.69 | C86: 3.75 | D86: 2.741 | E86: 2.949 | G86: 4.4783333 | H86: 4.6931667 | I86: 3.755714 | J86: 0.72261933 | L86: 4.4173611 | M86: 4.7241667 | N86: 3.7049262 | O86: 0.71243492 | Q86: 4.5045238 | R86: 4.7638095 | S86: 3.8015679 | T86: 0.70295592
A87: 39872 | B87: 5.6 | C87: 3.79 | D87: 2.55597 | E87: 3.04403 | G87: 4.5053333 | H87: 4.6751667 | I87: 3.7449136 | J87: 0.76041974 | L87: 4.4388889 | M87: 4.7097222 | N87: 3.6973183 | O87: 0.7415706 | Q87: 4.5078571 | R87: 4.7484524 | S87: 3.7760817 | T87: 0.73177549
A88: 39903 | B88: 5.69 | C88: 3.81 | D88: 2.37591 | E88: 3.31409 | G88: 4.536 | H88: 4.6568333 | I88: 3.7342538 | J88: 0.80174616 | L88: 4.4601389 | M88: 4.6955556 | N88: 3.6851176 | O88: 0.7750213 | Q88: 4.5089286 | R88: 4.7333333 | S88: 3.7444976 | T88: 0.76443095
A89: 39933 | B89: 5.27 | C89: 3.83 | D89: 2.39713 | E89: 2.87287 | G89: 4.5556667 | H89: 4.6418333 | I89: 3.718637 | J89: 0.8370297 | L89: 4.4758333 | M89: 4.6816667 | N89: 3.67322 | O89: 0.80261329 | Q89: 4.5067857 | R89: 4.7192857 | S89: 3.7155193 | T89: 0.79126644
A90: 39964 | B90: 4.83 | C90: 3.8 | D90: 2.4662 | E90: 2.3638 | G90: 4.5666667 | H90: 4.6285 | I90: 3.7015857 | J90: 0.86508097 | L90: 4.4905556 | M90: 4.665 | N90: 3.6684977 | O90: 0.82205785 | Q90: 4.4986905 | R90: 4.7046429 | S90: 3.6870752 | T90: 0.81161528
A91: 39994 | B91: 4.49 | C91: 3.85 | D91: 2.5496 | E91: 1.9404 | G91: 4.5713333 | H91: 4.6158333 | I91: 3.6851803 | J91: 0.886153 | L91: 4.5002778 | M91: 4.6497222 | N91: 3.6634027 | O91: 0.83687508 | Q91: 4.4888095 | R91: 4.6902381 | S91: 3.6621679 | T91: 0.82664162
A92: 40025 | B92: 4.01 | C92: 3.94 | D92: 2.5003 | E92: 1.5097 | G92: 4.5696667 | H92: 4.604 | I92: 3.6690693 | J92: 0.90059733 | L92: 4.4984722 | M92: 4.6368056 | N92: 3.650373 | O92: 0.84809925 | Q92: 4.475 | R92: 4.677619 | S92: 3.639409 | T92: 0.83559103
A93: 40056 | B93: 3.93 | C93: 3.89 | D93: 2.47292 | E93: 1.45708 | G93: 4.5701667 | H93: 4.5901667 | I93: 3.6564191 | J93: 0.91374757 | L93: 4.4943056 | M93: 4.6220833 | N93: 3.6359626 | O93: 0.85834293 | Q93: 4.4628571 | R93: 4.6646429 | S93: 3.6192059 | T93: 0.8436512
A94: 40086 | B94: 3.79 | C94: 3.9 | D94: 2.4148 | E94: 1.3752 | G94: 4.5678333 | H94: 4.5751667 | I94: 3.6426749 | J94: 0.92515842 | L94: 4.4920833 | M94: 4.6077778 | N94: 3.6251381 | O94: 0.86694522 | Q94: 4.452381 | R94: 4.6517857 | S94: 3.6029013 | T94: 0.8494797
A95: 40117 | B95: 3.73 | C95: 3.96 | D95: 2.52256 | E95: 1.20744 | G95: 4.5658333 | H95: 4.558 | I95: 3.6324254 | J95: 0.9334079 | L95: 4.4844444 | M95: 4.5956944 | N95: 3.6098142 | O95: 0.87463024 | Q95: 4.4390476 | R95: 4.6411905 | S95: 3.5863189 | T95: 0.85272872
A96: 40147 | B96: 3.65 | C96: 3.96 | D96: 2.42192 | E96: 1.22808 | G96: 4.5645 | H96: 4.54 | I96: 3.6223283 | J96: 0.94217167 | L96: 4.47375 | M96: 4.5840278 | N96: 3.5908991 | O96: 0.88285088 | Q96: 4.4259524 | R96: 4.6294048 | S96: 3.5683589 | T96: 0.85759345
A97: 40178 | B97: 3.78 | C97: 3.89 | D97: 2.52302 | E97: 1.25698 | G97: 4.5658333 | H97: 4.5195 | I97: 3.613933 | J97: 0.95190036 | L97: 4.4675 | M97: 4.5701389 | N97: 3.5766908 | O97: 0.89080921 | Q97: 4.4179762 | R97: 4.6159524 | S97: 3.5561969 | T97: 0.86177931 | V97: 4.5047917 | W97: 4.6660417 | X97: 3.6726649 | Y97: 0.83212672
A98: 40209 | B98: 3.55 | C98: 3.97 | D98: 2.32961 | E98: 1.22039 | G98: 4.5658333 | H98: 4.5 | I98: 3.603525 | J98: 0.96230833 | L98: 4.4586111 | M98: 4.5580556 | N98: 3.5606223 | O98: 0.89798882 | Q98: 4.4091667 | R98: 4.6039286 | S98: 3.5433261 | T98: 0.8658406 | V98: 4.4864583 | W98: 4.6536458 | X98: 3.6479366 | Y98: 0.83852178
A99: 40237 | B99: 3.46 | C99: 3.98 | D99: 2.15396 | E99: 1.30604 | G99: 4.5623333 | H99: 4.482 | I99: 3.5874755 | J99: 0.97485787 | L99: 4.4513889 | M99: 4.5456944 | N99: 3.5462251 | O99: 0.90516383 | Q99: 4.4021429 | R99: 4.5938095 | S99: 3.5323295 | T99: 0.86981331 | V99: 4.4670833 | W99: 4.6421875 | X99: 3.6217034 | Y99: 0.84537993
A100: 40268 | B100: 3.43 | C100: 4 | D100: 2.12 | E100: 1.31 | G100: 4.5588333 | H100: 4.4656667 | I100: 3.5722355 | J100: 0.98659786 | L100: 4.4455556 | M100: 4.5330556 | N100: 3.5331887 | O100: 0.91236683 | Q100: 4.3934524 | R100: 4.5839286 | S100: 3.5184664 | T100: 0.87498597 | V100: 4.4444792 | W100: 4.6309375 | X100: 3.5910152 | Y100: 0.85346397
A101: 40298 | B101: 3.35 | C101: 4.12 | D101: 2.07656 | E101: 1.27344 | G101: 4.5573333 | H101: 4.4505 | I101: 3.5595472 | J101: 0.99778613 | L101: 4.4352778 | M101: 4.5245833 | N101: 3.5148007 | O101: 0.92047712 | Q101: 4.3840476 | R101: 4.5754762 | S101: 3.5037875 | T101: 0.88026016 | V101: 4.4226042 | W101: 4.6216667 | X101: 3.5617152 | Y101: 0.86088894
A102: 40329 | B102: 3.45 | C102: 4.3 | D102: 1.9441 | E102: 1.5059 | G102: 4.5596667 | H102: 4.4386667 | I102: 3.5463689 | J102: 1.0132978 | L102: 4.4252778 | M102: 4.5204167 | N102: 3.4911329 | O102: 0.93414483 | Q102: 4.3802381 | R102: 4.5671429 | S102: 3.4916961 | T102: 0.88854202 | V102: 4.4011458 | W102: 4.6140625 | X102: 3.5297764 | Y102: 0.87136948
A103: 40359 | B103: 3.47 | C103: 4.29 | D103: 1.90785 | E103: 1.56215 | G103: 4.5651667 | H103: 4.427 | I103: 3.5356474 | J103: 1.0295193 | L103: 4.415 | M103: 4.5159722 | N103: 3.4670258 | O103: 0.94797417 | Q103: 4.3764286 | R103: 4.5592857 | S103: 3.4785103 | T103: 0.89791823 | V103: 4.381875 | W103: 4.6060417 | X103: 3.5002424 | Y103: 0.88163256
A104: 40390 | B104: 3.33 | C104: 4.28 | D104: 1.9746 | E104: 1.3554 | G104: 4.5663333 | H104: 4.4148333 | I104: 3.5224993 | J104: 1.0438341 | L104: 4.4041667 | M104: 4.5108333 | N104: 3.445115 | O104: 0.95905169 | Q104: 4.3667857 | R104: 4.5522619 | S104: 3.4601785 | T104: 0.90660717 | V104: 4.3627083 | W104: 4.5985417 | X104: 3.4740567 | Y104: 0.88865161
A105: 40421 | B105: 2.93 | C105: 4.4 | D105: 1.604 | E105: 1.326 | G105: 4.5626667 | H105: 4.4036667 | I105: 3.504414 | J105: 1.0582526 | L105: 4.3906944 | M105: 4.5063889 | N105: 3.4209388 | O105: 0.96975563 | Q105: 4.3513095 | R105: 4.5457143 | S105: 3.4362412 | T105: 0.91506837 | V105: 4.3416667 | W105: 4.5925 | X105: 3.4462836 | Y105: 0.89538307
A106: 40451 | B106: 3.13 | C106: 4.34 | D106: 1.85082 | E106: 1.27918 | G106: 4.5611667 | H106: 4.3928333 | I106: 3.4879343 | J106: 1.0732324 | L106: 4.3795833 | M106: 4.5 | N106: 3.4 | O106: 0.97958333 | Q106: 4.3415476 | R106: 4.5386905 | S106: 3.4189798 | T106: 0.92256781 | V106: 4.325625 | W106: 4.5858333 | X106: 3.425048 | Y106: 0.90057701
A107: 40482 | B107: 3.29 | C107: 4.3 | D107: 2.0336 | E107: 1.2564 | G107: 4.558 | H107: 4.3826667 | I107: 3.4699365 | J107: 1.0880635 | L107: 4.3718056 | M107: 4.4904167 | N107: 3.3834241 | O107: 0.98838141 | Q107: 4.3297619 | R107: 4.532381 | S107: 3.399157 | T107: 0.93060493 | V107: 4.309375 | W107: 4.5801042 | X107: 3.4047339 | Y107: 0.90464114
A108: 40512 | B108: 3.63 | C108: 4.21 | D108: 2.10081 | E108: 1.52919 | G108: 4.5591667 | H108: 4.3715 | I108: 3.4517186 | J108: 1.1074481 | L108: 4.3704167 | M108: 4.4788889 | N108: 3.3695635 | O108: 1.0008532 | Q108: 4.3203571 | R108: 4.5253571 | S108: 3.3785061 | T108: 0.94185103 | V108: 4.2977083 | W108: 4.5723958 | X108: 3.3851789 | Y108: 0.91252948
A109: 40543 | B109: 3.82 | C109: 4.19 | D109: 2.26124 | E109: 1.55876 | G109: 4.5645 | H109: 4.361 | I109: 3.4365743 | J109: 1.1279257 | L109: 4.3720833 | M109: 4.4659722 | N109: 3.3581662 | O109: 1.0139171 | Q109: 4.3154762 | R109: 4.5170238 | S109: 3.3629127 | T109: 0.95256351 | V109: 4.2911458 | W109: 4.56375 | X109: 3.3716823 | Y109: 0.91946352 | AA109: 4.3824074 | AB109: 4.6140741 | AC109: 3.4961233 | AD109: 0.88628409
A110: 40574 | B110: 4.07 | C110: 4.12 | D110: 2.65708 | E110: 1.41292 | G110: 4.5715 | H110: 4.3495 | I110: 3.4246516 | J110: 1.1468484 | L110: 4.3793056 | M110: 4.4518056 | N110: 3.3530226 | O110: 1.026283 | Q110: 4.3140476 | R110: 4.5084524 | S110: 3.352407 | T110: 0.96164065 | V110: 4.2888542 | W110: 4.5547917 | X110: 3.3633002 | Y110: 0.92555394 | AA110: 4.3709259 | AB110: 4.6044444 | AC110: 3.4766539 | AD110: 0.89427202
...

Sheet Zinsswaps
A1: Stichtag | B1: 1 Jahre | C1: 2 Jahre | D1: 3 Jahre | E1: 4 Jahre | F1: 5 Jahre | G1: 6 Jahre | H1: 7 Jahre | I1: 8 Jahre | J1: 9 Jahre | K1: 10 Jahre | L1: 11 Jahre | M1: 12 Jahre | N1: 13 Jahre | O1: 14 Jahre | P1: 15 Jahre | Q1: 16 Jahre | R1: 17 Jahre | S1: 18 Jahre | T1: 19 Jahre | U1: 20 Jahre | V1: 21 Jahre | W1: 22 Jahre | X1: 23 Jahre | Y1: 24 Jahre | Z1: 25 Jahre | AA1: 26 Jahre | AB1: 27 Jahre | AC1: 28 Jahre | AD1: 29 Jahre | AE1: 30 Jahre | AF1: 31 Jahre | AG1: 32 Jahre | AH1: 33 Jahre | AI1: 34 Jahre | AJ1: 35 Jahre | AK1: 36 Jahre | AL1: 37 Jahre | AM1: 38 Jahre | AN1: 39 Jahre | AO1: 40 Jahre | AP1: 41 Jahre | AQ1: 42 Jahre | AR1: 43 Jahre | AS1: 44 Jahre | AT1: 45 Jahre | AU1: 46 Jahre | AV1: 47 Jahre | AW1: 48 Jahre | AX1: 49 Jahre | AY1: 50 Jahre
A2: 37287 | B2: 3.662 | C2: 4.123 | D2: 4.415 | E2: 4.613 | F2: 4.777 | G2: 4.91 | H2: 5.025 | I2: 5.123 | J2: 5.187 | K2: 5.239 | L2: 5.288 | M2: 5.33 | N2: 5.368 | O2: 5.4 | P2: 5.429 | Q2: 5.445 | R2: 5.46 | S2: 5.473 | T2: 5.485 | U2: 5.5 | V2: 5.491 | W2: 5.486 | X2: 5.482 | Y2: 5.478 | Z2: 5.474 | AA2: 5.461 | AB2: 5.449 | AC2: 5.438 | AD2: 5.427 | AE2: 5.417 | AF2: 5.398 | AG2: 5.38 | AH2: 5.363 | AI2: 5.347 | AJ2: 5.332 | AK2: 5.318 | AL2: 5.304 | AM2: 5.291 | AN2: 5.279 | AO2: 5.268 | AP2: 5.256 | AQ2: 5.245 | AR2: 5.234 | AS2: 5.224 | AT2: 5.214 | AU2: 5.204 | AV2: 5.195 | AW2: 5.187 | AX2: 5.178 | AY2: 5.171
A3: 37315 | B3: 3.66 | C3: 4.1 | D3: 4.352 | E3: 4.602 | F3: 4.775 | G3: 4.922 | H3: 5.047 | I3: 5.146 | J3: 5.225 | K3: 5.291 | L3: 5.334 | M3: 5.37 | N3: 5.416 | O3: 5.455 | P3: 5.49 | Q3: 5.521 | R3: 5.549 | S3: 5.573 | T3: 5.595 | U3: 5.62 | V3: 5.616 | W3: 5.616 | X3: 5.617 | Y3: 5.617 | Z3: 5.618 | AA3: 5.602 | AB3: 5.588 | AC3: 5.574 | AD3: 5.562 | AE3: 5.55 | AF3: 5.531 | AG3: 5.513 | AH3: 5.496 | AI3: 5.48 | AJ3: 5.465 | AK3: 5.451 | AL3: 5.438 | AM3: 5.425 | AN3: 5.413 | AO3: 5.401 | AP3: 5.387 | AQ3: 5.374 | AR3: 5.361 | AS3: 5.349 | AT3: 5.337 | AU3: 5.326 | AV3: 5.315 | AW3: 5.305 | AX3: 5.295 | AY3: 5.286
A4: 37346 | B4: 4.027 | C4: 4.524 | D4: 4.811 | E4: 5.002 | F4: 5.146 | G4: 5.263 | H4: 5.363 | I4: 5.447 | J4: 5.516 | K4: 5.57 | L4: 5.622 | M4: 5.665 | N4: 5.701 | O4: 5.732 | P4: 5.758 | Q4: 5.781 | R4: 5.801 | S4: 5.818 | T4: 5.834 | U4: 5.85 | V4: 5.85 | W4: 5.852 | X4: 5.853 | Y4: 5.855 | Z4: 5.856 | AA4: 5.84 | AB4: 5.824 | AC4: 5.81 | AD4: 5.796 | AE4: 5.784 | AF4: 5.764 | AG4: 5.745 | AH4: 5.727 | AI4: 5.71 | AJ4: 5.694 | AK4: 5.679 | AL4: 5.665 | AM4: 5.652 | AN4: 5.639 | AO4: 5.627 | AP4: 5.608 | AQ4: 5.589 | AR4: 5.571 | AS4: 5.554 | AT4: 5.538 | AU4: 5.523 | AV4: 5.508 | AW4: 5.494 | AX4: 5.48 | AY4: 5.467
A5: 37376 | B5: 3.831 | C5: 4.292 | D5: 4.583 | E5: 4.798 | F5: 4.969 | G5: 5.114 | H5: 5.225 | I5: 5.319 | J5: 5.396 | K5: 5.449 | L5: 5.508 | M5: 5.557 | N5: 5.605 | O5: 5.646 | P5: 5.682 | Q5: 5.707 | R5: 5.73 | S5: 5.75 | T5: 5.768 | U5: 5.78 | V5: 5.783 | W5: 5.782 | X5: 5.781 | Y5: 5.781 | Z5: 5.78 | AA5: 5.761 | AB5: 5.743 | AC5: 5.727 | AD5: 5.712 | AE5: 5.698 | AF5: 5.68 | AG5: 5.663 | AH5: 5.647 | AI5: 5.632 | AJ5: 5.618 | AK5: 5.605 | AL5: 5.593 | AM5: 5.581 | AN5: 5.57 | AO5: 5.559 | AP5: 5.541 | AQ5: 5.524 | AR5: 5.508 | AS5: 5.492 | AT5: 5.477 | AU5: 5.463 | AV5: 5.449 | AW5: 5.436 | AX5: 5.424 | AY5: 5.412
A6: 37407 | B6: 4.041 | C6: 4.456 | D6: 4.697 | E6: 4.893 | F6: 5.046 | G6: 5.171 | H6: 5.274 | I6: 5.358 | J6: 5.426 | K6: 5.484 | L6: 5.535 | M6: 5.578 | N6: 5.619 | O6: 5.655 | P6: 5.685 | Q6: 5.712 | R6: 5.735 | S6: 5.755 | T6: 5.774 | U6: 5.79 | V6: 5.791 | W6: 5.792 | X6: 5.793 | Y6: 5.793 | Z6: 5.794 | AA6: 5.78 | AB6: 5.768 | AC6: 5.756 | AD6: 5.745 | AE6: 5.735 | AF6: 5.713 | AG6: 5.693 | AH6: 5.674 | AI6: 5.656 | AJ6: 5.639 | AK6: 5.623 | AL6: 5.608 | AM6: 5.593 | AN6: 5.58 | AO6: 5.567 | AP6: 5.549 | AQ6: 5.532 | AR6: 5.516 | AS6: 5.501 | AT6: 5.486 | AU6: 5.472 | AV6: 5.459 | AW6: 5.446 | AX6: 5.434 | AY6: 5.422
A7: 37437 | B7: 3.792 | C7: 4.152 | D7: 4.414 | E7: 4.619 | F7: 4.774 | G7: 4.916 | H7: 5.036 | I7: 5.137 | J7: 5.22 | K7: 5.286 | L7: 5.34 | M7: 5.385 | N7: 5.422 | O7: 5.455 | P7: 5.482 | Q7: 5.495 | R7: 5.506 | S7: 5.516 | T7: 5.524 | U7: 5.53 | V7: 5.525 | W7: 5.518 | X7: 5.512 | Y7: 5.507 | Z7: 5.501 | AA7: 5.483 | AB7: 5.467 | AC7: 5.451 | AD7: 5.437 | AE7: 5.423 | AF7: 5.401 | AG7: 5.38 | AH7: 5.36 | AI7: 5.341 | AJ7: 5.324 | AK7: 5.307 | AL7: 5.292 | AM7: 5.277 | AN7: 5.263 | AO7: 5.249 | AP7: 5.232 | AQ7: 5.216 | AR7: 5.2 | AS7: 5.185 | AT7: 5.171 | AU7: 5.158 | AV7: 5.145 | AW7: 5.132 | AX7: 5.12 | AY7: 5.109
A8: 37468 | B8: 3.518 | C8: 3.813 | D8: 4.107 | E8: 4.346 | F8: 4.535 | G8: 4.698 | H8: 4.831 | I8: 4.94 | J8: 5.024 | K8: 5.103 | L8: 5.165 | M8: 5.217 | N8: 5.261 | O8: 5.3 | P8: 5.333 | Q8: 5.356 | R8: 5.377 | S8: 5.395 | T8: 5.412 | U8: 5.43 | V8: 5.419 | W8: 5.412 | X8: 5.406 | Y8: 5.4 | Z8: 5.395 | AA8: 5.376 | AB8: 5.359 | AC8: 5.343 | AD8: 5.328 | AE8: 5.314 | AF8: 5.29 | AG8: 5.268 | AH8: 5.247 | AI8: 5.228 | AJ8: 5.21 | AK8: 5.192 | AL8: 5.176 | AM8: 5.16 | AN8: 5.146 | AO8: 5.132 | AP8: 5.117 | AQ8: 5.102 | AR8: 5.089 | AS8: 5.076 | AT8: 5.063 | AU8: 5.051 | AV8: 5.04 | AW8: 5.029 | AX8: 5.019 | AY8: 5.009
A9: 37499 | B9: 3.427 | C9: 3.644 | D9: 3.89 | E9: 4.112 | F9: 4.291 | G9: 4.468 | H9: 4.606 | I9: 4.725 | J9: 4.822 | K9: 4.9 | L9: 4.964 | M9: 5.018 | N9: 5.064 | O9: 5.104 | P9: 5.138 | Q9: 5.167 | R9: 5.193 | S9: 5.216 | T9: 5.237 | U9: 5.26 | V9: 5.256 | W9: 5.256 | X9: 5.256 | Y9: 5.257 | Z9: 5.257 | AA9: 5.236 | AB9: 5.217 | AC9: 5.2 | AD9: 5.183 | AE9: 5.168 | AF9: 5.148 | AG9: 5.13 | AH9: 5.113 | AI9: 5.096 | AJ9: 5.081 | AK9: 5.067 | AL9: 5.053 | AM9: 5.04 | AN9: 5.028 | AO9: 5.016 | AP9: 5.001 | AQ9: 4.986 | AR9: 4.972 | AS9: 4.959 | AT9: 4.946 | AU9: 4.934 | AV9: 4.922 | AW9: 4.911 | AX9: 4.9 | AY9: 4.89
A10: 37529 | B10: 3.06 | C10: 3.235 | D10: 3.492 | E10: 3.719 | F10: 3.919 | G10: 4.107 | H10: 4.287 | I10: 4.428 | J10: 4.548 | K10: 4.644 | L10: 4.729 | M10: 4.799 | N10: 4.867 | O10: 4.926 | P10: 4.977 | Q10: 5.017 | R10: 5.052 | S10: 5.083 | T10: 5.111 | U10: 5.14 | V10: 5.142 | W10: 5.148 | X10: 5.153 | Y10: 5.158 | Z10: 5.163 | AA10: 5.147 | AB10: 5.133 | AC10: 5.119 | AD10: 5.107 | AE10: 5.095 | AF10: 5.073 | AG10: 5.052 | AH10: 5.032 | AI10: 5.013 | AJ10: 4.996 | AK10: 4.979 | AL10: 4.963 | AM10: 4.949 | AN10: 4.934 | AO10: 4.921 | AP10: 4.905 | AQ10: 4.89 | AR10: 4.875 | AS10: 4.862 | AT10: 4.848 | AU10: 4.836 | AV10: 4.824 | AW10: 4.812 | AX10: 4.801 | AY10: 4.79
A11: 37560 | B11: 3.085 | C11: 3.273 | D11: 3.56 | E11: 3.826 | F11: 4.049 | G11: 4.261 | H11: 4.453 | I11: 4.602 | J11: 4.727 | K11: 4.829 | L11: 4.909 | M11: 4.976 | N11: 5.047 | O11: 5.108 | P11: 5.161 | Q11: 5.201 | R11: 5.237 | S11: 5.269 | T11: 5.297 | U11: 5.32 | V11: 5.33 | W11: 5.336 | X11: 5.342 | Y11: 5.348 | Z11: 5.353 | AA11: 5.335 | AB11: 5.318 | AC11: 5.302 | AD11: 5.288 | AE11: 5.274 | AF11: 5.252 | AG11: 5.231 | AH11: 5.212 | AI11: 5.193 | AJ11: 5.176 | AK11: 5.16 | AL11: 5.144 | AM11: 5.13 | AN11: 5.116 | AO11: 5.102 | AP11: 5.084 | AQ11: 5.066 | AR11: 5.049 | AS11: 5.032 | AT11: 5.017 | AU11: 5.002 | AV11: 4.988 | AW11: 4.974 | AX11: 4.961 | AY11: 4.948
A12: 37590 | B12: 3.005 | C12: 3.282 | D12: 3.569 | E12: 3.837 | F12: 4.056 | G12: 4.254 | H12: 4.423 | I12: 4.568 | J12: 4.691 | K12: 4.796 | L12: 4.887 | M12: 4.964 | N12: 5.028 | O12: 5.084 | P12: 5.131 | Q12: 5.169 | R12: 5.202 | S12: 5.232 | T12: 5.258 | U12: 5.28 | V12: 5.29 | W12: 5.297 | X12: 5.304 | Y12: 5.31 | Z12: 5.316 | AA12: 5.301 | AB12: 5.288 | AC12: 5.275 | AD12: 5.264 | AE12: 5.253 | AF12: 5.23 | AG12: 5.209 | AH12: 5.189 | AI12: 5.17 | AJ12: 5.152 | AK12: 5.135 | AL12: 5.119 | AM12: 5.104 | AN12: 5.09 | AO12: 5.077 | AP12: 5.059 | AQ12: 5.042 | AR12: 5.026 | AS12: 5.01 | AT12: 4.996 | AU12: 4.982 | AV12: 4.968 | AW12: 4.955 | AX12: 4.943 | AY12: 4.931
A13: 37621 | B13: 2.722 | C13: 2.892 | D13: 3.167 | E13: 3.441 | F13: 3.689 | G13: 3.905 | H13: 4.084 | I13: 4.259 | J13: 4.377 | K13: 4.524 | L13: 4.611 | M13: 4.684 | N13: 4.755 | O13: 4.816 | P13: 4.869 | Q13: 4.923 | R13: 4.971 | S13: 5.013 | T13: 5.051 | U13: 5.09 | V13: 5.093 | W13: 5.1 | X13: 5.106 | Y13: 5.112 | Z13: 5.118 | AA13: 5.104 | AB13: 5.092 | AC13: 5.081 | AD13: 5.07 | AE13: 5.061 | AF13: 5.039 | AG13: 5.018 | AH13: 4.999 | AI13: 4.981 | AJ13: 4.963 | AK13: 4.947 | AL13: 4.932 | AM13: 4.917 | AN13: 4.904 | AO13: 4.89 | AP13: 4.873 | AQ13: 4.856 | AR13: 4.84 | AS13: 4.825 | AT13: 4.81 | AU13: 4.796 | AV13: 4.783 | AW13: 4.77 | AX13: 4.758 | AY13: 4.746
... A481: 51866 | B481: 2.141 | C481: 2.149 | D481: 2.195 | E481: 2.266 | F481: 2.336 | G481: 2.412 | H481: 2.485 | I481: 2.556 | J481: 2.623 | K481: 2.685 | L481: 2.747 | M481: 2.798 | N481: 2.849 | O481: 2.892 | P481: 2.929 | Q481: 2.955 | R481: 2.978 | S481: 2.999 | T481: 3.017 | U481: 3.034 | V481: 3.035 | W481: 3.036 | X481: 3.037 | Y481: 3.038 | Z481: 3.039 | AA481: 3.031 | AB481: 3.023 | AC481: 3.015 | AD481: 3.008 | AE481: 3.002 | AF481: 2.985 | AG481: 2.969 | AH481: 2.955 | AI481: 2.941 | AJ481: 2.928 | AK481: 2.915 | AL481: 2.904 | AM481: 2.893 | AN481: 2.882 | AO481: 2.872 | AP481: 2.85 | AQ481: 2.829 | AR481: 2.808 | AS481: 2.789 | AT481: 2.77 | AU481: 2.753 | AV481: 2.736 | AW481: 2.72 | AX481: 2.704 | AY481: 2.689

Sheet Stichtagszins
A1: Stichtag | B1: 1 Jahre | C1: 2 Jahre | D1: 3 Jahre | E1: 4 Jahre | F1: 5 Jahre | G1: 6 Jahre | H1: 7 Jahre | I1: 8 Jahre | J1: 9 Jahre | K1: 10 Jahre | L1: 11 Jahre | M1: 12 Jahre | N1: 13 Jahre | O1: 14 Jahre | P1: 15 Jahre | Q1: 16 Jahre | R1: 17 Jahre | S1: 18 Jahre | T1: 19 Jahre | U1: 20 Jahre | V1: 21 Jahre | W1: 22 Jahre | X1: 23 Jahre | Y1: 24 Jahre | Z1: 25 Jahre | AA1: 26 Jahre | AB1: 27 Jahre | AC1: 28 Jahre | AD1: 29 Jahre | AE1: 30 Jahre | AF1: 31 Jahre | AG1: 32 Jahre | AH1: 33 Jahre | AI1: 34 Jahre | AJ1: 35 Jahre | AK1: 36 Jahre | AL1: 37 Jahre | AM1: 38 Jahre | AN1: 39 Jahre | AO1: 40 Jahre | AP1: 41 Jahre | AQ1: 42 Jahre | AR1: 43 Jahre | AS1: 44 Jahre | AT1: 45 Jahre | AU1: 46 Jahre | AV1: 47 Jahre | AW1: 48 Jahre | AX1: 49 Jahre | AY1: 50 Jahre
A2: 37287 | B2: 4.17 | C2: 4.63 | D2: 4.93 | E2: 5.12 | F2: 5.29 | G2: 5.42 | H2: 5.54 | I2: 5.63 | J2: 5.7 | K2: 5.75 | L2: 5.8 | M2: 5.84 | N2: 5.88 | O2: 5.91 | P2: 5.94 | Q2: 5.96 | R2: 5.97 | S2: 5.98 | T2: 6 | U2: 6.01 | V2: 6 | W2: 6 | X2: 5.99 | Y2: 5.99 | Z2: 5.99 | AA2: 5.97 | AB2: 5.96 | AC2: 5.95 | AD2: 5.94 | AE2: 5.93 | AF2: 5.91 | AG2: 5.89 | AH2: 5.87 | AI2: 5.86 | AJ2: 5.84 | AK2: 5.83 | AL2: 5.82 | AM2: 5.8 | AN2: 5.79 | AO2: 5.78 | AP2: 5.77 | AQ2: 5.76 | AR2: 5.75 | AS2: 5.74 | AT2: 5.73 | AU2: 5.72 | AV2: 5.71 | AW2: 5.7 | AX2: 5.69 | AY2: 5.68
A3: 37315 | B3: 4.19 | C3: 4.63 | D3: 4.89 | E3: 5.14 | F3: 5.31 | G3: 5.46 | H3: 5.58 | I3: 5.68 | J3: 5.76 | K3: 5.82 | L3: 5.87 | M3: 5.9 | N3: 5.95 | O3: 5.99 | P3: 6.02 | Q3: 6.05 | R3: 6.08 | S3: 6.11 | T3: 6.13 | U3: 6.15 | V3: 6.15 | W3: 6.15 | X3: 6.15 | Y3: 6.15 | Z3: 6.15 | AA3: 6.14 | AB3: 6.12 | AC3: 6.11 | AD3: 6.1 | AE3: 6.08 | AF3: 6.06 | AG3: 6.05 | AH3: 6.03 | AI3: 6.01 | AJ3: 6 | AK3: 5.98 | AL3: 5.97 | AM3: 5.96 | AN3: 5.95 | AO3: 5.93 | AP3: 5.92 | AQ3: 5.91 | AR3: 5.89 | AS3: 5.88 | AT3: 5.87 | AU3: 5.86 | AV3: 5.85 | AW3: 5.84 | AX3: 5.83 | AY3: 5.82
A4: 37346 | B4: 4.47 | C4: 4.97 | D4: 5.26 | E4: 5.45 | F4: 5.59 | G4: 5.71 | H4: 5.81 | I4: 5.89 | J4: 5.96 | K4: 6.01 | L4: 6.07 | M4: 6.11 | N4: 6.15 | O4: 6.18 | P4: 6.2 | Q4: 6.23 | R4: 6.25 | S4: 6.26 | T4: 6.28 | U4: 6.29 | V4: 6.29 | W4: 6.3 | X4: 6.3 | Y4: 6.3 | Z4: 6.3 | AA4: 6.28 | AB4: 6.27 | AC4: 6.25 | AD4: 6.24 | AE4: 6.23 | AF4: 6.21 | AG4: 6.19 | AH4: 6.17 | AI4: 6.15 | AJ4: 6.14 | AK4: 6.12 | AL4: 6.11 | AM4: 6.1 | AN4: 6.08 | AO4: 6.07 | AP4: 6.05 | AQ4: 6.03 | AR4: 6.02 | AS4: 6 | AT4: 5.98 | AU4: 5.97 | AV4: 5.95 | AW4: 5.94 | AX4: 5.92 | AY4: 5.91
A5: 37376 | B5: 4.31 | C5: 4.77 | D5: 5.06 | E5: 5.28 | F5: 5.45 | G5: 5.59 | H5: 5.7 | I5: 5.8 | J5: 5.88 | K5: 5.93 | L5: 5.99 | M5: 6.04 | N5: 6.08 | O5: 6.13 | P5: 6.16 | Q5: 6.19 | R5: 6.21 | S5: 6.23 | T5: 6.25 | U5: 6.26 | V5: 6.26 | W5: 6.26 | X5: 6.26 | Y5: 6.26 | Z5: 6.26 | AA5: 6.24 | AB5: 6.22 | AC5: 6.21 | AD5: 6.19 | AE5: 6.18 | AF5: 6.16 | AG5: 6.14 | AH5: 6.13 | AI5: 6.11 | AJ5: 6.1 | AK5: 6.08 | AL5: 6.07 | AM5: 6.06 | AN5: 6.05 | AO5: 6.04 | AP5: 6.02 | AQ5: 6 | AR5: 5.99 | AS5: 5.97 | AT5: 5.96 | AU5: 5.94 | AV5: 5.93 | AW5: 5.92 | AX5: 5.9 | AY5: 5.89
A6: 37407 | B6: 4.5 | C6: 4.92 | D6: 5.16 | E6: 5.35 | F6: 5.51 | G6: 5.63 | H6: 5.73 | I6: 5.82 | J6: 5.89 | K6: 5.94 | L6: 6 | M6: 6.04 | N6: 6.08 | O6: 6.12 | P6: 6.15 | Q6: 6.17 | R6: 6.2 | S6: 6.22 | T6: 6.23 | U6: 6.25 | V6: 6.25 | W6: 6.25 | X6: 6.25 | Y6: 6.25 | Z6: 6.25 | AA6: 6.24 | AB6: 6.23 | AC6: 6.22 | AD6: 6.21 | AE6: 6.2 | AF6: 6.17 | AG6: 6.15 | AH6: 6.13 | AI6: 6.12 | AJ6: 6.1 | AK6: 6.08 | AL6: 6.07 | AM6: 6.05 | AN6: 6.04 | AO6: 6.03 | AP6: 6.01 | AQ6: 5.99 | AR6: 5.98 | AS6: 5.96 | AT6: 5.95 | AU6: 5.93 | AV6: 5.92 | AW6: 5.91 | AX6: 5.89 | AY6: 5.88
A7: 37437 | B7: 4.33 | C7: 4.69 | D7: 4.95 | E7: 5.16 | F7: 5.31 | G7: 5.45 | H7: 5.57 | I7: 5.67 | J7: 5.76 | K7: 5.82 | L7: 5.88 | M7: 5.92 | N7: 5.96 | O7: 5.99 | P7: 6.02 | Q7: 6.03 | R7: 6.04 | S7: 6.05 | T7: 6.06 | U7: 6.07 | V7: 6.06 | W7: 6.06 | X7: 6.05 | Y7: 6.04 | Z7: 6.04 | AA7: 6.02 | AB7: 6 | AC7: 5.99 | AD7: 5.97 | AE7: 5.96 | AF7: 5.94 | AG7: 5.92 | AH7: 5.9 | AI7: 5.88 | AJ7: 5.86 | AK7: 5.84 | AL7: 5.83 | AM7: 5.81 | AN7: 5.8 | AO7: 5.79 | AP7: 5.77 | AQ7: 5.75 | AR7: 5.74 | AS7: 5.72 | AT7: 5.71 | AU7: 5.7 | AV7: 5.68 | AW7: 5.67 | AX7: 5.66 | AY7: 5.65
A8: 37468 | B8: 4.15 | C8: 4.45 | D8: 4.74 | E8: 4.98 | F8: 5.17 | G8: 5.33 | H8: 5.47 | I8: 5.58 | J8: 5.66 | K8: 5.74 | L8: 5.8 | M8: 5.85 | N8: 5.9 | O8: 5.93 | P8: 5.97 | Q8: 5.99 | R8: 6.01 | S8: 6.03 | T8: 6.05 | U8: 6.06 | V8: 6.05 | W8: 6.05 | X8: 6.04 | Y8: 6.04 | Z8: 6.03 | AA8: 6.01 | AB8: 5.99 | AC8: 5.98 | AD8: 5.96 | AE8: 5.95 | AF8: 5.92 | AG8: 5.9 | AH8: 5.88 | AI8: 5.86 | AJ8: 5.84 | AK8: 5.83 | AL8: 5.81 | AM8: 5.79 | AN8: 5.78 | AO8: 5.77 | AP8: 5.75 | AQ8: 5.74 | AR8: 5.72 | AS8: 5.71 | AT8: 5.7 | AU8: 5.69 | AV8: 5.67 | AW8: 5.66 | AX8: 5.65 | AY8: 5.64
A9: 37499 | B9: 4.09 | C9: 4.31 | D9: 4.55 | E9: 4.77 | F9: 4.95 | G9: 5.13 | H9: 5.27 | I9: 5.39 | J9: 5.48 | K9: 5.56 | L9: 5.63 | M9: 5.68 | N9: 5.73 | O9: 5.77 | P9: 5.8 | Q9: 5.83 | R9: 5.86 | S9: 5.88 | T9: 5.9 | U9: 5.92 | V9: 5.92 | W9: 5.92 | X9: 5.92 | Y9: 5.92 | Z9: 5.92 | AA9: 5.9 | AB9: 5.88 | AC9: 5.86 | AD9: 5.85 | AE9: 5.83 | AF9: 5.81 | AG9: 5.79 | AH9: 5.78 | AI9: 5.76 | AJ9: 5.74 | AK9: 5.73 | AL9: 5.72 | AM9: 5.7 | AN9: 5.69 | AO9: 5.68 | AP9: 5.66 | AQ9: 5.65 | AR9: 5.63 | AS9: 5.62 | AT9: 5.61 | AU9: 5.6 | AV9: 5.58 | AW9: 5.57 | AX9: 5.56 | AY9: 5.55
A10: 37529 | B10: 3.81 | C10: 3.99 | D10: 4.25 | E10: 4.47 | F10: 4.67 | G10: 4.86 | H10: 5.04 | I10: 5.18 | J10: 5.3 | K10: 5.4 | L10: 5.48 | M10: 5.55 | N10: 5.62 | O10: 5.68 | P10: 5.73 | Q10: 5.77 | R10: 5.81 | S10: 5.84 | T10: 5.87 | U10: 5.89 | V10: 5.9 | W10: 5.9 | X10: 5.91 | Y10: 5.91 | Z10: 5.92 | AA10: 5.9 | AB10: 5.89 | AC10: 5.87 | AD10: 5.86 | AE10: 5.85 | AF10: 5.83 | AG10: 5.81 | AH10: 5.79 | AI10: 5.77 | AJ10: 5.75 | AK10: 5.73 | AL10: 5.72 | AM10: 5.7 | AN10: 5.69 | AO10: 5.68 | AP10: 5.66 | AQ10: 5.64 | AR10: 5.63 | AS10: 5.62 | AT10: 5.6 | AU10: 5.59 | AV10: 5.58 | AW10: 5.57 | AX10: 5.56 | AY10: 5.54
A11: 37560 | B11: 3.92 | C11: 4.11 | D11: 4.39 | E11: 4.66 | F11: 4.88 | G11: 5.1 | H11: 5.29 | I11: 5.44 | J11: 5.56 | K11: 5.66 | L11: 5.74 | M11: 5.81 | N11: 5.88 | O11: 5.94 | P11: 6 | Q11: 6.04 | R11: 6.07 | S11: 6.1 | T11: 6.13 | U11: 6.15 | V11: 6.16 | W11: 6.17 | X11: 6.18 | Y11: 6.18 | Z11: 6.19 | AA11: 6.17 | AB11: 6.15 | AC11: 6.14 | AD11: 6.12 | AE11: 6.11 | AF11: 6.09 | AG11: 6.07 | AH11: 6.05 | AI11: 6.03 | AJ11: 6.01 | AK11: 5.99 | AL11: 5.98 | AM11: 5.96 | AN11: 5.95 | AO11: 5.94 | AP11: 5.92 | AQ11: 5.9 | AR11: 5.88 | AS11: 5.87 | AT11: 5.85 | AU11: 5.84 | AV11: 5.82 | AW11: 5.81 | AX11: 5.8 | AY11: 5.78
A12: 37590 | B12: 3.71 | C12: 3.99 | D12: 4.27 | E12: 4.54 | F12: 4.76 | G12: 4.96 | H12: 5.13 | I12: 5.27 | J12: 5.4 | K12: 5.5 | L12: 5.59 | M12: 5.67 | N12: 5.73 | O12: 5.79 | P12: 5.84 | Q12: 5.87 | R12: 5.91 | S12: 5.94 | T12: 5.96 | U12: 5.98 | V12: 5.99 | W12: 6 | X12: 6.01 | Y12: 6.01 | Z12: 6.02 | AA12: 6.01 | AB12: 5.99 | AC12: 5.98 | AD12: 5.97 | AE12: 5.96 | AF12: 5.93 | AG12: 5.91 | AH12: 5.89 | AI12: 5.87 | AJ12: 5.86 | AK12: 5.84 | AL12: 5.82 | AM12: 5.81 | AN12: 5.79 | AO12: 5.78 | AP12: 5.76 | AQ12: 5.75 | AR12: 5.73 | AS12: 5.71 | AT12: 5.7 | AU12: 5.69 | AV12: 5.67 | AW12: 5.66 | AX12: 5.65 | AY12: 5.64
A13: 37621 | B13: 3.48 | C13: 3.65 | D13: 3.92 | E13: 4.2 | F13: 4.45 | G13: 4.66 | H13: 4.84 | I13: 5.02 | J13: 5.13 | K13: 5.28 | L13: 5.37 | M13: 5.44 | N13: 5.51 | O13: 5.57 | P13: 5.63 | Q13: 5.68 | R13: 5.73 | S13: 5.77 | T13: 5.81 | U13: 5.85 | V13: 5.85 | W13: 5.86 | X13: 5.86 | Y13: 5.87 | Z13: 5.87 | AA13: 5.86 | AB13: 5.85 | AC13: 5.84 | AD13: 5.83 | AE13: 5.82 | AF13: 5.8 | AG13: 5.77 | AH13: 5.76 | AI13: 5.74 | AJ13: 5.72 | AK13: 5.7 | AL13: 5.69 | AM13: 5.67 | AN13: 5.66 | AO13: 5.65 | AP13: 5.63 | AQ13: 5.61 | AR13: 5.6 | AS13: 5.58 | AT13: 5.57 | AU13: 5.55 | AV13: 5.54 | AW13: 5.53 | AX13: 5.51 | AY13: 5.5
... A481: 51866 | B481: 2.99 | C481: 3 | D481: 3.05 | E481: 3.12 | F481: 3.19 | G481: 3.27 | H481: 3.34 | I481: 3.41 | J481: 3.48 | K481: 3.54 | L481: 3.6 | M481: 3.65 | N481: 3.7 | O481: 3.75 | P481: 3.78 | Q481: 3.81 | R481: 3.83 | S481: 3.85 | T481: 3.87 | U481: 3.89 | V481: 3.89 | W481: 3.89 | X481: 3.89 | Y481: 3.89 | Z481: 3.89 | AA481: 3.88 | AB481: 3.88 | AC481: 3.87 | AD481: 3.86 | AE481: 3.86 | AF481: 3.84 | AG481: 3.82 | AH481: 3.81 | AI481: 3.79 | AJ481: 3.78 | AK481: 3.77 | AL481: 3.76 | AM481: 3.75 | AN481: 3.74 | AO481: 3.73 | AP481: 3.7 | AQ481: 3.68 | AR481: 3.66 | AS481: 3.64 | AT481: 3.62 | AU481: 3.61 | AV481: 3.59 | AW481: 3.57 | AX481: 3.56 | AY481: 3.54

Sheet 5J-Zins
A1: Stichtag | B1: 1 Jahre | C1: 2 Jahre | D1: 3 Jahre | E1: 4 Jahre | F1: 5 Jahre | G1: 6 Jahre | H1: 7 Jahre | I1: 8 Jahre | J1: 9 Jahre | K1: 10 Jahre | L1: 11 Jahre | M1: 12 Jahre | N1: 13 Jahre | O1: 14 Jahre | P1: 15 Jahre | Q1: 16 Jahre | R1: 17 Jahre | S1: 18 Jahre | T1: 19 Jahre | U1: 20 Jahre | V1: 21 Jahre | W1: 22 Jahre | X1: 23 Jahre | Y1: 24 Jahre | Z1: 25 Jahre | AA1: 26 Jahre | AB1: 27 Jahre | AC1: 28 Jahre | AD1: 29 Jahre | AE1: 30 Jahre | AF1: 31 Jahre | AG1: 32 Jahre | AH1: 33 Jahre | AI1: 34 Jahre | AJ1: 35 Jahre | AK1: 36 Jahre | AL1: 37 Jahre | AM1: 38 Jahre | AN1: 39 Jahre | AO1: 40 Jahre | AP1: 41 Jahre | AQ1: 42 Jahre | AR1: 43 Jahre | AS1: 44 Jahre | AT1: 45 Jahre | AU1: 46 Jahre | AV1: 47 Jahre | AW1: 48 Jahre | AX1: 49 Jahre | AY1: 50 Jahre
A2: 37287
A3: 37315
A4: 37346
A5: 37376
A6: 37407
A7: 37437
A8: 37468
A9: 37499
A10: 37529
A11: 37560
A12: 37590
A13: 37621
... A84: 39782
A85: 39813 | B85: 4.11 | C85: 4.19 | D85: 4.3 | E85: 4.39 | F85: 4.48 | G85: 4.56 | H85: 4.65 | I85: 4.72 | J85: 4.8 | K85: 4.86 | L85: 4.92 | M85: 4.97 | N85: 5.02 | O85: 5.06 | P85: 5.1 | Q85: 5.13 | R85: 5.15 | S85: 5.17 | T85: 5.19 | U85: 5.21 | V85: 5.21 | W85: 5.22 | X85: 5.22 | Y85: 5.22 | Z85: 5.23 | AA85: 5.22 | AB85: 5.22 | AC85: 5.21 | AD85: 5.21 | AE85: 5.2 | AF85: 5.2 | AG85: 5.19 | AH85: 5.18 | AI85: 5.17 | AJ85: 5.17 | AK85: 5.16 | AL85: 5.16 | AM85: 5.15 | AN85: 5.15 | AO85: 5.14 | AP85: 5.13 | AQ85: 5.12 | AR85: 5.12 | AS85: 5.11 | AT85: 5.1 | AU85: 5.09 | AV85: 5.09 | AW85: 5.08 | AX85: 5.07 | AY85: 5.07
A86: 39844 | B86: 4.15 | C86: 4.22 | D86: 4.32 | E86: 4.42 | F86: 4.51 | G86: 4.59 | H86: 4.67 | I86: 4.75 | J86: 4.82 | K86: 4.89 | L86: 4.95 | M86: 5 | N86: 5.05 | O86: 5.09 | P86: 5.12 | Q86: 5.15 | R86: 5.17 | S86: 5.19 | T86: 5.21 | U86: 5.23 | V86: 5.23 | W86: 5.23 | X86: 5.24 | Y86: 5.24 | Z86: 5.24 | AA86: 5.23 | AB86: 5.23 | AC86: 5.22 | AD86: 5.22 | AE86: 5.21 | AF86: 5.2 | AG86: 5.2 | AH86: 5.19 | AI86: 5.18 | AJ86: 5.17 | AK86: 5.17 | AL86: 5.16 | AM86: 5.15 | AN86: 5.15 | AO86: 5.14 | AP86: 5.13 | AQ86: 5.13 | AR86: 5.12 | AS86: 5.11 | AT86: 5.1 | AU86: 5.1 | AV86: 5.09 | AW86: 5.08 | AX86: 5.08 | AY86: 5.07
A87: 39872 | B87: 4.18 | C87: 4.25 | D87: 4.36 | E87: 4.45 | F87: 4.53 | G87: 4.62 | H87: 4.7 | I87: 4.78 | J87: 4.85 | K87: 4.91 | L87: 4.97 | M87: 5.02 | N87: 5.07 | O87: 5.11 | P87: 5.15 | Q87: 5.17 | R87: 5.19 | S87: 5.21 | T87: 5.23 | U87: 5.25 | V87: 5.25 | W87: 5.25 | X87: 5.25 | Y87: 5.25 | Z87: 5.25 | AA87: 5.25 | AB87: 5.24 | AC87: 5.23 | AD87: 5.23 | AE87: 5.22 | AF87: 5.21 | AG87: 5.2 | AH87: 5.19 | AI87: 5.18 | AJ87: 5.18 | AK87: 5.17 | AL87: 5.16 | AM87: 5.16 | AN87: 5.15 | AO87: 5.14 | AP87: 5.13 | AQ87: 5.13 | AR87: 5.12 | AS87: 5.11 | AT87: 5.1 | AU87: 5.09 | AV87: 5.09 | AW87: 5.08 | AX87: 5.07 | AY87: 5.07
A88: 39903 | B88: 4.21 | C88: 4.29 | D88: 4.39 | E88: 4.48 | F88: 4.57 | G88: 4.65 | H88: 4.73 | I88: 4.81 | J88: 4.88 | K88: 4.94 | L88: 5 | M88: 5.05 | N88: 5.1 | O88: 5.14 | P88: 5.18 | Q88: 5.2 | R88: 5.22 | S88: 5.24 | T88: 5.26 | U88: 5.27 | V88: 5.27 | W88: 5.27 | X88: 5.27 | Y88: 5.27 | Z88: 5.27 | AA88: 5.26 | AB88: 5.26 | AC88: 5.25 | AD88: 5.24 | AE88: 5.24 | AF88: 5.23 | AG88: 5.22 | AH88: 5.21 | AI88: 5.2 | AJ88: 5.19 | AK88: 5.18 | AL88: 5.18 | AM88: 5.17 | AN88: 5.16 | AO88: 5.16 | AP88: 5.15 | AQ88: 5.14 | AR88: 5.13 | AS88: 5.12 | AT88: 5.11 | AU88: 5.1 | AV88: 5.1 | AW88: 5.09 | AX88: 5.08 | AY88: 5.08
A89: 39933 | B89: 4.24 | C89: 4.31 | D89: 4.41 | E89: 4.5 | F89: 4.59 | G89: 4.67 | H89: 4.75 | I89: 4.83 | J89: 4.9 | K89: 4.96 | L89: 5.02 | M89: 5.07 | N89: 5.12 | O89: 5.16 | P89: 5.2 | Q89: 5.22 | R89: 5.24 | S89: 5.26 | T89: 5.28 | U89: 5.29 | V89: 5.29 | W89: 5.29 | X89: 5.29 | Y89: 5.29 | Z89: 5.29 | AA89: 5.28 | AB89: 5.27 | AC89: 5.26 | AD89: 5.25 | AE89: 5.25 | AF89: 5.24 | AG89: 5.22 | AH89: 5.22 | AI89: 5.21 | AJ89: 5.2 | AK89: 5.19 | AL89: 5.18 | AM89: 5.17 | AN89: 5.17 | AO89: 5.16 | AP89: 5.15 | AQ89: 5.14 | AR89: 5.13 | AS89: 5.12 | AT89: 5.12 | AU89: 5.11 | AV89: 5.1 | AW89: 5.09 | AX89: 5.09 | AY89: 5.08
A90: 39964 | B90: 4.25 | C90: 4.32 | D90: 4.42 | E90: 4.51 | F90: 4.6 | G90: 4.68 | H90: 4.76 | I90: 4.84 | J90: 4.91 | K90: 4.98 | L90: 5.04 | M90: 5.09 | N90: 5.14 | O90: 5.18 | P90: 5.21 | Q90: 5.23 | R90: 5.25 | S90: 5.27 | T90: 5.29 | U90: 5.3 | V90: 5.3 | W90: 5.3 | X90: 5.3 | Y90: 5.3 | Z90: 5.29 | AA90: 5.28 | AB90: 5.27 | AC90: 5.27 | AD90: 5.26 | AE90: 5.25 | AF90: 5.24 | AG90: 5.23 | AH90: 5.22 | AI90: 5.21 | AJ90: 5.2 | AK90: 5.19 | AL90: 5.18 | AM90: 5.17 | AN90: 5.17 | AO90: 5.16 | AP90: 5.15 | AQ90: 5.14 | AR90: 5.13 | AS90: 5.12 | AT90: 5.11 | AU90: 5.11 | AV90: 5.1 | AW90: 5.09 | AX90: 5.09 | AY90: 5.08
A91: 39994 | B91: 4.25 | C91: 4.32 | D91: 4.42 | E91: 4.52 | F91: 4.6 | G91: 4.69 | H91: 4.77 | I91: 4.85 | J91: 4.92 | K91: 4.98 | L91: 5.04 | M91: 5.1 | N91: 5.14 | O91: 5.18 | P91: 5.22 | Q91: 5.24 | R91: 5.26 | S91: 5.28 | T91: 5.3 | U91: 5.31 | V91: 5.31 | W91: 5.3 | X91: 5.3 | Y91: 5.3 | Z91: 5.3 | AA91: 5.29 | AB91: 5.28 | AC91: 5.27 | AD91: 5.26 | AE91: 5.25 | AF91: 5.24 | AG91: 5.23 | AH91: 5.22 | AI91: 5.21 | AJ91: 5.2 | AK91: 5.19 | AL91: 5.18 | AM91: 5.17 | AN91: 5.16 | AO91: 5.16 | AP91: 5.15 | AQ91: 5.14 | AR91: 5.13 | AS91: 5.12 | AT91: 5.11 | AU91: 5.1 | AV91: 5.09 | AW91: 5.09 | AX91: 5.08 | AY91: 5.07
A92: 40025 | B92: 4.25 | C92: 4.31 | D92: 4.42 | E92: 4.52 | F92: 4.6 | G92: 4.69 | H92: 4.77 | I92: 4.85 | J92: 4.92 | K92: 4.98 | L92: 5.05 | M92: 5.1 | N92: 5.14 | O92: 5.19 | P92: 5.22 | Q92: 5.24 | R92: 5.26 | S92: 5.28 | T92: 5.3 | U92: 5.31 | V92: 5.31 | W92: 5.3 | X92: 5.3 | Y92: 5.3 | Z92: 5.3 | AA92: 5.29 | AB92: 5.28 | AC92: 5.27 | AD92: 5.26 | AE92: 5.25 | AF92: 5.24 | AG92: 5.22 | AH92: 5.21 | AI92: 5.2 | AJ92: 5.19 | AK92: 5.18 | AL92: 5.17 | AM92: 5.16 | AN92: 5.15 | AO92: 5.15 | AP92: 5.14 | AQ92: 5.13 | AR92: 5.12 | AS92: 5.11 | AT92: 5.1 | AU92: 5.09 | AV92: 5.08 | AW92: 5.08 | AX92: 5.07 | AY92: 5.06
A93: 40056 | B93: 4.24 | C93: 4.31 | D93: 4.42 | E93: 4.52 | F93: 4.61 | G93: 4.69 | H93: 4.77 | I93: 4.85 | J93: 4.92 | K93: 4.99 | L93: 5.05 | M93: 5.1 | N93: 5.15 | O93: 5.19 | P93: 5.22 | Q93: 5.25 | R93: 5.26 | S93: 5.28 | T93: 5.3 | U93: 5.31 | V93: 5.31 | W93: 5.3 | X93: 5.3 | Y93: 5.3 | Z93: 5.29 | AA93: 5.28 | AB93: 5.27 | AC93: 5.26 | AD93: 5.25 | AE93: 5.24 | AF93: 5.23 | AG93: 5.22 | AH93: 5.21 | AI93: 5.19 | AJ93: 5.18 | AK93: 5.17 | AL93: 5.16 | AM93: 5.15 | AN93: 5.15 | AO93: 5.14 | AP93: 5.13 | AQ93: 5.12 | AR93: 5.11 | AS93: 5.1 | AT93: 5.09 | AU93: 5.08 | AV93: 5.07 | AW93: 5.06 | AX93: 5.06 | AY93: 5.05
A94: 40086 | B94: 4.23 | C94: 4.31 | D94: 4.42 | E94: 4.52 | F94: 4.61 | G94: 4.69 | H94: 4.77 | I94: 4.85 | J94: 4.92 | K94: 4.99 | L94: 5.05 | M94: 5.1 | N94: 5.15 | O94: 5.19 | P94: 5.22 | Q94: 5.25 | R94: 5.27 | S94: 5.28 | T94: 5.3 | U94: 5.31 | V94: 5.31 | W94: 5.3 | X94: 5.3 | Y94: 5.3 | Z94: 5.29 | AA94: 5.28 | AB94: 5.27 | AC94: 5.26 | AD94: 5.25 | AE94: 5.24 | AF94: 5.23 | AG94: 5.21 | AH94: 5.2 | AI94: 5.19 | AJ94: 5.18 | AK94: 5.17 | AL94: 5.16 | AM94: 5.15 | AN94: 5.14 | AO94: 5.13 | AP94: 5.12 | AQ94: 5.11 | AR94: 5.1 | AS94: 5.09 | AT94: 5.08 | AU94: 5.07 | AV94: 5.06 | AW94: 5.05 | AX94: 5.05 | AY94: 5.04
A95: 40117 | B95: 4.22 | C95: 4.3 | D95: 4.42 | E95: 4.52 | F95: 4.61 | G95: 4.69 | H95: 4.77 | I95: 4.85 | J95: 4.92 | K95: 4.99 | L95: 5.05 | M95: 5.1 | N95: 5.15 | O95: 5.19 | P95: 5.22 | Q95: 5.25 | R95: 5.27 | S95: 5.28 | T95: 5.3 | U95: 5.31 | V95: 5.31 | W95: 5.3 | X95: 5.3 | Y95: 5.29 | Z95: 5.29 | AA95: 5.28 | AB95: 5.26 | AC95: 5.25 | AD95: 5.24 | AE95: 5.23 | AF95: 5.22 | AG95: 5.2 | AH95: 5.19 | AI95: 5.18 | AJ95: 5.17 | AK95: 5.16 | AL95: 5.14 | AM95: 5.13 | AN95: 5.13 | AO95: 5.12 | AP95: 5.11 | AQ95: 5.09 | AR95: 5.09 | AS95: 5.08 | AT95: 5.07 | AU95: 5.06 | AV95: 5.05 | AW95: 5.04 | AX95: 5.03 | AY95: 5.03
A96: 40147 | B96: 4.22 | C96: 4.3 | D96: 4.42 | E96: 4.52 | F96: 4.61 | G96: 4.69 | H96: 4.77 | I96: 4.85 | J96: 4.92 | K96: 4.99 | L96: 5.05 | M96: 5.1 | N96: 5.15 | O96: 5.19 | P96: 5.23 | Q96: 5.25 | R96: 5.27 | S96: 5.28 | T96: 5.3 | U96: 5.31 | V96: 5.31 | W96: 5.3 | X96: 5.3 | Y96: 5.29 | Z96: 5.29 | AA96: 5.27 | AB96: 5.26 | AC96: 5.25 | AD96: 5.24 | AE96: 5.23 | AF96: 5.21 | AG96: 5.2 | AH96: 5.18 | AI96: 5.17 | AJ96: 5.16 | AK96: 5.15 | AL96: 5.14 | AM96: 5.12 | AN96: 5.11 | AO96: 5.11 | AP96: 5.09 | AQ96: 5.08 | AR96: 5.07 | AS96: 5.06 | AT96: 5.05 | AU96: 5.05 | AV96: 5.04 | AW96: 5.03 | AX96: 5.02 | AY96: 5.01
... A481: 51866 | B481: 2.99 | C481: 3 | D481: 3.05 | E481: 3.12 | F481: 3.19 | G481: 3.27 | H481: 3.34 | I481: 3.41 | J481: 3.48 | K481: 3.54 | L481: 3.6 | M481: 3.65 | N481: 3.7 | O481: 3.75 | P481: 3.78 | Q481: 3.81 | R481: 3.83 | S481: 3.85 | T481: 3.87 | U481: 3.89 | V481: 3.89 | W481: 3.89 | X481: 3.89 | Y481: 3.89 | Z481: 3.89 | AA481: 3.88 | AB481: 3.88 | AC481: 3.87 | AD481: 3.86 | AE481: 3.86 | AF481: 3.84 | AG481: 3.82 | AH481: 3.81 | AI481: 3.79 | AJ481: 3.78 | AK481: 3.77 | AL481: 3.76 | AM481: 3.75 | AN481: 3.74 | AO481: 3.73 | AP481: 3.7 | AQ481: 3.68 | AR481: 3.66 | AS481: 3.64 | AT481: 3.62 | AU481: 3.61 | AV481: 3.59 | AW481: 3.57 | AX481: 3.56 | AY481: 3.54

Sheet 6J-Zins
A1: Stichtag | B1: 1 Jahre | C1: 2 Jahre | D1: 3 Jahre | E1: 4 Jahre | F1: 5 Jahre | G1: 6 Jahre | H1: 7 Jahre | I1: 8 Jahre | J1: 9 Jahre | K1: 10 Jahre | L1: 11 Jahre | M1: 12 Jahre | N1: 13 Jahre | O1: 14 Jahre | P1: 15 Jahre | Q1: 16 Jahre | R1: 17 Jahre | S1: 18 Jahre | T1: 19 Jahre | U1: 20 Jahre | V1: 21 Jahre | W1: 22 Jahre | X1: 23 Jahre | Y1: 24 Jahre | Z1: 25 Jahre | AA1: 26 Jahre | AB1: 27 Jahre | AC1: 28 Jahre | AD1: 29 Jahre | AE1: 30 Jahre | AF1: 31 Jahre | AG1: 32 Jahre | AH1: 33 Jahre | AI1: 34 Jahre | AJ1: 35 Jahre | AK1: 36 Jahre | AL1: 37 Jahre | AM1: 38 Jahre | AN1: 39 Jahre | AO1: 40 Jahre | AP1: 41 Jahre | AQ1: 42 Jahre | AR1: 43 Jahre | AS1: 44 Jahre | AT1: 45 Jahre | AU1: 46 Jahre | AV1: 47 Jahre | AW1: 48 Jahre | AX1: 49 Jahre | AY1: 50 Jahre
A2: 37287
A3: 37315
A4: 37346
A5: 37376
A6: 37407
A7: 37437
A8: 37468
A9: 37499
A10: 37529
A11: 37560
A12: 37590
A13: 37621
... A84: 39782
A85: 39813 | B85: 3.93 | C85: 4.04 | D85: 4.18 | E85: 4.31 | F85: 4.43 | G85: 4.54 | H85: 4.64 | I85: 4.73 | J85: 4.81 | K85: 4.89 | L85: 4.96 | M85: 5.02 | N85: 5.07 | O85: 5.12 | P85: 5.16 | Q85: 5.19 | R85: 5.22 | S85: 5.25 | T85: 5.27 | U85: 5.29 | V85: 5.3 | W85: 5.31 | X85: 5.32 | Y85: 5.32 | Z85: 5.33 | AA85: 5.32 | AB85: 5.32 | AC85: 5.31 | AD85: 5.31 | AE85: 5.31 | AF85: 5.3 | AG85: 5.29 | AH85: 5.29 | AI85: 5.28 | AJ85: 5.27 | AK85: 5.27 | AL85: 5.26 | AM85: 5.26 | AN85: 5.25 | AO85: 5.25 | AP85: 5.24 | AQ85: 5.23 | AR85: 5.22 | AS85: 5.22 | AT85: 5.21 | AU85: 5.2 | AV85: 5.19 | AW85: 5.19 | AX85: 5.18 | AY85: 5.18
A86: 39844 | B86: 3.95 | C86: 4.06 | D86: 4.2 | E86: 4.33 | F86: 4.45 | G86: 4.56 | H86: 4.66 | I86: 4.75 | J86: 4.83 | K86: 4.91 | L86: 4.98 | M86: 5.04 | N86: 5.09 | O86: 5.14 | P86: 5.18 | Q86: 5.21 | R86: 5.24 | S86: 5.27 | T86: 5.29 | U86: 5.31 | V86: 5.32 | W86: 5.32 | X86: 5.33 | Y86: 5.33 | Z86: 5.34 | AA86: 5.33 | AB86: 5.33 | AC86: 5.33 | AD86: 5.32 | AE86: 5.32 | AF86: 5.31 | AG86: 5.3 | AH86: 5.3 | AI86: 5.29 | AJ86: 5.28 | AK86: 5.28 | AL86: 5.27 | AM86: 5.27 | AN86: 5.26 | AO86: 5.26 | AP86: 5.25 | AQ86: 5.24 | AR86: 5.23 | AS86: 5.22 | AT86: 5.22 | AU86: 5.21 | AV86: 5.2 | AW86: 5.19 | AX86: 5.19 | AY86: 5.18
A87: 39872 | B87: 3.97 | C87: 4.09 | D87: 4.23 | E87: 4.36 | F87: 4.47 | G87: 4.58 | H87: 4.68 | I87: 4.77 | J87: 4.85 | K87: 4.93 | L87: 5 | M87: 5.06 | N87: 5.11 | O87: 5.16 | P87: 5.2 | Q87: 5.23 | R87: 5.26 | S87: 5.28 | T87: 5.31 | U87: 5.33 | V87: 5.33 | W87: 5.34 | X87: 5.34 | Y87: 5.35 | Z87: 5.35 | AA87: 5.34 | AB87: 5.34 | AC87: 5.33 | AD87: 5.33 | AE87: 5.33 | AF87: 5.32 | AG87: 5.31 | AH87: 5.3 | AI87: 5.29 | AJ87: 5.29 | AK87: 5.28 | AL87: 5.28 | AM87: 5.27 | AN87: 5.26 | AO87: 5.26 | AP87: 5.25 | AQ87: 5.24 | AR87: 5.23 | AS87: 5.23 | AT87: 5.22 | AU87: 5.21 | AV87: 5.2 | AW87: 5.2 | AX87: 5.19 | AY87: 5.19
A88: 39903 | B88: 3.99 | C88: 4.11 | D88: 4.25 | E88: 4.38 | F88: 4.49 | G88: 4.6 | H88: 4.7 | I88: 4.79 | J88: 4.88 | K88: 4.95 | L88: 5.02 | M88: 5.08 | N88: 5.13 | O88: 5.18 | P88: 5.22 | Q88: 5.25 | R88: 5.28 | S88: 5.3 | T88: 5.33 | U88: 5.35 | V88: 5.35 | W88: 5.35 | X88: 5.36 | Y88: 5.36 | Z88: 5.37 | AA88: 5.36 | AB88: 5.35 | AC88: 5.35 | AD88: 5.34 | AE88: 5.34 | AF88: 5.33 | AG88: 5.32 | AH88: 5.31 | AI88: 5.31 | AJ88: 5.3 | AK88: 5.29 | AL88: 5.29 | AM88: 5.28 | AN88: 5.28 | AO88: 5.27 | AP88: 5.26 | AQ88: 5.25 | AR88: 5.24 | AS88: 5.24 | AT88: 5.23 | AU88: 5.22 | AV88: 5.22 | AW88: 5.21 | AX88: 5.2 | AY88: 5.2
A89: 39933 | B89: 4.01 | C89: 4.13 | D89: 4.27 | E89: 4.4 | F89: 4.51 | G89: 4.62 | H89: 4.72 | I89: 4.81 | J89: 4.89 | K89: 4.97 | L89: 5.03 | M89: 5.09 | N89: 5.15 | O89: 5.19 | P89: 5.23 | Q89: 5.27 | R89: 5.29 | S89: 5.32 | T89: 5.34 | U89: 5.36 | V89: 5.36 | W89: 5.37 | X89: 5.37 | Y89: 5.37 | Z89: 5.37 | AA89: 5.37 | AB89: 5.36 | AC89: 5.36 | AD89: 5.35 | AE89: 5.35 | AF89: 5.34 | AG89: 5.33 | AH89: 5.32 | AI89: 5.31 | AJ89: 5.31 | AK89: 5.3 | AL89: 5.29 | AM89: 5.29 | AN89: 5.28 | AO89: 5.28 | AP89: 5.27 | AQ89: 5.26 | AR89: 5.25 | AS89: 5.24 | AT89: 5.23 | AU89: 5.23 | AV89: 5.22 | AW89: 5.21 | AX89: 5.21 | AY89: 5.2
A90: 39964 | B90: 4.02 | C90: 4.14 | D90: 4.28 | E90: 4.41 | F90: 4.53 | G90: 4.64 | H90: 4.74 | I90: 4.83 | J90: 4.91 | K90: 4.98 | L90: 5.05 | M90: 5.11 | N90: 5.16 | O90: 5.21 | P90: 5.25 | Q90: 5.28 | R90: 5.31 | S90: 5.33 | T90: 5.35 | U90: 5.37 | V90: 5.37 | W90: 5.38 | X90: 5.38 | Y90: 5.38 | Z90: 5.38 | AA90: 5.38 | AB90: 5.37 | AC90: 5.36 | AD90: 5.36 | AE90: 5.35 | AF90: 5.34 | AG90: 5.33 | AH90: 5.32 | AI90: 5.32 | AJ90: 5.31 | AK90: 5.3 | AL90: 5.3 | AM90: 5.29 | AN90: 5.28 | AO90: 5.28 | AP90: 5.27 | AQ90: 5.26 | AR90: 5.25 | AS90: 5.24 | AT90: 5.24 | AU90: 5.23 | AV90: 5.22 | AW90: 5.21 | AX90: 5.21 | AY90: 5.2
A91: 39994 | B91: 4.02 | C91: 4.15 | D91: 4.29 | E91: 4.43 | F91: 4.54 | G91: 4.65 | H91: 4.75 | I91: 4.84 | J91: 4.92 | K91: 4.99 | L91: 5.06 | M91: 5.12 | N91: 5.17 | O91: 5.22 | P91: 5.26 | Q91: 5.29 | R91: 5.31 | S91: 5.34 | T91: 5.36 | U91: 5.38 | V91: 5.38 | W91: 5.38 | X91: 5.38 | Y91: 5.39 | Z91: 5.39 | AA91: 5.38 | AB91: 5.37 | AC91: 5.37 | AD91: 5.36 | AE91: 5.35 | AF91: 5.34 | AG91: 5.33 | AH91: 5.32 | AI91: 5.32 | AJ91: 5.31 | AK91: 5.3 | AL91: 5.29 | AM91: 5.29 | AN91: 5.28 | AO91: 5.27 | AP91: 5.26 | AQ91: 5.26 | AR91: 5.25 | AS91: 5.24 | AT91: 5.23 | AU91: 5.22 | AV91: 5.22 | AW91: 5.21 | AX91: 5.2 | AY91: 5.2
A92: 40025 | B92: 4.02 | C92: 4.14 | D92: 4.29 | E92: 4.42 | F92: 4.54 | G92: 4.65 | H92: 4.75 | I92: 4.84 | J92: 4.92 | K92: 4.99 | L92: 5.06 | M92: 5.12 | N92: 5.17 | O92: 5.22 | P92: 5.26 | Q92: 5.29 | R92: 5.31 | S92: 5.34 | T92: 5.36 | U92: 5.38 | V92: 5.38 | W92: 5.38 | X92: 5.38 | Y92: 5.38 | Z92: 5.38 | AA92: 5.37 | AB92: 5.37 | AC92: 5.36 | AD92: 5.35 | AE92: 5.35 | AF92: 5.33 | AG92: 5.32 | AH92: 5.31 | AI92: 5.31 | AJ92: 5.3 | AK92: 5.29 | AL92: 5.28 | AM92: 5.27 | AN92: 5.27 | AO92: 5.26 | AP92: 5.25 | AQ92: 5.24 | AR92: 5.23 | AS92: 5.22 | AT92: 5.22 | AU92: 5.21 | AV92: 5.2 | AW92: 5.2 | AX92: 5.19 | AY92: 5.18
A93: 40056 | B93: 4.01 | C93: 4.14 | D93: 4.29 | E93: 4.42 | F93: 4.54 | G93: 4.65 | H93: 4.74 | I93: 4.83 | J93: 4.92 | K93: 4.99 | L93: 5.06 | M93: 5.12 | N93: 5.17 | O93: 5.22 | P93: 5.26 | Q93: 5.29 | R93: 5.31 | S93: 5.33 | T93: 5.35 | U93: 5.37 | V93: 5.37 | W93: 5.37 | X93: 5.38 | Y93: 5.38 | Z93: 5.38 | AA93: 5.37 | AB93: 5.36 | AC93: 5.35 | AD93: 5.34 | AE93: 5.34 | AF93: 5.33 | AG93: 5.32 | AH93: 5.31 | AI93: 5.3 | AJ93: 5.29 | AK93: 5.28 | AL93: 5.27 | AM93: 5.26 | AN93: 5.26 | AO93: 5.25 | AP93: 5.24 | AQ93: 5.23 | AR93: 5.22 | AS93: 5.21 | AT93: 5.2 | AU93: 5.2 | AV93: 5.19 | AW93: 5.18 | AX93: 5.18 | AY93: 5.17
A94: 40086 | B94: 4.01 | C94: 4.14 | D94: 4.29 | E94: 4.42 | F94: 4.54 | G94: 4.64 | H94: 4.74 | I94: 4.83 | J94: 4.92 | K94: 4.99 | L94: 5.06 | M94: 5.12 | N94: 5.17 | O94: 5.22 | P94: 5.26 | Q94: 5.28 | R94: 5.31 | S94: 5.33 | T94: 5.35 | U94: 5.37 | V94: 5.37 | W94: 5.37 | X94: 5.37 | Y94: 5.37 | Z94: 5.37 | AA94: 5.36 | AB94: 5.35 | AC94: 5.34 | AD94: 5.34 | AE94: 5.33 | AF94: 5.32 | AG94: 5.31 | AH94: 5.3 | AI94: 5.29 | AJ94: 5.28 | AK94: 5.27 | AL94: 5.26 | AM94: 5.25 | AN94: 5.24 | AO94: 5.24 | AP94: 5.23 | AQ94: 5.22 | AR94: 5.21 | AS94: 5.2 | AT94: 5.19 | AU94: 5.18 | AV94: 5.18 | AW94: 5.17 | AX94: 5.16 | AY94: 5.16
A95: 40117 | B95: 4 | C95: 4.13 | D95: 4.28 | E95: 4.42 | F95: 4.53 | G95: 4.64 | H95: 4.74 | I95: 4.83 | J95: 4.91 | K95: 4.98 | L95: 5.05 | M95: 5.11 | N95: 5.16 | O95: 5.21 | P95: 5.25 | Q95: 5.28 | R95: 5.3 | S95: 5.33 | T95: 5.35 | U95: 5.36 | V95: 5.36 | W95: 5.36 | X95: 5.36 | Y95: 5.36 | Z95: 5.36 | AA95: 5.35 | AB95: 5.34 | AC95: 5.33 | AD95: 5.33 | AE95: 5.32 | AF95: 5.31 | AG95: 5.29 | AH95: 5.28 | AI95: 5.27 | AJ95: 5.26 | AK95: 5.25 | AL95: 5.25 | AM95: 5.24 | AN95: 5.23 | AO95: 5.22 | AP95: 5.21 | AQ95: 5.2 | AR95: 5.19 | AS95: 5.19 | AT95: 5.18 | AU95: 5.17 | AV95: 5.16 | AW95: 5.15 | AX95: 5.15 | AY95: 5.14
A96: 40147 | B96: 3.99 | C96: 4.12 | D96: 4.27 | E96: 4.41 | F96: 4.52 | G96: 4.63 | H96: 4.73 | I96: 4.82 | J96: 4.9 | K96: 4.98 | L96: 5.05 | M96: 5.1 | N96: 5.16 | O96: 5.2 | P96: 5.24 | Q96: 5.27 | R96: 5.3 | S96: 5.32 | T96: 5.34 | U96: 5.36 | V96: 5.35 | W96: 5.35 | X96: 5.35 | Y96: 5.35 | Z96: 5.35 | AA96: 5.34 | AB96: 5.33 | AC96: 5.32 | AD96: 5.31 | AE96: 5.31 | AF96: 5.29 | AG96: 5.28 | AH96: 5.27 | AI96: 5.26 | AJ96: 5.25 | AK96: 5.24 | AL96: 5.23 | AM96: 5.22 | AN96: 5.21 | AO96: 5.2 | AP96: 5.19 | AQ96: 5.19 | AR96: 5.18 | AS96: 5.17 | AT96: 5.16 | AU96: 5.15 | AV96: 5.14 | AW96: 5.14 | AX96: 5.13 | AY96: 5.12
... A481: 51866 | B481: 2.99 | C481: 3 | D481: 3.05 | E481: 3.12 | F481: 3.19 | G481: 3.27 | H481: 3.34 | I481: 3.41 | J481: 3.48 | K481: 3.54 | L481: 3.6 | M481: 3.65 | N481: 3.7 | O481: 3.75 | P481: 3.78 | Q481: 3.81 | R481: 3.83 | S481: 3.85 | T481: 3.87 | U481: 3.89 | V481: 3.89 | W481: 3.89 | X481: 3.89 | Y481: 3.89 | Z481: 3.89 | AA481: 3.88 | AB481: 3.88 | AC481: 3.87 | AD481: 3.86 | AE481: 3.86 | AF481: 3.84 | AG481: 3.82 | AH481: 3.81 | AI481: 3.79 | AJ481: 3.78 | AK481: 3.77 | AL481: 3.76 | AM481: 3.75 | AN481: 3.74 | AO481: 3.73 | AP481: 3.7 | AQ481: 3.68 | AR481: 3.66 | AS481: 3.64 | AT481: 3.62 | AU481: 3.61 | AV481: 3.59 | AW481: 3.57 | AX481: 3.56 | AY481: 3.54

Sheet 7J-Zins
A1: Stichtag | B1: 1 Jahre | C1: 2 Jahre | D1: 3 Jahre | E1: 4 Jahre | F1: 5 Jahre | G1: 6 Jahre | H1: 7 Jahre | I1: 8 Jahre | J1: 9 Jahre | K1: 10 Jahre | L1: 11 Jahre | M1: 12 Jahre | N1: 13 Jahre | O1: 14 Jahre | P1: 15 Jahre | Q1: 16 Jahre | R1: 17 Jahre | S1: 18 Jahre | T1: 19 Jahre | U1: 20 Jahre | V1: 21 Jahre | W1: 22 Jahre | X1: 23 Jahre | Y1: 24 Jahre | Z1: 25 Jahre | AA1: 26 Jahre | AB1: 27 Jahre | AC1: 28 Jahre | AD1: 29 Jahre | AE1: 30 Jahre | AF1: 31 Jahre | AG1: 32 Jahre | AH1: 33 Jahre | AI1: 34 Jahre | AJ1: 35 Jahre | AK1: 36 Jahre | AL1: 37 Jahre | AM1: 38 Jahre | AN1: 39 Jahre | AO1: 40 Jahre | AP1: 41 Jahre | AQ1: 42 Jahre | AR1: 43 Jahre | AS1: 44 Jahre | AT1: 45 Jahre | AU1: 46 Jahre | AV1: 47 Jahre | AW1: 48 Jahre | AX1: 49 Jahre | AY1: 50 Jahre
A2: 37287
A3: 37315
A4: 37346
A5: 37376
A6: 37407
A7: 37437
A8: 37468
A9: 37499
A10: 37529
A11: 37560
A12: 37590
A13: 37621
... A84: 39782
A85: 39813 | B85: 3.93 | C85: 4.07 | D85: 4.23 | E85: 4.38 | F85: 4.5 | G85: 4.62 | H85: 4.72 | I85: 4.82 | J85: 4.91 | K85: 4.98 | L85: 5.05 | M85: 5.11 | N85: 5.16 | O85: 5.21 | P85: 5.25 | Q85: 5.28 | R85: 5.31 | S85: 5.34 | T85: 5.36 | U85: 5.38 | V85: 5.39 | W85: 5.39 | X85: 5.4 | Y85: 5.4 | Z85: 5.41 | AA85: 5.4 | AB85: 5.4 | AC85: 5.39 | AD85: 5.39 | AE85: 5.38 | AF85: 5.37 | AG85: 5.37 | AH85: 5.36 | AI85: 5.35 | AJ85: 5.34 | AK85: 5.33 | AL85: 5.33 | AM85: 5.32 | AN85: 5.32 | AO85: 5.31 | AP85: 5.3 | AQ85: 5.29 | AR85: 5.28 | AS85: 5.27 | AT85: 5.26 | AU85: 5.26 | AV85: 5.25 | AW85: 5.24 | AX85: 5.23 | AY85: 5.23
A86: 39844 | B86: 3.94 | C86: 4.08 | D86: 4.24 | E86: 4.4 | F86: 4.51 | G86: 4.62 | H86: 4.73 | I86: 4.83 | J86: 4.91 | K86: 4.99 | L86: 5.06 | M86: 5.12 | N86: 5.17 | O86: 5.22 | P86: 5.26 | Q86: 5.29 | R86: 5.32 | S86: 5.35 | T86: 5.37 | U86: 5.39 | V86: 5.4 | W86: 5.4 | X86: 5.41 | Y86: 5.41 | Z86: 5.42 | AA86: 5.41 | AB86: 5.4 | AC86: 5.4 | AD86: 5.39 | AE86: 5.39 | AF86: 5.38 | AG86: 5.37 | AH86: 5.36 | AI86: 5.35 | AJ86: 5.35 | AK86: 5.34 | AL86: 5.33 | AM86: 5.32 | AN86: 5.32 | AO86: 5.31 | AP86: 5.3 | AQ86: 5.29 | AR86: 5.28 | AS86: 5.27 | AT86: 5.27 | AU86: 5.26 | AV86: 5.25 | AW86: 5.24 | AX86: 5.24 | AY86: 5.23
A87: 39872 | B87: 3.94 | C87: 4.08 | D87: 4.24 | E87: 4.41 | F87: 4.51 | G87: 4.63 | H87: 4.74 | I87: 4.83 | J87: 4.92 | K87: 5 | L87: 5.07 | M87: 5.13 | N87: 5.18 | O87: 5.23 | P87: 5.27 | Q87: 5.3 | R87: 5.33 | S87: 5.36 | T87: 5.38 | U87: 5.4 | V87: 5.4 | W87: 5.41 | X87: 5.41 | Y87: 5.42 | Z87: 5.42 | AA87: 5.42 | AB87: 5.41 | AC87: 5.4 | AD87: 5.4 | AE87: 5.39 | AF87: 5.38 | AG87: 5.37 | AH87: 5.36 | AI87: 5.35 | AJ87: 5.35 | AK87: 5.34 | AL87: 5.33 | AM87: 5.32 | AN87: 5.32 | AO87: 5.31 | AP87: 5.3 | AQ87: 5.29 | AR87: 5.28 | AS87: 5.27 | AT87: 5.26 | AU87: 5.26 | AV87: 5.25 | AW87: 5.24 | AX87: 5.23 | AY87: 5.23
A88: 39903 | B88: 3.95 | C88: 4.08 | D88: 4.24 | E88: 4.41 | F88: 4.51 | G88: 4.63 | H88: 4.74 | I88: 4.84 | J88: 4.93 | K88: 5.01 | L88: 5.08 | M88: 5.13 | N88: 5.19 | O88: 5.24 | P88: 5.28 | Q88: 5.31 | R88: 5.34 | S88: 5.37 | T88: 5.39 | U88: 5.41 | V88: 5.41 | W88: 5.42 | X88: 5.42 | Y88: 5.43 | Z88: 5.43 | AA88: 5.42 | AB88: 5.42 | AC88: 5.41 | AD88: 5.4 | AE88: 5.4 | AF88: 5.39 | AG88: 5.38 | AH88: 5.37 | AI88: 5.36 | AJ88: 5.35 | AK88: 5.34 | AL88: 5.34 | AM88: 5.33 | AN88: 5.32 | AO88: 5.32 | AP88: 5.31 | AQ88: 5.3 | AR88: 5.29 | AS88: 5.28 | AT88: 5.27 | AU88: 5.26 | AV88: 5.25 | AW88: 5.25 | AX88: 5.24 | AY88: 5.23
A89: 39933 | B89: 3.95 | C89: 4.08 | D89: 4.24 | E89: 4.41 | F89: 4.51 | G89: 4.63 | H89: 4.74 | I89: 4.84 | J89: 4.93 | K89: 5.01 | L89: 5.08 | M89: 5.14 | N89: 5.2 | O89: 5.24 | P89: 5.29 | Q89: 5.32 | R89: 5.35 | S89: 5.37 | T89: 5.39 | U89: 5.41 | V89: 5.42 | W89: 5.42 | X89: 5.43 | Y89: 5.43 | Z89: 5.43 | AA89: 5.43 | AB89: 5.42 | AC89: 5.41 | AD89: 5.41 | AE89: 5.4 | AF89: 5.39 | AG89: 5.38 | AH89: 5.37 | AI89: 5.36 | AJ89: 5.35 | AK89: 5.35 | AL89: 5.34 | AM89: 5.33 | AN89: 5.32 | AO89: 5.32 | AP89: 5.31 | AQ89: 5.3 | AR89: 5.29 | AS89: 5.28 | AT89: 5.27 | AU89: 5.26 | AV89: 5.26 | AW89: 5.25 | AX89: 5.24 | AY89: 5.23
A90: 39964 | B90: 3.93 | C90: 4.07 | D90: 4.23 | E90: 4.4 | F90: 4.51 | G90: 4.63 | H90: 4.74 | I90: 4.84 | J90: 4.93 | K90: 5.01 | L90: 5.08 | M90: 5.14 | N90: 5.2 | O90: 5.25 | P90: 5.29 | Q90: 5.32 | R90: 5.35 | S90: 5.37 | T90: 5.4 | U90: 5.42 | V90: 5.42 | W90: 5.42 | X90: 5.43 | Y90: 5.43 | Z90: 5.43 | AA90: 5.43 | AB90: 5.42 | AC90: 5.41 | AD90: 5.41 | AE90: 5.4 | AF90: 5.39 | AG90: 5.38 | AH90: 5.37 | AI90: 5.36 | AJ90: 5.35 | AK90: 5.34 | AL90: 5.34 | AM90: 5.33 | AN90: 5.32 | AO90: 5.31 | AP90: 5.3 | AQ90: 5.29 | AR90: 5.29 | AS90: 5.28 | AT90: 5.27 | AU90: 5.26 | AV90: 5.25 | AW90: 5.24 | AX90: 5.24 | AY90: 5.23
A91: 39994 | B91: 3.92 | C91: 4.05 | D91: 4.22 | E91: 4.39 | F91: 4.5 | G91: 4.62 | H91: 4.73 | I91: 4.83 | J91: 4.92 | K91: 5 | L91: 5.08 | M91: 5.14 | N91: 5.19 | O91: 5.24 | P91: 5.29 | Q91: 5.32 | R91: 5.35 | S91: 5.37 | T91: 5.4 | U91: 5.42 | V91: 5.42 | W91: 5.42 | X91: 5.43 | Y91: 5.43 | Z91: 5.43 | AA91: 5.43 | AB91: 5.42 | AC91: 5.41 | AD91: 5.4 | AE91: 5.4 | AF91: 5.39 | AG91: 5.38 | AH91: 5.37 | AI91: 5.36 | AJ91: 5.35 | AK91: 5.34 | AL91: 5.33 | AM91: 5.33 | AN91: 5.32 | AO91: 5.31 | AP91: 5.3 | AQ91: 5.29 | AR91: 5.28 | AS91: 5.27 | AT91: 5.27 | AU91: 5.26 | AV91: 5.25 | AW91: 5.24 | AX91: 5.23 | AY91: 5.23
A92: 40025 | B92: 3.9 | C92: 4.04 | D92: 4.2 | E92: 4.38 | F92: 4.49 | G92: 4.61 | H92: 4.72 | I92: 4.82 | J92: 4.91 | K92: 4.99 | L92: 5.07 | M92: 5.13 | N92: 5.19 | O92: 5.24 | P92: 5.28 | Q92: 5.31 | R92: 5.34 | S92: 5.37 | T92: 5.39 | U92: 5.41 | V92: 5.41 | W92: 5.42 | X92: 5.42 | Y92: 5.42 | Z92: 5.43 | AA92: 5.42 | AB92: 5.41 | AC92: 5.4 | AD92: 5.4 | AE92: 5.39 | AF92: 5.38 | AG92: 5.37 | AH92: 5.36 | AI92: 5.35 | AJ92: 5.34 | AK92: 5.33 | AL92: 5.32 | AM92: 5.32 | AN92: 5.31 | AO92: 5.3 | AP92: 5.29 | AQ92: 5.28 | AR92: 5.27 | AS92: 5.26 | AT92: 5.26 | AU92: 5.25 | AV92: 5.24 | AW92: 5.23 | AX92: 5.22 | AY92: 5.22
A93: 40056 | B93: 3.88 | C93: 4.02 | D93: 4.19 | E93: 4.35 | F93: 4.48 | G93: 4.6 | H93: 4.72 | I93: 4.82 | J93: 4.91 | K93: 4.99 | L93: 5.06 | M93: 5.12 | N93: 5.18 | O93: 5.23 | P93: 5.28 | Q93: 5.31 | R93: 5.34 | S93: 5.36 | T93: 5.39 | U93: 5.41 | V93: 5.41 | W93: 5.41 | X93: 5.42 | Y93: 5.42 | Z93: 5.42 | AA93: 5.41 | AB93: 5.41 | AC93: 5.4 | AD93: 5.39 | AE93: 5.39 | AF93: 5.38 | AG93: 5.36 | AH93: 5.35 | AI93: 5.34 | AJ93: 5.34 | AK93: 5.33 | AL93: 5.32 | AM93: 5.31 | AN93: 5.3 | AO93: 5.3 | AP93: 5.29 | AQ93: 5.28 | AR93: 5.27 | AS93: 5.26 | AT93: 5.25 | AU93: 5.24 | AV93: 5.23 | AW93: 5.23 | AX93: 5.22 | AY93: 5.21
A94: 40086 | B94: 3.87 | C94: 4.01 | D94: 4.18 | E94: 4.34 | F94: 4.47 | G94: 4.6 | H94: 4.71 | I94: 4.81 | J94: 4.9 | K94: 4.98 | L94: 5.06 | M94: 5.12 | N94: 5.18 | O94: 5.23 | P94: 5.27 | Q94: 5.3 | R94: 5.33 | S94: 5.36 | T94: 5.38 | U94: 5.4 | V94: 5.41 | W94: 5.41 | X94: 5.41 | Y94: 5.41 | Z94: 5.42 | AA94: 5.41 | AB94: 5.4 | AC94: 5.39 | AD94: 5.39 | AE94: 5.38 | AF94: 5.37 | AG94: 5.36 | AH94: 5.35 | AI94: 5.34 | AJ94: 5.33 | AK94: 5.32 | AL94: 5.31 | AM94: 5.3 | AN94: 5.3 | AO94: 5.29 | AP94: 5.28 | AQ94: 5.27 | AR94: 5.26 | AS94: 5.25 | AT94: 5.24 | AU94: 5.23 | AV94: 5.23 | AW94: 5.22 | AX94: 5.21 | AY94: 5.2
