Workbook

Sheet Zinsbandbreite
A1: Eingabe | D1: Ergebnis aus Sicht 28.02.2026
A2: Stichtag | B2: Duration | C2: Zinsdelta | D2: IAS 19 Zins | E2: Stichtags- zins UGB | F2: 5-Jahres- durchschnitts- zins | G2: 6-Jahres- durchschnitts- zins | H2: 7-Jahres- durchschnitts- zins | I2: 8-Jahres- durchschnitts- zins | J2: 9-Jahres- durchschnitts- zins | K2: 10-Jahres- durchschnitts- zins
A3: 46081 | B3: 15 | C3: 0 | D3: =ROUND(VLOOKUP(A3,'iBoxx Data'!A:DO,ROUND(B3,0)+69,0)/100,4) -> 0.0399 | E3: =ROUND(VLOOKUP(A3,'Stichtag-UGB'!A:AY,ROUND(B3,0)+1,0)/100,4) -> 0.0378 | F3: =ROUND(VLOOKUP(A3,'5J-Daten'!A:AY,ROUND(B3,0)+1,0)/100,4) -> 0.0288 | G3: =ROUND(VLOOKUP(A3,'6J-Daten'!A:AY,ROUND(B3,0)+1,0)/100,4) -> 0.0251 | H3: =ROUND(VLOOKUP(A3,'7J-Daten'!A:AY,ROUND(B3,0)+1,0)/100,4) -> 0.0227 | I3: =ROUND(VLOOKUP(A3,'8J-Daten'!A:AY,ROUND(B3,0)+1,0)/100,4) -> 0.0221 | J3: =ROUND(VLOOKUP(A3,'9J-Daten'!A:AY,ROUND(B3,0)+1,0)/100,4) -> 0.0216 | K3: =ROUND(VLOOKUP(A3,'10J-Daten'!A:AY,ROUND(B3,0)+1,0)/100,4) -> 0.0209
A4: =DATE(YEAR(A3+1)+1,MONTH(A3+1),DAY(A3+1))-1 -> 46446 | B4: =B3 -> 15 | C4: 0 | D4: =ROUND(VLOOKUP(A4,'iBoxx Data'!A:DO,ROUND(B4,0)+69,0)/100,4) -> 0.0399 | E4: =ROUND(VLOOKUP(A4,'Stichtag-UGB'!A:AY,ROUND(B4,0)+1,0)/100,4) -> 0.0378 | F4: =ROUND(VLOOKUP(A4,'5J-Daten'!A:AY,ROUND(B4,0)+1,0)/100,4) -> 0.0345 | G4: =ROUND(VLOOKUP(A4,'6J-Daten'!A:AY,ROUND(B4,0)+1,0)/100,4) -> 0.0303 | H4: =ROUND(VLOOKUP(A4,'7J-Daten'!A:AY,ROUND(B4,0)+1,0)/100,4) -> 0.0269 | I4: =ROUND(VLOOKUP(A4,'8J-Daten'!A:AY,ROUND(B4,0)+1,0)/100,4) -> 0.0246 | J4: =ROUND(VLOOKUP(A4,'9J-Daten'!A:AY,ROUND(B4,0)+1,0)/100,4) -> 0.0239 | K4: =ROUND(VLOOKUP(A4,'10J-Daten'!A:AY,ROUND(B4,0)+1,0)/100,4) -> 0.0232
A5: =DATE(YEAR(A4+1)+1,MONTH(A4+1),DAY(A4+1))-1 -> 46812 | B5: =B4 -> 15 | C5: 0 | D5: =ROUND(VLOOKUP(A5,'iBoxx Data'!A:DO,ROUND(B5,0)+69,0)/100,4) -> 0.0399 | E5: =ROUND(VLOOKUP(A5,'Stichtag-UGB'!A:AY,ROUND(B5,0)+1,0)/100,4) -> 0.0378 | F5: =ROUND(VLOOKUP(A5,'5J-Daten'!A:AY,ROUND(B5,0)+1,0)/100,4) -> 0.0362 | G5: =ROUND(VLOOKUP(A5,'6J-Daten'!A:AY,ROUND(B5,0)+1,0)/100,4) -> 0.0351 | H5: =ROUND(VLOOKUP(A5,'7J-Daten'!A:AY,ROUND(B5,0)+1,0)/100,4) -> 0.0314 | I5: =ROUND(VLOOKUP(A5,'8J-Daten'!A:AY,ROUND(B5,0)+1,0)/100,4) -> 0.0283 | J5: =ROUND(VLOOKUP(A5,'9J-Daten'!A:AY,ROUND(B5,0)+1,0)/100,4) -> 0.0261 | K5: =ROUND(VLOOKUP(A5,'10J-Daten'!A:AY,ROUND(B5,0)+1,0)/100,4) -> 0.0253
A6: =DATE(YEAR(A5+1)+1,MONTH(A5+1),DAY(A5+1))-1 -> 47177 | B6: =B5 -> 15 | C6: 0 | D6: =ROUND(VLOOKUP(A6,'iBoxx Data'!A:DO,ROUND(B6,0)+69,0)/100,4) -> 0.0399 | E6: =ROUND(VLOOKUP(A6,'Stichtag-UGB'!A:AY,ROUND(B6,0)+1,0)/100,4) -> 0.0378 | F6: =ROUND(VLOOKUP(A6,'5J-Daten'!A:AY,ROUND(B6,0)+1,0)/100,4) -> 0.0366 | G6: =ROUND(VLOOKUP(A6,'6J-Daten'!A:AY,ROUND(B6,0)+1,0)/100,4) -> 0.0365 | H6: =ROUND(VLOOKUP(A6,'7J-Daten'!A:AY,ROUND(B6,0)+1,0)/100,4) -> 0.0355 | I6: =ROUND(VLOOKUP(A6,'8J-Daten'!A:AY,ROUND(B6,0)+1,0)/100,4) -> 0.0322 | J6: =ROUND(VLOOKUP(A6,'9J-Daten'!A:AY,ROUND(B6,0)+1,0)/100,4) -> 0.0294 | K6: =ROUND(VLOOKUP(A6,'10J-Daten'!A:AY,ROUND(B6,0)+1,0)/100,4) -> 0.0273
A7: =DATE(YEAR(A6+1)+1,MONTH(A6+1),DAY(A6+1))-1 -> 47542 | B7: =B6 -> 15 | C7: 0 | D7: =ROUND(VLOOKUP(A7,'iBoxx Data'!A:DO,ROUND(B7,0)+69,0)/100,4) -> 0.0399 | E7: =ROUND(VLOOKUP(A7,'Stichtag-UGB'!A:AY,ROUND(B7,0)+1,0)/100,4) -> 0.0378 | F7: =ROUND(VLOOKUP(A7,'5J-Daten'!A:AY,ROUND(B7,0)+1,0)/100,4) -> 0.0376 | G7: =ROUND(VLOOKUP(A7,'6J-Daten'!A:AY,ROUND(B7,0)+1,0)/100,4) -> 0.0368 | H7: =ROUND(VLOOKUP(A7,'7J-Daten'!A:AY,ROUND(B7,0)+1,0)/100,4) -> 0.0367 | I7: =ROUND(VLOOKUP(A7,'8J-Daten'!A:AY,ROUND(B7,0)+1,0)/100,4) -> 0.0358 | J7: =ROUND(VLOOKUP(A7,'9J-Daten'!A:AY,ROUND(B7,0)+1,0)/100,4) -> 0.0328 | K7: =ROUND(VLOOKUP(A7,'10J-Daten'!A:AY,ROUND(B7,0)+1,0)/100,4) -> 0.0302
A8: =DATE(YEAR(A7+1)+1,MONTH(A7+1),DAY(A7+1))-1 -> 47907 | B8: =B7 -> 15 | C8: 0 | D8: =ROUND(VLOOKUP(A8,'iBoxx Data'!A:DO,ROUND(B8,0)+69,0)/100,4) -> 0.0399 | E8: =ROUND(VLOOKUP(A8,'Stichtag-UGB'!A:AY,ROUND(B8,0)+1,0)/100,4) -> 0.0378 | F8: =ROUND(VLOOKUP(A8,'5J-Daten'!A:AY,ROUND(B8,0)+1,0)/100,4) -> 0.0378 | G8: =ROUND(VLOOKUP(A8,'6J-Daten'!A:AY,ROUND(B8,0)+1,0)/100,4) -> 0.0377 | H8: =ROUND(VLOOKUP(A8,'7J-Daten'!A:AY,ROUND(B8,0)+1,0)/100,4) -> 0.037 | I8: =ROUND(VLOOKUP(A8,'8J-Daten'!A:AY,ROUND(B8,0)+1,0)/100,4) -> 0.0368 | J8: =ROUND(VLOOKUP(A8,'9J-Daten'!A:AY,ROUND(B8,0)+1,0)/100,4) -> 0.036 | K8: =ROUND(VLOOKUP(A8,'10J-Daten'!A:AY,ROUND(B8,0)+1,0)/100,4) -> 0.0333
A9: =DATE(YEAR(A8+1)+1,MONTH(A8+1),DAY(A8+1))-1 -> 48273 | B9: =B8 -> 15 | C9: 0 | D9: =ROUND(VLOOKUP(A9,'iBoxx Data'!A:DO,ROUND(B9,0)+69,0)/100,4) -> 0.0399 | E9: =ROUND(VLOOKUP(A9,'Stichtag-UGB'!A:AY,ROUND(B9,0)+1,0)/100,4) -> 0.0378 | F9: =ROUND(VLOOKUP(A9,'5J-Daten'!A:AY,ROUND(B9,0)+1,0)/100,4) -> 0.0378 | G9: =ROUND(VLOOKUP(A9,'6J-Daten'!A:AY,ROUND(B9,0)+1,0)/100,4) -> 0.0378 | H9: =ROUND(VLOOKUP(A9,'7J-Daten'!A:AY,ROUND(B9,0)+1,0)/100,4) -> 0.0377 | I9: =ROUND(VLOOKUP(A9,'8J-Daten'!A:AY,ROUND(B9,0)+1,0)/100,4) -> 0.0371 | J9: =ROUND(VLOOKUP(A9,'9J-Daten'!A:AY,ROUND(B9,0)+1,0)/100,4) -> 0.0369 | K9: =ROUND(VLOOKUP(A9,'10J-Daten'!A:AY,ROUND(B9,0)+1,0)/100,4) -> 0.0362
A10: =DATE(YEAR(A9+1)+1,MONTH(A9+1),DAY(A9+1))-1 -> 48638 | B10: =B9 -> 15 | C10: 0 | D10: =ROUND(VLOOKUP(A10,'iBoxx Data'!A:DO,ROUND(B10,0)+69,0)/100,4) -> 0.0399 | E10: =ROUND(VLOOKUP(A10,'Stichtag-UGB'!A:AY,ROUND(B10,0)+1,0)/100,4) -> 0.0378 | F10: =ROUND(VLOOKUP(A10,'5J-Daten'!A:AY,ROUND(B10,0)+1,0)/100,4) -> 0.0378 | G10: =ROUND(VLOOKUP(A10,'6J-Daten'!A:AY,ROUND(B10,0)+1,0)/100,4) -> 0.0378 | H10: =ROUND(VLOOKUP(A10,'7J-Daten'!A:AY,ROUND(B10,0)+1,0)/100,4) -> 0.0378 | I10: =ROUND(VLOOKUP(A10,'8J-Daten'!A:AY,ROUND(B10,0)+1,0)/100,4) -> 0.0377 | J10: =ROUND(VLOOKUP(A10,'9J-Daten'!A:AY,ROUND(B10,0)+1,0)/100,4) -> 0.0372 | K10: =ROUND(VLOOKUP(A10,'10J-Daten'!A:AY,ROUND(B10,0)+1,0)/100,4) -> 0.037
A11: =DATE(YEAR(A10+1)+1,MONTH(A10+1),DAY(A10+1))-1 -> 49003 | B11: =B10 -> 15 | C11: 0 | D11: =ROUND(VLOOKUP(A11,'iBoxx Data'!A:DO,ROUND(B11,0)+69,0)/100,4) -> 0.0399 | E11: =ROUND(VLOOKUP(A11,'Stichtag-UGB'!A:AY,ROUND(B11,0)+1,0)/100,4) -> 0.0378 | F11: =ROUND(VLOOKUP(A11,'5J-Daten'!A:AY,ROUND(B11,0)+1,0)/100,4) -> 0.0378 | G11: =ROUND(VLOOKUP(A11,'6J-Daten'!A:AY,ROUND(B11,0)+1,0)/100,4) -> 0.0378 | H11: =ROUND(VLOOKUP(A11,'7J-Daten'!A:AY,ROUND(B11,0)+1,0)/100,4) -> 0.0378 | I11: =ROUND(VLOOKUP(A11,'8J-Daten'!A:AY,ROUND(B11,0)+1,0)/100,4) -> 0.0378 | J11: =ROUND(VLOOKUP(A11,'9J-Daten'!A:AY,ROUND(B11,0)+1,0)/100,4) -> 0.0377 | K11: =ROUND(VLOOKUP(A11,'10J-Daten'!A:AY,ROUND(B11,0)+1,0)/100,4) -> 0.0372
A12: =DATE(YEAR(A11+1)+1,MONTH(A11+1),DAY(A11+1))-1 -> 49368 | B12: =B11 -> 15 | C12: 0 | D12: =ROUND(VLOOKUP(A12,'iBoxx Data'!A:DO,ROUND(B12,0)+69,0)/100,4) -> 0.0399 | E12: =ROUND(VLOOKUP(A12,'Stichtag-UGB'!A:AY,ROUND(B12,0)+1,0)/100,4) -> 0.0378 | F12: =ROUND(VLOOKUP(A12,'5J-Daten'!A:AY,ROUND(B12,0)+1,0)/100,4) -> 0.0378 | G12: =ROUND(VLOOKUP(A12,'6J-Daten'!A:AY,ROUND(B12,0)+1,0)/100,4) -> 0.0378 | H12: =ROUND(VLOOKUP(A12,'7J-Daten'!A:AY,ROUND(B12,0)+1,0)/100,4) -> 0.0378 | I12: =ROUND(VLOOKUP(A12,'8J-Daten'!A:AY,ROUND(B12,0)+1,0)/100,4) -> 0.0378 | J12: =ROUND(VLOOKUP(A12,'9J-Daten'!A:AY,ROUND(B12,0)+1,0)/100,4) -> 0.0378 | K12: =ROUND(VLOOKUP(A12,'10J-Daten'!A:AY,ROUND(B12,0)+1,0)/100,4) -> 0.0377
A13: =DATE(YEAR(A12+1)+1,MONTH(A12+1),DAY(A12+1))-1 -> 49734 | B13: =B12 -> 15 | C13: 0 | D13: =ROUND(VLOOKUP(A13,'iBoxx Data'!A:DO,ROUND(B13,0)+69,0)/100,4) -> 0.0399 | E13: =ROUND(VLOOKUP(A13,'Stichtag-UGB'!A:AY,ROUND(B13,0)+1,0)/100,4) -> 0.0378 | F13: =ROUND(VLOOKUP(A13,'5J-Daten'!A:AY,ROUND(B13,0)+1,0)/100,4) -> 0.0378 | G13: =ROUND(VLOOKUP(A13,'6J-Daten'!A:AY,ROUND(B13,0)+1,0)/100,4) -> 0.0378 | H13: =ROUND(VLOOKUP(A13,'7J-Daten'!A:AY,ROUND(B13,0)+1,0)/100,4) -> 0.0378 | I13: =ROUND(VLOOKUP(A13,'8J-Daten'!A:AY,ROUND(B13,0)+1,0)/100,4) -> 0.0378 | J13: =ROUND(VLOOKUP(A13,'9J-Daten'!A:AY,ROUND(B13,0)+1,0)/100,4) -> 0.0378 | K13: =ROUND(VLOOKUP(A13,'10J-Daten'!A:AY,ROUND(B13,0)+1,0)/100,4) -> 0.0378

Sheet iBoxx Data
A1: Stichtag | C1: iBoxx € Corporates AA | H1: Markit iBoxx € Sovereigns & Sub-Sovereigns AA | W1: iBoxx € Corporates AA | AB1: Markit iBoxx € Sovereigns & Sub-Sovereigns AA | AQ1: Staatsanleihen | BR1: IFRS-Zinssätze | CQ1: IFRS-Zinssätze-Extrapolation
C2: 1- | D2: 3-5 | E2: 5-7 | F2: 7-10 | G2: 10+ | H2: 1-3 Index | I2: 1-5 Index | J2: 1-10 Index | K2: 3-5 Index | L2: 5-7 Index | M2: 5-10 Index | N2: 5-15 Index | O2: 7-10 Index | P2: 10+ Index | Q2: 10-15 Index | R2: 15+ Index | S2: 25+ Index | T2: 30+ Index | W2: 1- | X2: 3-5 | Y2: 5-7 | Z2: 7-10 | AA2: 10+ | AB2: 1-3 Index | AC2: 1-5 Index | AD2: 1-10 Index | AE2: 3-5 Index | AF2: 5-7 Index | AG2: 5-10 Index | AH2: 5-15 Index | AI2: 7-10 Index | AJ2: 10+ Index | AK2: 10-15 Index | AL2: 15+ Index | AM2: 25+ Index | AN2: 30+ Index | AQ2: 1 | AR2: 2 | AS2: 3 | AT2: 4 | AU2: 5 | AV2: 6 | AW2: 7 | AX2: 8 | AY2: 9 | AZ2: 10 | BA2: 11 | BB2: 12 | BC2: 13 | BD2: 14 | BE2: 15 | BF2: 16 | BG2: 17 | BH2: 18 | BI2: 19 | BJ2: 20 | BK2: 21 | BL2: 22 | BM2: 23 | BN2: 24 | BO2: 25 | BR2: 1 | BS2: 2 | BT2: 3 | BU2: 4 | BV2: 5 | BW2: 6 | BX2: 7 | BY2: 8 | BZ2: 9 | CA2: 10 | CB2: 11 | CC2: 12 | CD2: 13 | CE2: 14 | CF2: 15 | CG2: 16 | CH2: 17 | CI2: 18 | CJ2: 19 | CK2: 20 | CL2: 21 | CM2: 22 | CN2: 23 | CO2: 24 | CP2: 25 | CQ2: 26 | CR2: 27 | CS2: 28 | CT2: 29 | CU2: 30 | CV2: 31 | CW2: 32 | CX2: 33 | CY2: 34 | CZ2: 35 | DA2: 36 | DB2: 37 | DC2: 38 | DD2: 39 | DE2: 40 | DF2: 41 | DG2: 42 | DH2: 43 | DI2: 44 | DJ2: 45 | DK2: 46 | DL2: 47 | DM2: 48 | DN2: 49 | DO2: 50
A3: 37315 | B3: Annual Yield to maturity | V3: Modified Duration to maturity | AP3: Staatsanleihen | BQ3: Unternehmensanleihen
A4: 37346 | B4: Annual Yield to maturity | V4: Modified Duration to maturity | AP4: Staatsanleihen | BQ4: Unternehmensanleihen
A5: 37376 | B5: Annual Yield to maturity | V5: Modified Duration to maturity | AP5: Staatsanleihen | BQ5: Unternehmensanleihen
A6: 37407 | B6: Annual Yield to maturity | V6: Modified Duration to maturity | AP6: Staatsanleihen | BQ6: Unternehmensanleihen
A7: 37437 | B7: Annual Yield to maturity | V7: Modified Duration to maturity | AP7: Staatsanleihen | BQ7: Unternehmensanleihen
A8: 37468 | B8: Annual Yield to maturity | V8: Modified Duration to maturity | AP8: Staatsanleihen | BQ8: Unternehmensanleihen
A9: 37499 | B9: Annual Yield to maturity | V9: Modified Duration to maturity | AP9: Staatsanleihen | BQ9: Unternehmensanleihen
A10: 37529 | B10: Annual Yield to maturity | V10: Modified Duration to maturity | AP10: Staatsanleihen | BQ10: Unternehmensanleihen
A11: 37560 | B11: Annual Yield to maturity | V11: Modified Duration to maturity | AP11: Staatsanleihen | BQ11: Unternehmensanleihen
A12: 37590 | B12: Annual Yield to maturity | V12: Modified Duration to maturity | AP12: Staatsanleihen | BQ12: Unternehmensanleihen
A13: 37621 | B13: Annual Yield to maturity | V13: Modified Duration to maturity | AP13: Staatsanleihen | BQ13: Unternehmensanleihen
A14: 37652 | B14: Annual Yield to maturity | V14: Modified Duration to maturity | AP14: Staatsanleihen | BQ14: Unternehmensanleihen
... A84: 39782 | B84: Annual Yield to maturity | V84: Modified Duration to maturity | AP84: Staatsanleihen | BQ84: Unternehmensanleihen
A85: 39813 | B85: Annual Yield to maturity | V85: Modified Duration to maturity | AP85: Staatsanleihen | BQ85: Unternehmensanleihen | BR85: 5.9246906 | BS85: 5.9575747 | BT85: 5.9904589 | BU85: 6.0233431 | BV85: 6.0562273 | BW85: 6.1219956 | BX85: 6.187764 | BY85: 6.2535323 | BZ85: 6.3193007 | CA85: 6.3850691 | CB85: 6.3622072 | CC85: 6.3393453 | CD85: 6.3164835 | CE85: 6.2936216 | CF85: 6.2707598 | CG85: 6.2867701 | CH85: 6.3027805 | CI85: 6.3187909 | CJ85: 6.3348013 | CK85: 6.3508117 | CL85: 6.3555882 | CM85: 6.3603646 | CN85: 6.3651411 | CO85: 6.3699176 | CP85: 6.3746941 | CQ85: 6.3746941 | CR85: 6.3746941 | CS85: 6.3746941 | CT85: 6.3746941 | CU85: 6.3746941 | CV85: 6.3746941 | CW85: 6.3746941 | CX85: 6.3746941 | CY85: 6.3746941 | CZ85: 6.3746941 | DA85: 6.3746941 | DB85: 6.3746941 | DC85: 6.3746941 | DD85: 6.3746941 | DE85: 6.3746941 | DF85: 6.3746941 | DG85: 6.3746941 | DH85: 6.3746941 | DI85: 6.3746941 | DJ85: 6.3746941 | DK85: 6.3746941 | DL85: 6.3746941 | DM85: 6.3746941 | DN85: 6.3746941 | DO85: 6.3746941
A86: 39844 | B86: Annual Yield to maturity | V86: Modified Duration to maturity | AP86: Staatsanleihen | BQ86: Unternehmensanleihen | BR86: 5.3924147 | BS86: 5.4609398 | BT86: 5.5294649 | BU86: 5.5979899 | BV86: 5.666515 | BW86: 5.8035651 | BX86: 5.9406152 | BY86: 6.0776654 | BZ86: 6.2147155 | CA86: 6.3517656 | CB86: 6.2824281 | CC86: 6.2130906 | CD86: 6.1437531 | CE86: 6.0744156 | CF86: 6.0050782 | CG86: 6.0135219 | CH86: 6.0219657 | CI86: 6.0304095 | CJ86: 6.0388532 | CK86: 6.047297 | CL86: 6.0485514 | CM86: 6.0498059 | CN86: 6.0510603 | CO86: 6.0523147 | CP86: 6.0535691 | CQ86: 6.0535691 | CR86: 6.0535691 | CS86: 6.0535691 | CT86: 6.0535691 | CU86: 6.0535691 | CV86: 6.0535691 | CW86: 6.0535691 | CX86: 6.0535691 | CY86: 6.0535691 | CZ86: 6.0535691 | DA86: 6.0535691 | DB86: 6.0535691 | DC86: 6.0535691 | DD86: 6.0535691 | DE86: 6.0535691 | DF86: 6.0535691 | DG86: 6.0535691 | DH86: 6.0535691 | DI86: 6.0535691 | DJ86: 6.0535691 | DK86: 6.0535691 | DL86: 6.0535691 | DM86: 6.0535691 | DN86: 6.0535691 | DO86: 6.0535691
A87: 39872 | B87: Annual Yield to maturity | V87: Modified Duration to maturity | AP87: Staatsanleihen | BQ87: Unternehmensanleihen | BR87: 5.3063921 | BS87: 5.377049 | BT87: 5.447706 | BU87: 5.5183629 | BV87: 5.5890198 | BW87: 5.7303336 | BX87: 5.8716474 | BY87: 6.0129612 | BZ87: 6.1542751 | CA87: 6.2955889 | CB87: 6.2343743 | CC87: 6.1731598 | CD87: 6.1119452 | CE87: 6.0507306 | CF87: 5.9895161 | CG87: 6.0036818 | CH87: 6.0178476 | CI87: 6.0320134 | CJ87: 6.0461791 | CK87: 6.0603449 | CL87: 6.0642974 | CM87: 6.06825 | CN87: 6.0722026 | CO87: 6.0761551 | CP87: 6.0801077 | CQ87: 6.0801077 | CR87: 6.0801077 | CS87: 6.0801077 | CT87: 6.0801077 | CU87: 6.0801077 | CV87: 6.0801077 | CW87: 6.0801077 | CX87: 6.0801077 | CY87: 6.0801077 | CZ87: 6.0801077 | DA87: 6.0801077 | DB87: 6.0801077 | DC87: 6.0801077 | DD87: 6.0801077 | DE87: 6.0801077 | DF87: 6.0801077 | DG87: 6.0801077 | DH87: 6.0801077 | DI87: 6.0801077 | DJ87: 6.0801077 | DK87: 6.0801077 | DL87: 6.0801077 | DM87: 6.0801077 | DN87: 6.0801077 | DO87: 6.0801077
A88: 39903 | B88: Annual Yield to maturity | V88: Modified Duration to maturity | AP88: Staatsanleihen | BQ88: Unternehmensanleihen | BR88: 5.4153458 | BS88: 5.4863767 | BT88: 5.5574076 | BU88: 5.6284386 | BV88: 5.6994695 | BW88: 5.8415314 | BX88: 5.9835932 | BY88: 6.1256551 | BZ88: 6.267717 | CA88: 6.4097788 | CB88: 6.3404826 | CC88: 6.2711863 | CD88: 6.20189 | CE88: 6.1325937 | CF88: 6.0632975 | CG88: 6.0897643 | CH88: 6.1162312 | CI88: 6.142698 | CJ88: 6.1691649 | CK88: 6.1956317 | CL88: 6.2079206 | CM88: 6.2202095 | CN88: 6.2324984 | CO88: 6.2447873 | CP88: 6.2570762 | CQ88: 6.2570762 | CR88: 6.2570762 | CS88: 6.2570762 | CT88: 6.2570762 | CU88: 6.2570762 | CV88: 6.2570762 | CW88: 6.2570762 | CX88: 6.2570762 | CY88: 6.2570762 | CZ88: 6.2570762 | DA88: 6.2570762 | DB88: 6.2570762 | DC88: 6.2570762 | DD88: 6.2570762 | DE88: 6.2570762 | DF88: 6.2570762 | DG88: 6.2570762 | DH88: 6.2570762 | DI88: 6.2570762 | DJ88: 6.2570762 | DK88: 6.2570762 | DL88: 6.2570762 | DM88: 6.2570762 | DN88: 6.2570762 | DO88: 6.2570762
A89: 39933 | B89: Annual Yield to maturity | V89: Modified Duration to maturity | AP89: Staatsanleihen | BQ89: Unternehmensanleihen | BR89: 4.9689296 | BS89: 5.0446226 | BT89: 5.1203156 | BU89: 5.1960085 | BV89: 5.2717015 | BW89: 5.4230875 | BX89: 5.5744734 | BY89: 5.7258594 | BZ89: 5.8772453 | CA89: 6.0286313 | CB89: 6.0467792 | CC89: 6.0649271 | CD89: 6.083075 | CE89: 6.101223 | CF89: 6.1193709 | CG89: 6.1381181 | CH89: 6.1568653 | CI89: 6.1756126 | CJ89: 6.1943598 | CK89: 6.213107 | CL89: 6.2222249 | CM89: 6.2313427 | CN89: 6.2404606 | CO89: 6.2495784 | CP89: 6.2586962 | CQ89: 6.2586962 | CR89: 6.2586962 | CS89: 6.2586962 | CT89: 6.2586962 | CU89: 6.2586962 | CV89: 6.2586962 | CW89: 6.2586962 | CX89: 6.2586962 | CY89: 6.2586962 | CZ89: 6.2586962 | DA89: 6.2586962 | DB89: 6.2586962 | DC89: 6.2586962 | DD89: 6.2586962 | DE89: 6.2586962 | DF89: 6.2586962 | DG89: 6.2586962 | DH89: 6.2586962 | DI89: 6.2586962 | DJ89: 6.2586962 | DK89: 6.2586962 | DL89: 6.2586962 | DM89: 6.2586962 | DN89: 6.2586962 | DO89: 6.2586962
A90: 39964 | B90: Annual Yield to maturity | V90: Modified Duration to maturity | AP90: Staatsanleihen | BQ90: Unternehmensanleihen | BR90: 4.4754701 | BS90: 4.5660183 | BT90: 4.6565666 | BU90: 4.7471149 | BV90: 4.8376632 | BW90: 5.0187598 | BX90: 5.1998564 | BY90: 5.380953 | BZ90: 5.5620496 | CA90: 5.7431462 | CB90: 5.816773 | CC90: 5.8903998 | CD90: 5.9640266 | CE90: 6.0376534 | CF90: 6.1112802 | CG90: 6.1293222 | CH90: 6.1473642 | CI90: 6.1654063 | CJ90: 6.1834483 | CK90: 6.2014904 | CL90: 6.2114298 | CM90: 6.2213692 | CN90: 6.2313086 | CO90: 6.241248 | CP90: 6.2511875 | CQ90: 6.2511875 | CR90: 6.2511875 | CS90: 6.2511875 | CT90: 6.2511875 | CU90: 6.2511875 | CV90: 6.2511875 | CW90: 6.2511875 | CX90: 6.2511875 | CY90: 6.2511875 | CZ90: 6.2511875 | DA90: 6.2511875 | DB90: 6.2511875 | DC90: 6.2511875 | DD90: 6.2511875 | DE90: 6.2511875 | DF90: 6.2511875 | DG90: 6.2511875 | DH90: 6.2511875 | DI90: 6.2511875 | DJ90: 6.2511875 | DK90: 6.2511875 | DL90: 6.2511875 | DM90: 6.2511875 | DN90: 6.2511875 | DO90: 6.2511875
A91: 39994 | B91: Annual Yield to maturity | V91: Modified Duration to maturity | AP91: Staatsanleihen | BQ91: Unternehmensanleihen | BR91: 3.8429679 | BS91: 3.9479825 | BT91: 4.0529971 | BU91: 4.1580117 | BV91: 4.2630264 | BW91: 4.4730556 | BX91: 4.6830849 | BY91: 4.8931141 | BZ91: 5.1031434 | CA91: 5.3131726 | CB91: 5.3705844 | CC91: 5.4279962 | CD91: 5.485408 | CE91: 5.5428198 | CF91: 5.6002317 | CG91: 5.6255572 | CH91: 5.6508827 | CI91: 5.6762082 | CJ91: 5.7015337 | CK91: 5.7268593 | CL91: 5.7400794 | CM91: 5.7532995 | CN91: 5.7665196 | CO91: 5.7797398 | CP91: 5.7929599 | CQ91: 5.7929599 | CR91: 5.7929599 | CS91: 5.7929599 | CT91: 5.7929599 | CU91: 5.7929599 | CV91: 5.7929599 | CW91: 5.7929599 | CX91: 5.7929599 | CY91: 5.7929599 | CZ91: 5.7929599 | DA91: 5.7929599 | DB91: 5.7929599 | DC91: 5.7929599 | DD91: 5.7929599 | DE91: 5.7929599 | DF91: 5.7929599 | DG91: 5.7929599 | DH91: 5.7929599 | DI91: 5.7929599 | DJ91: 5.7929599 | DK91: 5.7929599 | DL91: 5.7929599 | DM91: 5.7929599 | DN91: 5.7929599 | DO91: 5.7929599
A92: 40025 | B92: Annual Yield to maturity | V92: Modified Duration to maturity | AP92: Staatsanleihen | BQ92: Unternehmensanleihen | BR92: 3.4188186 | BS92: 3.5207363 | BT92: 3.6226539 | BU92: 3.7245715 | BV92: 3.8264892 | BW92: 4.0303245 | BX92: 4.2341598 | BY92: 4.437995 | BZ92: 4.6418303 | CA92: 4.8456656 | CB92: 4.9235569 | CC92: 5.0014481 | CD92: 5.0793393 | CE92: 5.1572306 | CF92: 5.2351218 | CG92: 5.2633681 | CH92: 5.2916143 | CI92: 5.3198606 | CJ92: 5.3481068 | CK92: 5.376353 | CL92: 5.3914643 | CM92: 5.4065756 | CN92: 5.4216868 | CO92: 5.4367981 | CP92: 5.4519094 | CQ92: 5.4519094 | CR92: 5.4519094 | CS92: 5.4519094 | CT92: 5.4519094 | CU92: 5.4519094 | CV92: 5.4519094 | CW92: 5.4519094 | CX92: 5.4519094 | CY92: 5.4519094 | CZ92: 5.4519094 | DA92: 5.4519094 | DB92: 5.4519094 | DC92: 5.4519094 | DD92: 5.4519094 | DE92: 5.4519094 | DF92: 5.4519094 | DG92: 5.4519094 | DH92: 5.4519094 | DI92: 5.4519094 | DJ92: 5.4519094 | DK92: 5.4519094 | DL92: 5.4519094 | DM92: 5.4519094 | DN92: 5.4519094 | DO92: 5.4519094
A93: 40056 | B93: Annual Yield to maturity | V93: Modified Duration to maturity | AP93: Staatsanleihen | BQ93: Unternehmensanleihen | BR93: 3.3494253 | BS93: 3.4404743 | BT93: 3.5315232 | BU93: 3.6225722 | BV93: 3.7136212 | BW93: 3.8957191 | BX93: 4.0778171 | BY93: 4.259915 | BZ93: 4.442013 | CA93: 4.6241109 | CB93: 4.7273103 | CC93: 4.8305096 | CD93: 4.933709 | CE93: 5.0369083 | CF93: 5.1401077 | CG93: 5.170128 | CH93: 5.2001484 | CI93: 5.2301688 | CJ93: 5.2601892 | CK93: 5.2902095 | CL93: 5.3065914 | CM93: 5.3229732 | CN93: 5.339355 | CO93: 5.3557369 | CP93: 5.3721187 | CQ93: 5.3721187 | CR93: 5.3721187 | CS93: 5.3721187 | CT93: 5.3721187 | CU93: 5.3721187 | CV93: 5.3721187 | CW93: 5.3721187 | CX93: 5.3721187 | CY93: 5.3721187 | CZ93: 5.3721187 | DA93: 5.3721187 | DB93: 5.3721187 | DC93: 5.3721187 | DD93: 5.3721187 | DE93: 5.3721187 | DF93: 5.3721187 | DG93: 5.3721187 | DH93: 5.3721187 | DI93: 5.3721187 | DJ93: 5.3721187 | DK93: 5.3721187 | DL93: 5.3721187 | DM93: 5.3721187 | DN93: 5.3721187 | DO93: 5.3721187
A94: 40086 | B94: Annual Yield to maturity | V94: Modified Duration to maturity | AP94: Staatsanleihen | BQ94: Unternehmensanleihen | BR94: 3.2448046 | BS94: 3.3390903 | BT94: 3.433376 | BU94: 3.5276617 | BV94: 3.6219474 | BW94: 3.8105188 | BX94: 3.9990901 | BY94: 4.1876615 | BZ94: 4.3762329 | CA94: 4.5648043 | CB94: 4.6758524 | CC94: 4.7869004 | CD94: 4.8979485 | CE94: 5.0089966 | CF94: 5.1200447 | CG94: 5.1451307 | CH94: 5.1702167 | CI94: 5.1953027 | CJ94: 5.2203887 | CK94: 5.2454748 | CL94: 5.2575939 | CM94: 5.269713 | CN94: 5.2818321 | CO94: 5.2939512 | CP94: 5.3060703 | CQ94: 5.3060703 | CR94: 5.3060703 | CS94: 5.3060703 | CT94: 5.3060703 | CU94: 5.3060703 | CV94: 5.3060703 | CW94: 5.3060703 | CX94: 5.3060703 | CY94: 5.3060703 | CZ94: 5.3060703 | DA94: 5.3060703 | DB94: 5.3060703 | DC94: 5.3060703 | DD94: 5.3060703 | DE94: 5.3060703 | DF94: 5.3060703 | DG94: 5.3060703 | DH94: 5.3060703 | DI94: 5.3060703 | DJ94: 5.3060703 | DK94: 5.3060703 | DL94: 5.3060703 | DM94: 5.3060703 | DN94: 5.3060703 | DO94: 5.3060703
A95: 40117 | B95: Annual Yield to maturity | V95: Modified Duration to maturity | AP95: Staatsanleihen | BQ95: Unternehmensanleihen | BR95: 3.1412977 | BS95: 3.2391319 | BT95: 3.3369661 | BU95: 3.4348003 | BV95: 3.5326345 | BW95: 3.7283028 | BX95: 3.9239712 | BY95: 4.1196396 | BZ95: 4.3153079 | CA95: 4.5109763 | CB95: 4.6234934 | CC95: 4.7360106 | CD95: 4.8485278 | CE95: 4.9610449 | CF95: 5.0735621 | CG95: 5.1046097 | CH95: 5.1356572 | CI95: 5.1667048 | CJ95: 5.1977524 | CK95: 5.2287999 | CL95: 5.2450385 | CM95: 5.261277 | CN95: 5.2775155 | CO95: 5.293754 | CP95: 5.3099926 | CQ95: 5.3099926 | CR95: 5.3099926 | CS95: 5.3099926 | CT95: 5.3099926 | CU95: 5.3099926 | CV95: 5.3099926 | CW95: 5.3099926 | CX95: 5.3099926 | CY95: 5.3099926 | CZ95: 5.3099926 | DA95: 5.3099926 | DB95: 5.3099926 | DC95: 5.3099926 | DD95: 5.3099926 | DE95: 5.3099926 | DF95: 5.3099926 | DG95: 5.3099926 | DH95: 5.3099926 | DI95: 5.3099926 | DJ95: 5.3099926 | DK95: 5.3099926 | DL95: 5.3099926 | DM95: 5.3099926 | DN95: 5.3099926 | DO95: 5.3099926
A96: 40147 | B96: Annual Yield to maturity | V96: Modified Duration to maturity | AP96: Staatsanleihen | BQ96: Unternehmensanleihen | BR96: 3.0263352 | BS96: 3.125373 | BT96: 3.2244109 | BU96: 3.3234488 | BV96: 3.4224867 | BW96: 3.6205624 | BX96: 3.8186382 | BY96: 4.0167139 | BZ96: 4.2147897 | CA96: 4.4128654 | CB96: 4.5062004 | CC96: 4.5995353 | CD96: 4.6928703 | CE96: 4.7862052 | CF96: 4.8795401 | CG96: 4.9075407 | CH96: 4.9355412 | CI96: 4.9635418 | CJ96: 4.9915424 | CK96: 5.0195429 | CL96: 5.0332565 | CM96: 5.0469701 | CN96: 5.0606838 | CO96: 5.0743974 | CP96: 5.088111 | CQ96: 5.088111 | CR96: 5.088111 | CS96: 5.088111 | CT96: 5.088111 | CU96: 5.088111 | CV96: 5.088111 | CW96: 5.088111 | CX96: 5.088111 | CY96: 5.088111 | CZ96: 5.088111 | DA96: 5.088111 | DB96: 5.088111 | DC96: 5.088111 | DD96: 5.088111 | DE96: 5.088111 | DF96: 5.088111 | DG96: 5.088111 | DH96: 5.088111 | DI96: 5.088111 | DJ96: 5.088111 | DK96: 5.088111 | DL96: 5.088111 | DM96: 5.088111 | DN96: 5.088111 | DO96: 5.088111
... A289: 46022 | B289: Annual Yield to maturity | V289: Modified Duration to maturity | AP289: Staatsanleihen | BQ289: Unternehmensanleihen | BR289: 2.4643294 | BS289: 2.5423294 | BT289: 2.6991253 | BU289: 2.8637192 | BV289: 3.0406184 | BW289: 3.1977136 | BX289: 3.3468567 | BY289: 3.4825113 | BZ289: 3.6158267 | CA289: 3.749142 | CB289: 3.8824573 | CC289: 3.9574577 | CD289: 4.0254747 | CE289: 4.0865085 | CF289: 4.1435459 | CG289: 4.1951003 | CH289: 4.2411717 | CI289: 4.2785569 | CJ289: 4.3068893 | CK289: 4.3316459 | CL289: 4.3528268 | CM289: 4.3626487 | CN289: 4.3636348 | CO289: 4.3596161 | CP289: 4.3495917 | CQ289: 4.3435917 | CR289: 4.3375917 | CS289: 4.3325917 | CT289: 4.3275917 | CU289: 4.3225917 | CV289: 4.3125917 | CW289: 4.3025917 | CX289: 4.2925917 | CY289: 4.2835917 | CZ289: 4.2755917 | DA289: 4.2675917 | DB289: 4.2595917 | DC289: 4.2525917 | DD289: 4.2465917 | DE289: 4.2395917 | DF289: 4.2215917 | DG289: 4.2035917 | DH289: 4.1865917 | DI289: 4.1695917 | DJ289: 4.1545917 | DK289: 4.1395917 | DL289: 4.1255917 | DM289: 4.1115917 | DN289: 4.0985917 | DO289: 4.0865917
A290: 46053 | B290: Annual Yield to maturity | C290: 2.4454 | D290: 2.6957 | E290: 2.9996 | F290: 3.295 | G290: 3.8969 | H290: 2.1832 | I290: 2.3769 | J290: 2.7717 | K290: 2.4725 | L290: 2.7345 | M290: 2.9432 | N290: 3.0872 | O290: 3.0432 | P290: 3.7716 | Q290: 3.4408 | R290: 3.8681 | S290: 3.9549 | T290: 3.9166 | V290: Modified Duration to maturity | W290: 1.8305 | X290: 3.5735 | Y290: 5.2758 | Z290: 7.0987 | AA290: 11.4651 | AB290: 1.8405 | AC290: 2.7792 | AD290: 4.6322 | AE290: 3.7174 | AF290: 5.4709 | AG290: 6.5368 | AH290: 7.3366 | AI290: 7.212 | AJ290: 15.0018 | AK290: 10.5077 | AL290: 17.1513 | AM290: 20.9249 | AN290: 24.357 | AP290: Staatsanleihen | AR290: =($H290*(2-$AC290)+$I290*($AB290-2))/($AB290-$AC290) -> 2.2161127 | AS290: =($I290*(3-$AE290)+$K290*($AC290-3))/($AC290-$AE290) -> 2.3993989 | AT290: =($K290*(4-$AD290)+$J290*($AE290-4))/($AE290-$AD290) -> 2.5649289 | AU290: =($J290*(5-$AF290)+$L290*($AD290-5))/($AD290-$AF290) -> 2.7553865 | AV290: =($L290*(6-$AG290)+$M290*($AF290-6))/($AF290-$AG290) -> 2.8380962 | AW290: =($N290*(7-$AG290)+$M290*($AH290-7))/($AH290-$AG290) -> 3.0265968 | AX290: =($Q290*(8-$AH290)+$N290*($AK290-8))/($AK290-$AH290) -> 3.1611738 | AY290: =($N290*(9-$AK290)+$Q290*($AH290-9))/($AH290-$AK290) -> 3.2726808 | AZ290: =($N290*(10-$AK290)+$Q290*($AH290-10))/($AH290-$AK290) -> 3.3841879 | BA290: =($Q290*(11-$AJ290)+$P290*($AK290-11))/($AK290-$AJ290) -> 3.477037 | BB290: =($Q290*(12-$AJ290)+$P290*($AK290-12))/($AK290-$AJ290) -> 3.5506446 | BC290: =($Q290*(13-$AJ290)+$P290*($AK290-13))/($AK290-$AJ290) -> 3.6242523 | BD290: =($Q290*(14-$AJ290)+$P290*($AK290-14))/($AK290-$AJ290) -> 3.6978599 | BE290: =($P290*(15-$AL290)+$R290*($AJ290-15))/($AJ290-$AL290) -> 3.7715192 | BF290: =($P290*(16-$AL290)+$R290*($AJ290-16))/($AJ290-$AL290) -> 3.8164134 | BG290: =($P290*(17-$AL290)+$R290*($AJ290-17))/($AJ290-$AL290) -> 3.8613075 | BH290: =($S290*(18-$AL290)+$R290*($AM290-18))/($AM290-$AL290) -> 3.8876217 | BI290: =($S290*(19-$AL290)+$R290*($AM290-19))/($AM290-$AL290) -> 3.9106236 | BJ290: =($S290*(20-$AL290)+$R290*($AM290-20))/($AM290-$AL290) -> 3.9336255 | BK290: =($S290*(21-$AL290)+$R290*($AM290-21))/($AM290-$AL290) -> 3.9566274 | BL290: =($S290*(22-$AN290)+$T290*($AM290-22))/($AM290-$AN290) -> 3.9429026 | BM290: =($S290*(23-$AN290)+$T290*($AM290-23))/($AM290-$AN290) -> 3.9317432 | BN290: =($S290*(24-$AN290)+$T290*($AM290-24))/($AM290-$AN290) -> 3.9205839 | BO290: =BN290+(BN290-BJ290)/5 -> 3.9179756 | BQ290: Unternehmensanleihen | BR290: =$BS290+'Stichtag-UGB'!B290-'Stichtag-UGB'!$C290 -> 2.3997407 | BS290: =($C290*(2-$X290)+$D290*($W290-2))/($W290-$X290) -> 2.4697407 | BT290: =($C290*(3-$X290)+$D290*($W290-3))/($W290-$X290) -> 2.6133437 | BU290: =($D290*(4-$Y290)+$E290*($X290-4))/($X290-$Y290) -> 2.7718401 | BV290: =($D290*(5-$Y290)+$E290*($X290-5))/($X290-$Y290) -> 2.9503633 | BW290: =($E290*(6-$Z290)+$F290*($Y290-6))/($Y290-$Z290) -> 3.1169562 | BX290: =($E290*(7-$Z290)+$F290*($Y290-7))/($Y290-$Z290) -> 3.2790057 | BY290: =($F290*(8-$AA290)+$G290*($Z290-8))/($Z290-$AA290) -> 3.4192425 | BZ290: =($F290*(9-$AA290)+$G290*($Z290-9))/($Z290-$AA290) -> 3.5570906 | CA290: =($F290*(10-$AA290)+$G290*($Z290-10))/($Z290-$AA290) -> 3.6949387 | CB290: =($F290*(11-$AA290)+$G290*($Z290-11))/($Z290-$AA290) -> 3.8327868 | CC290: =CB290+(BB290-AX290)/5 -> 3.910681 | CD290: =CC290+(BC290-AY290)/5 -> 3.9809953 | CE290: =CD290+(BD290-AZ290)/5 -> 4.0437297 | CF290: =CE290+(BE290-BA290)/5 -> 4.1026261 | CG290: =CF290+(BF290-BB290)/5 -> 4.1557799 | CH290: =CG290+(BG290-BC290)/5 -> 4.2031909 | CI290: =CH290+(BH290-BD290)/5 -> 4.2411433 | CJ290: =CI290+(BI290-BE290)/5 -> 4.2689642 | ... CP290: =CO290+(BO290-BK290)/5 -> 4.316412 | CQ290: =$CP290+'Stichtag-UGB'!AA290-'Stichtag-UGB'!$Z290 -> 4.316412 | CR290: =$CP290+'Stichtag-UGB'!AB290-'Stichtag-UGB'!$Z290 -> 4.306412 | CS290: =$CP290+'Stichtag-UGB'!AC290-'Stichtag-UGB'!$Z290 -> 4.296412 | CT290: =$CP290+'Stichtag-UGB'!AD290-'Stichtag-UGB'!$Z290 -> 4.286412 | CU290: =$CP290+'Stichtag-UGB'!AE290-'Stichtag-UGB'!$Z290 -> 4.286412 | CV290: =$CP290+'Stichtag-UGB'!AF290-'Stichtag-UGB'!$Z290 -> 4.266412 | CW290: =$CP290+'Stichtag-UGB'!AG290-'Stichtag-UGB'!$Z290 -> 4.256412 | CX290: =$CP290+'Stichtag-UGB'!AH290-'Stichtag-UGB'!$Z290 -> 4.236412 | ... DO290: =$CP290+'Stichtag-UGB'!AY290-'Stichtag-UGB'!$Z290 -> 3.996412
A291: 46081 | B291: Annual Yield to maturity | C291: 2.4373 | D291: 2.6583 | E291: 2.9231 | F291: 3.207 | G291: 3.7984 | H291: 2.1181 | I291: 2.2667 | J291: 2.6128 | K291: 2.3365 | L291: 2.5684 | M291: 2.7636 | N291: 2.911 | O291: 2.8563 | P291: 3.5652 | Q291: 3.2237 | R291: 3.674 | S291: 3.7596 | T291: 3.7213 | V291: Modified Duration to maturity | W291: 1.8431 | X291: 3.5959 | Y291: 5.2885 | Z291: 7.0863 | AA291: 11.5434 | AB291: 1.7777 | AC291: 2.7399 | AD291: 4.5984 | AE291: 3.6767 | AF291: 5.4546 | AG291: 6.5403 | AH291: 7.391 | AI291: 7.2258 | AJ291: 14.8108 | AK291: 10.2236 | AL291: 17.2933 | AM291: 21.2318 | AN291: 25.0314 | AP291: Staatsanleihen | AR291: =($H291*(2-$AC291)+$I291*($AB291-2))/($AB291-$AC291) -> 2.1524315 | AS291: =($I291*(3-$AE291)+$K291*($AC291-3))/($AC291-$AE291) -> 2.2860798 | AT291: =($K291*(4-$AD291)+$J291*($AE291-4))/($AE291-$AD291) -> 2.4334163 | AU291: =($J291*(5-$AF291)+$L291*($AD291-5))/($AD291-$AF291) -> 2.5919742 | AV291: =($L291*(6-$AG291)+$M291*($AF291-6))/($AF291-$AG291) -> 2.6664585 | AW291: =($N291*(7-$AG291)+$M291*($AH291-7))/($AH291-$AG291) -> 2.8432518 | AX291: =($Q291*(8-$AH291)+$N291*($AK291-8))/($AK291-$AH291) -> 2.9782295 | AY291: =($N291*(9-$AK291)+$Q291*($AH291-9))/($AH291-$AK291) -> 3.0886228 | AZ291: =($N291*(10-$AK291)+$Q291*($AH291-10))/($AH291-$AK291) -> 3.1990161 | BA291: =($Q291*(11-$AJ291)+$P291*($AK291-11))/($AK291-$AJ291) -> 3.2815001 | BB291: =($Q291*(12-$AJ291)+$P291*($AK291-12))/($AK291-$AJ291) -> 3.3559464 | BC291: =($Q291*(13-$AJ291)+$P291*($AK291-13))/($AK291-$AJ291) -> 3.4303927 | BD291: =($Q291*(14-$AJ291)+$P291*($AK291-14))/($AK291-$AJ291) -> 3.504839 | BE291: =($P291*(15-$AL291)+$R291*($AJ291-15))/($AJ291-$AL291) -> 3.573492 | BF291: =($P291*(16-$AL291)+$R291*($AJ291-16))/($AJ291-$AL291) -> 3.6173188 | BG291: =($P291*(17-$AL291)+$R291*($AJ291-17))/($AJ291-$AL291) -> 3.6611456 | BH291: =($S291*(18-$AL291)+$R291*($AM291-18))/($AM291-$AL291) -> 3.6893595 | BI291: =($S291*(19-$AL291)+$R291*($AM291-19))/($AM291-$AL291) -> 3.7110937 | BJ291: =($S291*(20-$AL291)+$R291*($AM291-20))/($AM291-$AL291) -> 3.7328279 | BK291: =($S291*(21-$AL291)+$R291*($AM291-21))/($AM291-$AL291) -> 3.754562 | BL291: =($S291*(22-$AN291)+$T291*($AM291-22))/($AM291-$AN291) -> 3.7518565 | BM291: =($S291*(23-$AN291)+$T291*($AM291-23))/($AM291-$AN291) -> 3.7417765 | BN291: =($S291*(24-$AN291)+$T291*($AM291-24))/($AM291-$AN291) -> 3.7316965 | BO291: =BN291+(BN291-BJ291)/5 -> 3.7314703 | BQ291: Unternehmensanleihen | BR291: =$BS291+'Stichtag-UGB'!B291-'Stichtag-UGB'!$C291 -> 2.4470826 | BS291: =($C291*(2-$X291)+$D291*($W291-2))/($W291-$X291) -> 2.4570826 | BT291: =($C291*(3-$X291)+$D291*($W291-3))/($W291-$X291) -> 2.5831666 | BU291: =($D291*(4-$Y291)+$E291*($X291-4))/($X291-$Y291) -> 2.7215197 | BV291: =($D291*(5-$Y291)+$E291*($X291-5))/($X291-$Y291) -> 2.8779654 | BW291: =($E291*(6-$Z291)+$F291*($Y291-6))/($Y291-$Z291) -> 3.0354567 | BX291: =($E291*(7-$Z291)+$F291*($Y291-7))/($Y291-$Z291) -> 3.1933719 | BY291: =($F291*(8-$AA291)+$G291*($Z291-8))/($Z291-$AA291) -> 3.3282363 | BZ291: =($F291*(9-$AA291)+$G291*($Z291-9))/($Z291-$AA291) -> 3.4609234 | CA291: =($F291*(10-$AA291)+$G291*($Z291-10))/($Z291-$AA291) -> 3.5936106 | CB291: =($F291*(11-$AA291)+$G291*($Z291-11))/($Z291-$AA291) -> 3.7262978 | CC291: =CB291+(BB291-AX291)/5 -> 3.8018412 | CD291: =CC291+(BC291-AY291)/5 -> 3.8701951 | CE291: =CD291+(BD291-AZ291)/5 -> 3.9313597 | CF291: =CE291+(BE291-BA291)/5 -> 3.9897581 | CG291: =CF291+(BF291-BB291)/5 -> 4.0420326 | CH291: =CG291+(BG291-BC291)/5 -> 4.0881832 | CI291: =CH291+(BH291-BD291)/5 -> 4.1250873 | CJ291: =CI291+(BI291-BE291)/5 -> 4.1526076 | ... CP291: =CO291+(BO291-BK291)/5 -> 4.2081841 | CQ291: =$CP291+'Stichtag-UGB'!AA291-'Stichtag-UGB'!$Z291 -> 4.1981841 | CR291: =$CP291+'Stichtag-UGB'!AB291-'Stichtag-UGB'!$Z291 -> 4.1981841 | CS291: =$CP291+'Stichtag-UGB'!AC291-'Stichtag-UGB'!$Z291 -> 4.1881841 | CT291: =$CP291+'Stichtag-UGB'!AD291-'Stichtag-UGB'!$Z291 -> 4.1781841 | CU291: =$CP291+'Stichtag-UGB'!AE291-'Stichtag-UGB'!$Z291 -> 4.1781841 | CV291: =$CP291+'Stichtag-UGB'!AF291-'Stichtag-UGB'!$Z291 -> 4.1581841 | CW291: =$CP291+'Stichtag-UGB'!AG291-'Stichtag-UGB'!$Z291 -> 4.1381841 | CX291: =$CP291+'Stichtag-UGB'!AH291-'Stichtag-UGB'!$Z291 -> 4.1281841 | ... DO291: =$CP291+'Stichtag-UGB'!AY291-'Stichtag-UGB'!$Z291 -> 3.8581841
A292: 46112 | B292: Annual Yield to maturity | C292: =C291 -> 2.4373 | D292: =D291 -> 2.6583 | E292: =E291 -> 2.9231 | F292: =F291 -> 3.207 | G292: =G291 -> 3.7984 | H292: =H291 -> 2.1181 | I292: =I291 -> 2.2667 | J292: =J291 -> 2.6128 | ... T292: =T291 -> 3.7213 | V292: Modified Duration to maturity | W292: =W291 -> 1.8431 | X292: =X291 -> 3.5959 | Y292: =Y291 -> 5.2885 | Z292: =Z291 -> 7.0863 | AA292: =AA291 -> 11.5434 | AB292: =AB291 -> 1.7777 | AC292: =AC291 -> 2.7399 | AD292: =AD291 -> 4.5984 | ... AN292: =AN291 -> 25.0314 | AP292: Staatsanleihen | AR292: =AR291 -> 2.1524315 | AS292: =AS291 -> 2.2860798 | AT292: =AT291 -> 2.4334163 | AU292: =AU291 -> 2.5919742 | AV292: =AV291 -> 2.6664585 | AW292: =AW291 -> 2.8432518 | AX292: =AX291 -> 2.9782295 | AY292: =AY291 -> 3.0886228 | ... BO292: =BO291 -> 3.7314703 | BQ292: Unternehmensanleihen | BR292: =BR291 -> 2.4470826 | BS292: =BS291 -> 2.4570826 | BT292: =BT291 -> 2.5831666 | BU292: =BU291 -> 2.7215197 | BV292: =BV291 -> 2.8779654 | BW292: =BW291 -> 3.0354567 | BX292: =BX291 -> 3.1933719 | BY292: =BY291 -> 3.3282363 | ... DO292: =DO291 -> 3.8581841
A293: 46142 | B293: Annual Yield to maturity | C293: =C292 -> 2.4373 | D293: =D292 -> 2.6583 | E293: =E292 -> 2.9231 | F293: =F292 -> 3.207 | G293: =G292 -> 3.7984 | H293: =H292 -> 2.1181 | I293: =I292 -> 2.2667 | J293: =J292 -> 2.6128 | ... T293: =T292 -> 3.7213 | V293: Modified Duration to maturity | W293: =W292 -> 1.8431 | X293: =X292 -> 3.5959 | Y293: =Y292 -> 5.2885 | Z293: =Z292 -> 7.0863 | AA293: =AA292 -> 11.5434 | AB293: =AB292 -> 1.7777 | AC293: =AC292 -> 2.7399 | AD293: =AD292 -> 4.5984 | ... AN293: =AN292 -> 25.0314 | AP293: Staatsanleihen | AR293: =AR292 -> 2.1524315 | AS293: =AS292 -> 2.2860798 | AT293: =AT292 -> 2.4334163 | AU293: =AU292 -> 2.5919742 | AV293: =AV292 -> 2.6664585 | AW293: =AW292 -> 2.8432518 | AX293: =AX292 -> 2.9782295 | AY293: =AY292 -> 3.0886228 | ... BO293: =BO292 -> 3.7314703 | BQ293: Unternehmensanleihen | BR293: =BR292 -> 2.4470826 | BS293: =BS292 -> 2.4570826 | BT293: =BT292 -> 2.5831666 | BU293: =BU292 -> 2.7215197 | BV293: =BV292 -> 2.8779654 | BW293: =BW292 -> 3.0354567 | BX293: =BX292 -> 3.1933719 | BY293: =BY292 -> 3.3282363 | ... DO293: =DO292 -> 3.8581841
A294: 46173 | B294: Annual Yield to maturity | C294: =C293 -> 2.4373 | D294: =D293 -> 2.6583 | E294: =E293 -> 2.9231 | F294: =F293 -> 3.207 | G294: =G293 -> 3.7984 | H294: =H293 -> 2.1181 | I294: =I293 -> 2.2667 | J294: =J293 -> 2.6128 | ... T294: =T293 -> 3.7213 | V294: Modified Duration to maturity | W294: =W293 -> 1.8431 | X294: =X293 -> 3.5959 | Y294: =Y293 -> 5.2885 | Z294: =Z293 -> 7.0863 | AA294: =AA293 -> 11.5434 | AB294: =AB293 -> 1.7777 | AC294: =AC293 -> 2.7399 | AD294: =AD293 -> 4.5984 | ... AN294: =AN293 -> 25.0314 | AP294: Staatsanleihen | AR294: =AR293 -> 2.1524315 | AS294: =AS293 -> 2.2860798 | AT294: =AT293 -> 2.4334163 | AU294: =AU293 -> 2.5919742 | AV294: =AV293 -> 2.6664585 | AW294: =AW293 -> 2.8432518 | AX294: =AX293 -> 2.9782295 | AY294: =AY293 -> 3.0886228 | ... BO294: =BO293 -> 3.7314703 | BQ294: Unternehmensanleihen | BR294: =BR293 -> 2.4470826 | BS294: =BS293 -> 2.4570826 | BT294: =BT293 -> 2.5831666 | BU294: =BU293 -> 2.7215197 | BV294: =BV293 -> 2.8779654 | BW294: =BW293 -> 3.0354567 | BX294: =BX293 -> 3.1933719 | BY294: =BY293 -> 3.3282363 | ... DO294: =DO293 -> 3.8581841
A295: 46203 | B295: Annual Yield to maturity | C295: =C294 -> 2.4373 | D295: =D294 -> 2.6583 | E295: =E294 -> 2.9231 | F295: =F294 -> 3.207 | G295: =G294 -> 3.7984 | H295: =H294 -> 2.1181 | I295: =I294 -> 2.2667 | J295: =J294 -> 2.6128 | ... T295: =T294 -> 3.7213 | V295: Modified Duration to maturity | W295: =W294 -> 1.8431 | X295: =X294 -> 3.5959 | Y295: =Y294 -> 5.2885 | Z295: =Z294 -> 7.0863 | AA295: =AA294 -> 11.5434 | AB295: =AB294 -> 1.7777 | AC295: =AC294 -> 2.7399 | AD295: =AD294 -> 4.5984 | ... AN295: =AN294 -> 25.0314 | AP295: Staatsanleihen | AR295: =AR294 -> 2.1524315 | AS295: =AS294 -> 2.2860798 | AT295: =AT294 -> 2.4334163 | AU295: =AU294 -> 2.5919742 | AV295: =AV294 -> 2.6664585 | AW295: =AW294 -> 2.8432518 | AX295: =AX294 -> 2.9782295 | AY295: =AY294 -> 3.0886228 | ... BO295: =BO294 -> 3.7314703 | BQ295: Unternehmensanleihen | BR295: =BR294 -> 2.4470826 | BS295: =BS294 -> 2.4570826 | BT295: =BT294 -> 2.5831666 | BU295: =BU294 -> 2.7215197 | BV295: =BV294 -> 2.8779654 | BW295: =BW294 -> 3.0354567 | BX295: =BX294 -> 3.1933719 | BY295: =BY294 -> 3.3282363 | ... DO295: =DO294 -> 3.8581841
A296: 46234 | B296: Annual Yield to maturity | C296: =C295 -> 2.4373 | D296: =D295 -> 2.6583 | E296: =E295 -> 2.9231 | F296: =F295 -> 3.207 | G296: =G295 -> 3.7984 | H296: =H295 -> 2.1181 | I296: =I295 -> 2.2667 | J296: =J295 -> 2.6128 | ... T296: =T295 -> 3.7213 | V296: Modified Duration to maturity | W296: =W295 -> 1.8431 | X296: =X295 -> 3.5959 | Y296: =Y295 -> 5.2885 | Z296: =Z295 -> 7.0863 | AA296: =AA295 -> 11.5434 | AB296: =AB295 -> 1.7777 | AC296: =AC295 -> 2.7399 | AD296: =AD295 -> 4.5984 | ... AN296: =AN295 -> 25.0314 | AP296: Staatsanleihen | AR296: =AR295 -> 2.1524315 | AS296: =AS295 -> 2.2860798 | AT296: =AT295 -> 2.4334163 | AU296: =AU295 -> 2.5919742 | AV296: =AV295 -> 2.6664585 | AW296: =AW295 -> 2.8432518 | AX296: =AX295 -> 2.9782295 | AY296: =AY295 -> 3.0886228 | ... BO296: =BO295 -> 3.7314703 | BQ296: Unternehmensanleihen | BR296: =BR295 -> 2.4470826 | BS296: =BS295 -> 2.4570826 | BT296: =BT295 -> 2.5831666 | BU296: =BU295 -> 2.7215197 | BV296: =BV295 -> 2.8779654 | BW296: =BW295 -> 3.0354567 | BX296: =BX295 -> 3.1933719 | BY296: =BY295 -> 3.3282363 | ... DO296: =DO295 -> 3.8581841
A297: 46265 | B297: Annual Yield to maturity | C297: =C296 -> 2.4373 | D297: =D296 -> 2.6583 | E297: =E296 -> 2.9231 | F297: =F296 -> 3.207 | G297: =G296 -> 3.7984 | H297: =H296 -> 2.1181 | I297: =I296 -> 2.2667 | J297: =J296 -> 2.6128 | ... T297: =T296 -> 3.7213 | V297: Modified Duration to maturity | W297: =W296 -> 1.8431 | X297: =X296 -> 3.5959 | Y297: =Y296 -> 5.2885 | Z297: =Z296 -> 7.0863 | AA297: =AA296 -> 11.5434 | AB297: =AB296 -> 1.7777 | AC297: =AC296 -> 2.7399 | AD297: =AD296 -> 4.5984 | ... AN297: =AN296 -> 25.0314 | AP297: Staatsanleihen | AR297: =AR296 -> 2.1524315 | AS297: =AS296 -> 2.2860798 | AT297: =AT296 -> 2.4334163 | AU297: =AU296 -> 2.5919742 | AV297: =AV296 -> 2.6664585 | AW297: =AW296 -> 2.8432518 | AX297: =AX296 -> 2.9782295 | AY297: =AY296 -> 3.0886228 | ... BO297: =BO296 -> 3.7314703 | BQ297: Unternehmensanleihen | BR297: =BR296 -> 2.4470826 | BS297: =BS296 -> 2.4570826 | BT297: =BT296 -> 2.5831666 | BU297: =BU296 -> 2.7215197 | BV297: =BV296 -> 2.8779654 | BW297: =BW296 -> 3.0354567 | BX297: =BX296 -> 3.1933719 | BY297: =BY296 -> 3.3282363 | ... DO297: =DO296 -> 3.8581841
A298: 46295 | B298: Annual Yield to maturity | C298: =C297 -> 2.4373 | D298: =D297 -> 2.6583 | E298: =E297 -> 2.9231 | F298: =F297 -> 3.207 | G298: =G297 -> 3.7984 | H298: =H297 -> 2.1181 | I298: =I297 -> 2.2667 | J298: =J297 -> 2.6128 | ... T298: =T297 -> 3.7213 | V298: Modified Duration to maturity | W298: =W297 -> 1.8431 | X298: =X297 -> 3.5959 | Y298: =Y297 -> 5.2885 | Z298: =Z297 -> 7.0863 | AA298: =AA297 -> 11.5434 | AB298: =AB297 -> 1.7777 | AC298: =AC297 -> 2.7399 | AD298: =AD297 -> 4.5984 | ... AN298: =AN297 -> 25.0314 | AP298: Staatsanleihen | AR298: =AR297 -> 2.1524315 | AS298: =AS297 -> 2.2860798 | AT298: =AT297 -> 2.4334163 | AU298: =AU297 -> 2.5919742 | AV298: =AV297 -> 2.6664585 | AW298: =AW297 -> 2.8432518 | AX298: =AX297 -> 2.9782295 | AY298: =AY297 -> 3.0886228 | ... BO298: =BO297 -> 3.7314703 | BQ298: Unternehmensanleihen | BR298: =BR297 -> 2.4470826 | BS298: =BS297 -> 2.4570826 | BT298: =BT297 -> 2.5831666 | BU298: =BU297 -> 2.7215197 | BV298: =BV297 -> 2.8779654 | BW298: =BW297 -> 3.0354567 | BX298: =BX297 -> 3.1933719 | BY298: =BY297 -> 3.3282363 | ... DO298: =DO297 -> 3.8581841
A299: 46326 | B299: Annual Yield to maturity | C299: =C298 -> 2.4373 | D299: =D298 -> 2.6583 | E299: =E298 -> 2.9231 | F299: =F298 -> 3.207 | G299: =G298 -> 3.7984 | H299: =H298 -> 2.1181 | I299: =I298 -> 2.2667 | J299: =J298 -> 2.6128 | ... T299: =T298 -> 3.7213 | V299: Modified Duration to maturity | W299: =W298 -> 1.8431 | X299: =X298 -> 3.5959 | Y299: =Y298 -> 5.2885 | Z299: =Z298 -> 7.0863 | AA299: =AA298 -> 11.5434 | AB299: =AB298 -> 1.7777 | AC299: =AC298 -> 2.7399 | AD299: =AD298 -> 4.5984 | ... AN299: =AN298 -> 25.0314 | AP299: Staatsanleihen | AR299: =AR298 -> 2.1524315 | AS299: =AS298 -> 2.2860798 | AT299: =AT298 -> 2.4334163 | AU299: =AU298 -> 2.5919742 | AV299: =AV298 -> 2.6664585 | AW299: =AW298 -> 2.8432518 | AX299: =AX298 -> 2.9782295 | AY299: =AY298 -> 3.0886228 | ... BO299: =BO298 -> 3.7314703 | BQ299: Unternehmensanleihen | BR299: =BR298 -> 2.4470826 | BS299: =BS298 -> 2.4570826 | BT299: =BT298 -> 2.5831666 | BU299: =BU298 -> 2.7215197 | BV299: =BV298 -> 2.8779654 | BW299: =BW298 -> 3.0354567 | BX299: =BX298 -> 3.1933719 | BY299: =BY298 -> 3.3282363 | ... DO299: =DO298 -> 3.8581841
A300: 46356 | B300: Annual Yield to maturity | C300: =C299 -> 2.4373 | D300: =D299 -> 2.6583 | E300: =E299 -> 2.9231 | F300: =F299 -> 3.207 | G300: =G299 -> 3.7984 | H300: =H299 -> 2.1181 | I300: =I299 -> 2.2667 | J300: =J299 -> 2.6128 | ... T300: =T299 -> 3.7213 | V300: Modified Duration to maturity | W300: =W299 -> 1.8431 | X300: =X299 -> 3.5959 | Y300: =Y299 -> 5.2885 | Z300: =Z299 -> 7.0863 | AA300: =AA299 -> 11.5434 | AB300: =AB299 -> 1.7777 | AC300: =AC299 -> 2.7399 | AD300: =AD299 -> 4.5984 | ... AN300: =AN299 -> 25.0314 | AP300: Staatsanleihen | AR300: =AR299 -> 2.1524315 | AS300: =AS299 -> 2.2860798 | AT300: =AT299 -> 2.4334163 | AU300: =AU299 -> 2.5919742 | AV300: =AV299 -> 2.6664585 | AW300: =AW299 -> 2.8432518 | AX300: =AX299 -> 2.9782295 | AY300: =AY299 -> 3.0886228 | ... BO300: =BO299 -> 3.7314703 | BQ300: Unternehmensanleihen | BR300: =BR299 -> 2.4470826 | BS300: =BS299 -> 2.4570826 | BT300: =BT299 -> 2.5831666 | BU300: =BU299 -> 2.7215197 | BV300: =BV299 -> 2.8779654 | BW300: =BW299 -> 3.0354567 | BX300: =BX299 -> 3.1933719 | BY300: =BY299 -> 3.3282363 | ... DO300: =DO299 -> 3.8581841
A301: 46387 | B301: Annual Yield to maturity | C301: =C300 -> 2.4373 | D301: =D300 -> 2.6583 | E301: =E300 -> 2.9231 | F301: =F300 -> 3.207 | G301: =G300 -> 3.7984 | H301: =H300 -> 2.1181 | I301: =I300 -> 2.2667 | J301: =J300 -> 2.6128 | ... T301: =T300 -> 3.7213 | V301: Modified Duration to maturity | W301: =W300 -> 1.8431 | X301: =X300 -> 3.5959 | Y301: =Y300 -> 5.2885 | Z301: =Z300 -> 7.0863 | AA301: =AA300 -> 11.5434 | AB301: =AB300 -> 1.7777 | AC301: =AC300 -> 2.7399 | AD301: =AD300 -> 4.5984 | ... AN301: =AN300 -> 25.0314 | AP301: Staatsanleihen | AR301: =AR300 -> 2.1524315 | AS301: =AS300 -> 2.2860798 | AT301: =AT300 -> 2.4334163 | AU301: =AU300 -> 2.5919742 | AV301: =AV300 -> 2.6664585 | AW301: =AW300 -> 2.8432518 | AX301: =AX300 -> 2.9782295 | AY301: =AY300 -> 3.0886228 | ... BO301: =BO300 -> 3.7314703 | BQ301: Unternehmensanleihen | BR301: =BR300 -> 2.4470826 | BS301: =BS300 -> 2.4570826 | BT301: =BT300 -> 2.5831666 | BU301: =BU300 -> 2.7215197 | BV301: =BV300 -> 2.8779654 | BW301: =BW300 -> 3.0354567 | BX301: =BX300 -> 3.1933719 | BY301: =BY300 -> 3.3282363 | ... DO301: =DO300 -> 3.8581841
...

Sheet iBoxx Extrapolation
A1: Stichtag | B1: BAY | C1: AMD | D1: BAY+ZD | F1: Aufschlag St. | G1: Aufschlag 5J | H1: Aufschlag 6J | I1: Aufschlag 7J | J1: Aufschlag 8J | K1: Aufschlag 9J | L1: Aufschlag 10J
A2: 37287 | B2: 5.31 | C2: 5.16 | D2: {=_xlfn.LET( _xlpm.stichtag,DATEVALUE(RIGHT(Zinsbandbreite!$D$1,10)), _xlpm.starts,Zinsbandbreite!$A$3:$A$13, _xlpm.deltas,Zinsbandbreite!$C$3:$C$13/12*100, _xlpm.monStichtagRaw,(YEAR(_xlpm.stichtag)-YEAR(_xlpm.starts))*12+MONTH(_xlpm.stichtag)-MONTH(_xlpm.starts), _xlpm.monZeileRaw,(YEAR(A2)-YEAR(_xlpm.starts))*12+MONTH(A2)-MONTH(_xlpm.starts), _xlpm.monStichtag,IF(_xlpm.monStichtagRaw<0,0,IF(_xlpm.monStichtagRaw>12,12,_xlpm.monStichtagRaw)), _xlpm.monZeile,IF(_xlpm.monZeileRaw<0,0,IF(_xlpm.monZeileRaw>12,12,_xlpm.monZeileRaw)), _xlpm.stufenRaw,_xlpm.monZeile-_xlpm.monStichtag, _xlpm.stufen,IF(_xlpm.stufenRaw<0,0,_xlpm.stufenRaw), B2+SUMPRODUCT(_xlpm.deltas*_xlpm.stufen) )} -> 5.31
A3: 37315 | B3: 5.32 | C3: 5.08 | D3: {=_xlfn.LET( _xlpm.stichtag,DATEVALUE(RIGHT(Zinsbandbreite!$D$1,10)), _xlpm.starts,Zinsbandbreite!$A$3:$A$13, _xlpm.deltas,Zinsbandbreite!$C$3:$C$13/12*100, _xlpm.monStichtagRaw,(YEAR(_xlpm.stichtag)-YEAR(_xlpm.starts))*12+MONTH(_xlpm.stichtag)-MONTH(_xlpm.starts), _xlpm.monZeileRaw,(YEAR(A3)-YEAR(_xlpm.starts))*12+MONTH(A3)-MONTH(_xlpm.starts), _xlpm.monStichtag,IF(_xlpm.monStichtagRaw<0,0,IF(_xlpm.monStichtagRaw>12,12,_xlpm.monStichtagRaw)), _xlpm.monZeile,IF(_xlpm.monZeileRaw<0,0,IF(_xlpm.monZeileRaw>12,12,_xlpm.monZeileRaw)), _xlpm.stufenRaw,_xlpm.monZeile-_xlpm.monStichtag, _xlpm.stufen,IF(_xlpm.stufenRaw<0,0,_xlpm.stufenRaw), B3+SUMPRODUCT(_xlpm.deltas*_xlpm.stufen) )} -> 5.32
A4: 37346 | B4: 5.6 | C4: 5.08 | D4: {=_xlfn.LET( _xlpm.stichtag,DATEVALUE(RIGHT(Zinsbandbreite!$D$1,10)), _xlpm.starts,Zinsbandbreite!$A$3:$A$13, _xlpm.deltas,Zinsbandbreite!$C$3:$C$13/12*100, _xlpm.monStichtagRaw,(YEAR(_xlpm.stichtag)-YEAR(_xlpm.starts))*12+MONTH(_xlpm.stichtag)-MONTH(_xlpm.starts), _xlpm.monZeileRaw,(YEAR(A4)-YEAR(_xlpm.starts))*12+MONTH(A4)-MONTH(_xlpm.starts), _xlpm.monStichtag,IF(_xlpm.monStichtagRaw<0,0,IF(_xlpm.monStichtagRaw>12,12,_xlpm.monStichtagRaw)), _xlpm.monZeile,IF(_xlpm.monZeileRaw<0,0,IF(_xlpm.monZeileRaw>12,12,_xlpm.monZeileRaw)), _xlpm.stufenRaw,_xlpm.monZeile-_xlpm.monStichtag, _xlpm.stufen,IF(_xlpm.stufenRaw<0,0,_xlpm.stufenRaw), B4+SUMPRODUCT(_xlpm.deltas*_xlpm.stufen) )} -> 5.6
A5: 37376 | B5: 5.45 | C5: 5.01 | D5: {=_xlfn.LET( _xlpm.stichtag,DATEVALUE(RIGHT(Zinsbandbreite!$D$1,10)), _xlpm.starts,Zinsbandbreite!$A$3:$A$13, _xlpm.deltas,Zinsbandbreite!$C$3:$C$13/12*100, _xlpm.monStichtagRaw,(YEAR(_xlpm.stichtag)-YEAR(_xlpm.starts))*12+MONTH(_xlpm.stichtag)-MONTH(_xlpm.starts), _xlpm.monZeileRaw,(YEAR(A5)-YEAR(_xlpm.starts))*12+MONTH(A5)-MONTH(_xlpm.starts), _xlpm.monStichtag,IF(_xlpm.monStichtagRaw<0,0,IF(_xlpm.monStichtagRaw>12,12,_xlpm.monStichtagRaw)), _xlpm.monZeile,IF(_xlpm.monZeileRaw<0,0,IF(_xlpm.monZeileRaw>12,12,_xlpm.monZeileRaw)), _xlpm.stufenRaw,_xlpm.monZeile-_xlpm.monStichtag, _xlpm.stufen,IF(_xlpm.stufenRaw<0,0,_xlpm.stufenRaw), B5+SUMPRODUCT(_xlpm.deltas*_xlpm.stufen) )} -> 5.45
A6: 37407 | B6: 5.51 | C6: 5.03 | D6: {=_xlfn.LET( _xlpm.stichtag,DATEVALUE(RIGHT(Zinsbandbreite!$D$1,10)), _xlpm.starts,Zinsbandbreite!$A$3:$A$13, _xlpm.deltas,Zinsbandbreite!$C$3:$C$13/12*100, _xlpm.monStichtagRaw,(YEAR(_xlpm.stichtag)-YEAR(_xlpm.starts))*12+MONTH(_xlpm.stichtag)-MONTH(_xlpm.starts), _xlpm.monZeileRaw,(YEAR(A6)-YEAR(_xlpm.starts))*12+MONTH(A6)-MONTH(_xlpm.starts), _xlpm.monStichtag,IF(_xlpm.monStichtagRaw<0,0,IF(_xlpm.monStichtagRaw>12,12,_xlpm.monStichtagRaw)), _xlpm.monZeile,IF(_xlpm.monZeileRaw<0,0,IF(_xlpm.monZeileRaw>12,12,_xlpm.monZeileRaw)), _xlpm.stufenRaw,_xlpm.monZeile-_xlpm.monStichtag, _xlpm.stufen,IF(_xlpm.stufenRaw<0,0,_xlpm.stufenRaw), B6+SUMPRODUCT(_xlpm.deltas*_xlpm.stufen) )} -> 5.51
A7: 37437 | B7: 5.32 | C7: 5.06 | D7: {=_xlfn.LET( _xlpm.stichtag,DATEVALUE(RIGHT(Zinsbandbreite!$D$1,10)), _xlpm.starts,Zinsbandbreite!$A$3:$A$13, _xlpm.deltas,Zinsbandbreite!$C$3:$C$13/12*100, _xlpm.monStichtagRaw,(YEAR(_xlpm.stichtag)-YEAR(_xlpm.starts))*12+MONTH(_xlpm.stichtag)-MONTH(_xlpm.starts), _xlpm.monZeileRaw,(YEAR(A7)-YEAR(_xlpm.starts))*12+MONTH(A7)-MONTH(_xlpm.starts), _xlpm.monStichtag,IF(_xlpm.monStichtagRaw<0,0,IF(_xlpm.monStichtagRaw>12,12,_xlpm.monStichtagRaw)), _xlpm.monZeile,IF(_xlpm.monZeileRaw<0,0,IF(_xlpm.monZeileRaw>12,12,_xlpm.monZeileRaw)), _xlpm.stufenRaw,_xlpm.monZeile-_xlpm.monStichtag, _xlpm.stufen,IF(_xlpm.stufenRaw<0,0,_xlpm.stufenRaw), B7+SUMPRODUCT(_xlpm.deltas*_xlpm.stufen) )} -> 5.32
A8: 37468 | B8: 5.17 | C8: 5 | D8: {=_xlfn.LET( _xlpm.stichtag,DATEVALUE(RIGHT(Zinsbandbreite!$D$1,10)), _xlpm.starts,Zinsbandbreite!$A$3:$A$13, _xlpm.deltas,Zinsbandbreite!$C$3:$C$13/12*100, _xlpm.monStichtagRaw,(YEAR(_xlpm.stichtag)-YEAR(_xlpm.starts))*12+MONTH(_xlpm.stichtag)-MONTH(_xlpm.starts), _xlpm.monZeileRaw,(YEAR(A8)-YEAR(_xlpm.starts))*12+MONTH(A8)-MONTH(_xlpm.starts), _xlpm.monStichtag,IF(_xlpm.monStichtagRaw<0,0,IF(_xlpm.monStichtagRaw>12,12,_xlpm.monStichtagRaw)), _xlpm.monZeile,IF(_xlpm.monZeileRaw<0,0,IF(_xlpm.monZeileRaw>12,12,_xlpm.monZeileRaw)), _xlpm.stufenRaw,_xlpm.monZeile-_xlpm.monStichtag, _xlpm.stufen,IF(_xlpm.stufenRaw<0,0,_xlpm.stufenRaw), B8+SUMPRODUCT(_xlpm.deltas*_xlpm.stufen) )} -> 5.17
A9: 37499 | B9: 4.95 | C9: 4.98 | D9: {=_xlfn.LET( _xlpm.stichtag,DATEVALUE(RIGHT(Zinsbandbreite!$D$1,10)), _xlpm.starts,Zinsbandbreite!$A$3:$A$13, _xlpm.deltas,Zinsbandbreite!$C$3:$C$13/12*100, _xlpm.monStichtagRaw,(YEAR(_xlpm.stichtag)-YEAR(_xlpm.starts))*12+MONTH(_xlpm.stichtag)-MONTH(_xlpm.starts), _xlpm.monZeileRaw,(YEAR(A9)-YEAR(_xlpm.starts))*12+MONTH(A9)-MONTH(_xlpm.starts), _xlpm.monStichtag,IF(_xlpm.monStichtagRaw<0,0,IF(_xlpm.monStichtagRaw>12,12,_xlpm.monStichtagRaw)), _xlpm.monZeile,IF(_xlpm.monZeileRaw<0,0,IF(_xlpm.monZeileRaw>12,12,_xlpm.monZeileRaw)), _xlpm.stufenRaw,_xlpm.monZeile-_xlpm.monStichtag, _xlpm.stufen,IF(_xlpm.stufenRaw<0,0,_xlpm.stufenRaw), B9+SUMPRODUCT(_xlpm.deltas*_xlpm.stufen) )} -> 4.95
A10: 37529 | B10: 4.67 | C10: 4.98 | D10: {=_xlfn.LET( _xlpm.stichtag,DATEVALUE(RIGHT(Zinsbandbreite!$D$1,10)), _xlpm.starts,Zinsbandbreite!$A$3:$A$13, _xlpm.deltas,Zinsbandbreite!$C$3:$C$13/12*100, _xlpm.monStichtagRaw,(YEAR(_xlpm.stichtag)-YEAR(_xlpm.starts))*12+MONTH(_xlpm.stichtag)-MONTH(_xlpm.starts), _xlpm.monZeileRaw,(YEAR(A10)-YEAR(_xlpm.starts))*12+MONTH(A10)-MONTH(_xlpm.starts), _xlpm.monStichtag,IF(_xlpm.monStichtagRaw<0,0,IF(_xlpm.monStichtagRaw>12,12,_xlpm.monStichtagRaw)), _xlpm.monZeile,IF(_xlpm.monZeileRaw<0,0,IF(_xlpm.monZeileRaw>12,12,_xlpm.monZeileRaw)), _xlpm.stufenRaw,_xlpm.monZeile-_xlpm.monStichtag, _xlpm.stufen,IF(_xlpm.stufenRaw<0,0,_xlpm.stufenRaw), B10+SUMPRODUCT(_xlpm.deltas*_xlpm.stufen) )} -> 4.67
A11: 37560 | B11: 4.85 | C11: 4.85 | D11: {=_xlfn.LET( _xlpm.stichtag,DATEVALUE(RIGHT(Zinsbandbreite!$D$1,10)), _xlpm.starts,Zinsbandbreite!$A$3:$A$13, _xlpm.deltas,Zinsbandbreite!$C$3:$C$13/12*100, _xlpm.monStichtagRaw,(YEAR(_xlpm.stichtag)-YEAR(_xlpm.starts))*12+MONTH(_xlpm.stichtag)-MONTH(_xlpm.starts), _xlpm.monZeileRaw,(YEAR(A11)-YEAR(_xlpm.starts))*12+MONTH(A11)-MONTH(_xlpm.starts), _xlpm.monStichtag,IF(_xlpm.monStichtagRaw<0,0,IF(_xlpm.monStichtagRaw>12,12,_xlpm.monStichtagRaw)), _xlpm.monZeile,IF(_xlpm.monZeileRaw<0,0,IF(_xlpm.monZeileRaw>12,12,_xlpm.monZeileRaw)), _xlpm.stufenRaw,_xlpm.monZeile-_xlpm.monStichtag, _xlpm.stufen,IF(_xlpm.stufenRaw<0,0,_xlpm.stufenRaw), B11+SUMPRODUCT(_xlpm.deltas*_xlpm.stufen) )} -> 4.85
A12: 37590 | B12: 4.75 | C12: 4.95 | D12: {=_xlfn.LET( _xlpm.stichtag,DATEVALUE(RIGHT(Zinsbandbreite!$D$1,10)), _xlpm.starts,Zinsbandbreite!$A$3:$A$13, _xlpm.deltas,Zinsbandbreite!$C$3:$C$13/12*100, _xlpm.monStichtagRaw,(YEAR(_xlpm.stichtag)-YEAR(_xlpm.starts))*12+MONTH(_xlpm.stichtag)-MONTH(_xlpm.starts), _xlpm.monZeileRaw,(YEAR(A12)-YEAR(_xlpm.starts))*12+MONTH(A12)-MONTH(_xlpm.starts), _xlpm.monStichtag,IF(_xlpm.monStichtagRaw<0,0,IF(_xlpm.monStichtagRaw>12,12,_xlpm.monStichtagRaw)), _xlpm.monZeile,IF(_xlpm.monZeileRaw<0,0,IF(_xlpm.monZeileRaw>12,12,_xlpm.monZeileRaw)), _xlpm.stufenRaw,_xlpm.monZeile-_xlpm.monStichtag, _xlpm.stufen,IF(_xlpm.stufenRaw<0,0,_xlpm.stufenRaw), B12+SUMPRODUCT(_xlpm.deltas*_xlpm.stufen) )} -> 4.75
A13: 37621 | B13: 4.45 | C13: 5.02 | D13: {=_xlfn.LET( _xlpm.stichtag,DATEVALUE(RIGHT(Zinsbandbreite!$D$1,10)), _xlpm.starts,Zinsbandbreite!$A$3:$A$13, _xlpm.deltas,Zinsbandbreite!$C$3:$C$13/12*100, _xlpm.monStichtagRaw,(YEAR(_xlpm.stichtag)-YEAR(_xlpm.starts))*12+MONTH(_xlpm.stichtag)-MONTH(_xlpm.starts), _xlpm.monZeileRaw,(YEAR(A13)-YEAR(_xlpm.starts))*12+MONTH(A13)-MONTH(_xlpm.starts), _xlpm.monStichtag,IF(_xlpm.monStichtagRaw<0,0,IF(_xlpm.monStichtagRaw>12,12,_xlpm.monStichtagRaw)), _xlpm.monZeile,IF(_xlpm.monZeileRaw<0,0,IF(_xlpm.monZeileRaw>12,12,_xlpm.monZeileRaw)), _xlpm.stufenRaw,_xlpm.monZeile-_xlpm.monStichtag, _xlpm.stufen,IF(_xlpm.stufenRaw<0,0,_xlpm.stufenRaw), B13+SUMPRODUCT(_xlpm.deltas*_xlpm.stufen) )} -> 4.45
... A84: 39782 | B84: 6.33 | C84: 3.93 | D84: {=_xlfn.LET( _xlpm.stichtag,DATEVALUE(RIGHT(Zinsbandbreite!$D$1,10)), _xlpm.starts,Zinsbandbreite!$A$3:$A$13, _xlpm.deltas,Zinsbandbreite!$C$3:$C$13/12*100, _xlpm.monStichtagRaw,(YEAR(_xlpm.stichtag)-YEAR(_xlpm.starts))*12+MONTH(_xlpm.stichtag)-MONTH(_xlpm.starts), _xlpm.monZeileRaw,(YEAR(A84)-YEAR(_xlpm.starts))*12+MONTH(A84)-MONTH(_xlpm.starts), _xlpm.monStichtag,IF(_xlpm.monStichtagRaw<0,0,IF(_xlpm.monStichtagRaw>12,12,_xlpm.monStichtagRaw)), _xlpm.monZeile,IF(_xlpm.monZeileRaw<0,0,IF(_xlpm.monZeileRaw>12,12,_xlpm.monZeileRaw)), _xlpm.stufenRaw,_xlpm.monZeile-_xlpm.monStichtag, _xlpm.stufen,IF(_xlpm.stufenRaw<0,0,_xlpm.stufenRaw), B84+SUMPRODUCT(_xlpm.deltas*_xlpm.stufen) )} -> 6.33
A85: 39813 | B85: 6.06 | C85: 3.87 | D85: {=_xlfn.LET( _xlpm.stichtag,DATEVALUE(RIGHT(Zinsbandbreite!$D$1,10)), _xlpm.starts,Zinsbandbreite!$A$3:$A$13, _xlpm.deltas,Zinsbandbreite!$C$3:$C$13/12*100, _xlpm.monStichtagRaw,(YEAR(_xlpm.stichtag)-YEAR(_xlpm.starts))*12+MONTH(_xlpm.stichtag)-MONTH(_xlpm.starts), _xlpm.monZeileRaw,(YEAR(A85)-YEAR(_xlpm.starts))*12+MONTH(A85)-MONTH(_xlpm.starts), _xlpm.monStichtag,IF(_xlpm.monStichtagRaw<0,0,IF(_xlpm.monStichtagRaw>12,12,_xlpm.monStichtagRaw)), _xlpm.monZeile,IF(_xlpm.monZeileRaw<0,0,IF(_xlpm.monZeileRaw>12,12,_xlpm.monZeileRaw)), _xlpm.stufenRaw,_xlpm.monZeile-_xlpm.monStichtag, _xlpm.stufen,IF(_xlpm.stufenRaw<0,0,_xlpm.stufenRaw), B85+SUMPRODUCT(_xlpm.deltas*_xlpm.stufen) )} -> 6.06 | F85: {=_xlfn.LET( _xlpm.rw,ROW(), _xlpm.dur,C85, _xlpm.n,INT(_xlpm.dur), _xlpm.x,_xlpm.dur-_xlpm.n, _xlpm.a,INDEX(Zinsswaps!$B:$AY,_xlpm.rw,_xlpm.n), _xlpm.b,INDEX(Zinsswaps!$B:$AY,_xlpm.rw,_xlpm.n+1), _xlpm.swap,_xlpm.a+_xlpm.x*(_xlpm.b-_xlpm.a), D85-_xlpm.swap )} -> 2.97145 | G85: =_xlfn.LET( _xlpm.rw,ROW(), _xlpm.dur,AVERAGE($C26:$C85), _xlpm.n,INT(_xlpm.dur), _xlpm.x,_xlpm.dur-_xlpm.n, _xlpm.a,AVERAGE(INDEX(Zinsswaps!$B:$AY,_xlpm.rw-59,_xlpm.n):INDEX(Zinsswaps!$B:$AY,_xlpm.rw,_xlpm.n)), _xlpm.b,AVERAGE(INDEX(Zinsswaps!$B:$AY,_xlpm.rw-59,_xlpm.n+1):INDEX(Zinsswaps!$B:$AY,_xlpm.rw,_xlpm.n+1)), _xlpm.swap,_xlpm.a+_xlpm.x*(_xlpm.b-_xlpm.a), _xlpm.yield,AVERAGE($D26:$D85), _xlpm.yield-_xlpm.swap ) -> 0.68554546 | H85: =_xlfn.LET( _xlpm.rw,ROW(), _xlpm.dur,AVERAGE($C14:$C85), _xlpm.n,INT(_xlpm.dur), _xlpm.x,_xlpm.dur-_xlpm.n, _xlpm.a,AVERAGE(INDEX(Zinsswaps!$B:$AY,_xlpm.rw-71,_xlpm.n):INDEX(Zinsswaps!$B:$AY,_xlpm.rw,_xlpm.n)), _xlpm.b,AVERAGE(INDEX(Zinsswaps!$B:$AY,_xlpm.rw-71,_xlpm.n+1):INDEX(Zinsswaps!$B:$AY,_xlpm.rw,_xlpm.n+1)), _xlpm.swap,_xlpm.a+_xlpm.x*(_xlpm.b-_xlpm.a), _xlpm.yield,AVERAGE($D14:$D85), _xlpm.yield-_xlpm.swap ) -> 0.6838358 | I85: =_xlfn.LET( _xlpm.rw,ROW(), _xlpm.dur,AVERAGE($C2:$C85), _xlpm.n,INT(_xlpm.dur), _xlpm.x,_xlpm.dur-_xlpm.n, _xlpm.a,AVERAGE(INDEX(Zinsswaps!$B:$AY,_xlpm.rw-83,_xlpm.n):INDEX(Zinsswaps!$B:$AY,_xlpm.rw,_xlpm.n)), _xlpm.b,AVERAGE(INDEX(Zinsswaps!$B:$AY,_xlpm.rw-83,_xlpm.n+1):INDEX(Zinsswaps!$B:$AY,_xlpm.rw,_xlpm.n+1)), _xlpm.swap,_xlpm.a+_xlpm.x*(_xlpm.b-_xlpm.a), _xlpm.yield,AVERAGE($D2:$D85), _xlpm.yield-_xlpm.swap ) -> 0.67523828
A86: 39844 | B86: 5.69 | C86: 3.75 | D86: {=_xlfn.LET( _xlpm.stichtag,DATEVALUE(RIGHT(Zinsbandbreite!$D$1,10)), _xlpm.starts,Zinsbandbreite!$A$3:$A$13, _xlpm.deltas,Zinsbandbreite!$C$3:$C$13/12*100, _xlpm.monStichtagRaw,(YEAR(_xlpm.stichtag)-YEAR(_xlpm.starts))*12+MONTH(_xlpm.stichtag)-MONTH(_xlpm.starts), _xlpm.monZeileRaw,(YEAR(A86)-YEAR(_xlpm.starts))*12+MONTH(A86)-MONTH(_xlpm.starts), _xlpm.monStichtag,IF(_xlpm.monStichtagRaw<0,0,IF(_xlpm.monStichtagRaw>12,12,_xlpm.monStichtagRaw)), _xlpm.monZeile,IF(_xlpm.monZeileRaw<0,0,IF(_xlpm.monZeileRaw>12,12,_xlpm.monZeileRaw)), _xlpm.stufenRaw,_xlpm.monZeile-_xlpm.monStichtag, _xlpm.stufen,IF(_xlpm.stufenRaw<0,0,_xlpm.stufenRaw), B86+SUMPRODUCT(_xlpm.deltas*_xlpm.stufen) )} -> 5.69 | F86: {=_xlfn.LET( _xlpm.rw,ROW(), _xlpm.dur,C86, _xlpm.n,INT(_xlpm.dur), _xlpm.x,_xlpm.dur-_xlpm.n, _xlpm.a,INDEX(Zinsswaps!$B:$AY,_xlpm.rw,_xlpm.n), _xlpm.b,INDEX(Zinsswaps!$B:$AY,_xlpm.rw,_xlpm.n+1), _xlpm.swap,_xlpm.a+_xlpm.x*(_xlpm.b-_xlpm.a), D86-_xlpm.swap )} -> 2.949 | G86: =_xlfn.LET( _xlpm.rw,ROW(), _xlpm.dur,AVERAGE($C27:$C86), _xlpm.n,INT(_xlpm.dur), _xlpm.x,_xlpm.dur-_xlpm.n, _xlpm.a,AVERAGE(INDEX(Zinsswaps!$B:$AY,_xlpm.rw-59,_xlpm.n):INDEX(Zinsswaps!$B:$AY,_xlpm.rw,_xlpm.n)), _xlpm.b,AVERAGE(INDEX(Zinsswaps!$B:$AY,_xlpm.rw-59,_xlpm.n+1):INDEX(Zinsswaps!$B:$AY,_xlpm.rw,_xlpm.n+1)), _xlpm.swap,_xlpm.a+_xlpm.x*(_xlpm.b-_xlpm.a), _xlpm.yield,AVERAGE($D27:$D86), _xlpm.yield-_xlpm.swap ) -> 0.72261933 | H86: =_xlfn.LET( _xlpm.rw,ROW(), _xlpm.dur,AVERAGE($C15:$C86), _xlpm.n,INT(_xlpm.dur), _xlpm.x,_xlpm.dur-_xlpm.n, _xlpm.a,AVERAGE(INDEX(Zinsswaps!$B:$AY,_xlpm.rw-71,_xlpm.n):INDEX(Zinsswaps!$B:$AY,_xlpm.rw,_xlpm.n)), _xlpm.b,AVERAGE(INDEX(Zinsswaps!$B:$AY,_xlpm.rw-71,_xlpm.n+1):INDEX(Zinsswaps!$B:$AY,_xlpm.rw,_xlpm.n+1)), _xlpm.swap,_xlpm.a+_xlpm.x*(_xlpm.b-_xlpm.a), _xlpm.yield,AVERAGE($D15:$D86), _xlpm.yield-_xlpm.swap ) -> 0.71243492 | I86: =_xlfn.LET( _xlpm.rw,ROW(), _xlpm.dur,AVERAGE($C3:$C86), _xlpm.n,INT(_xlpm.dur), _xlpm.x,_xlpm.dur-_xlpm.n, _xlpm.a,AVERAGE(INDEX(Zinsswaps!$B:$AY,_xlpm.rw-83,_xlpm.n):INDEX(Zinsswaps!$B:$AY,_xlpm.rw,_xlpm.n)), _xlpm.b,AVERAGE(INDEX(Zinsswaps!$B:$AY,_xlpm.rw-83,_xlpm.n+1):INDEX(Zinsswaps!$B:$AY,_xlpm.rw,_xlpm.n+1)), _xlpm.swap,_xlpm.a+_xlpm.x*(_xlpm.b-_xlpm.a), _xlpm.yield,AVERAGE($D3:$D86), _xlpm.yield-_xlpm.swap ) -> 0.70295592
